Workbook

Sheet المستوى الأول 
B2: رقم الجامعي | C2: أسماء الطلبة | D2: الساعة | E2: القرآن الكريم | F2: الوزن | G2: الرمز | H2: النقاط | I2: الساعة | J2: التوحيد | K2: الوزن | L2: الرمز | M2: النقاط | N2: الساعة | O2: المدخل إلى علوم الحديث | P2: الوزن | Q2: الرمز | R2: النقاط | S2: الساعة | T2: الفقه (1) | U2: الوزن | V2: الرمز | W2: النقاط | X2: الساعة | Y2: المدخل إلى علوم القرآن | Z2: الوزن | AA2: الرمز | AB2: النقاط | AC2: الساعة | AD2: التجويد | AE2: الوزن | AF2: الرمز | AG2: النقاط | AH2: الساعة | AI2: مدخل إلى الحديث التحليلي | AJ2: الوزن | AK2: الرمز | AL2: النقاط | AM2: الساعة | AN2: النحو (1) | AO2: الوزن | AP2: الرمز | AQ2: النقاط | AR2: الساعة | AS2: تاريخ السنة | AT2: الوزن | AU2: الرمز | AV2: النقاط | AW2: الساعة | AX2: مناهج البحث | AY2: الوزن | AZ2: الرمز | BA2: النقاط | BB2: الساعة | BC2: التحرير العربي | BD2: الوزن | BE2: الرمز | BF2: النقاط | BG2: الساعة | BH2: English(2) | BI2: الوزن | BJ2: الرمز | BK2: النقاط | BL2: مجموع النقاط | BM2: مجموع الساعات | BN2: المعدل الفصلي | BO2: المعدل التراكمي | BP2: التقدير | BQ2: الترتيب
B3: 2024174 | C3: حمزة أبوبكر كابا | D3: 1 | E3: 99 | F3: =VLOOKUP(E3,[1]المرجع!$B$3:$C$12,2) -> 5 | G3: =VLOOKUP(F3,[1]المرجع!$D$3:$E$12,2) -> أ+ | H3: =F3*D3 -> 5 | I3: 2 | J3: 100 | K3: =VLOOKUP(J3,[1]المرجع!$B$3:$C$12,2) -> 5 | L3: =VLOOKUP(K3,[1]المرجع!$D$3:$E$12,2) -> أ+ | M3: =K3*I3 -> 10 | N3: 2 | O3: 100 | P3: =VLOOKUP(O3,[1]المرجع!$B$3:$C$12,2) -> 5 | Q3: =VLOOKUP(P3,[1]المرجع!$D$3:$E$12,2) -> أ+ | R3: =P3*N3 -> 10 | S3: 2 | T3: 98 | U3: =VLOOKUP(T3,[1]المرجع!$B$3:$C$12,2) -> 5 | V3: =VLOOKUP(U3,[1]المرجع!$D$3:$E$12,2) -> أ+ | W3: =U3*S3 -> 10 | X3: 2 | Y3: 100 | Z3: =VLOOKUP(Y3,[1]المرجع!$B$3:$C$12,2) -> 5 | AA3: =VLOOKUP(Z3,[1]المرجع!$D$3:$E$12,2) -> أ+ | AB3: =Z3*X3 -> 10 | AC3: 2 | AD3: 100 | AE3: =VLOOKUP(AD3,[1]المرجع!$B$3:$C$12,2) -> 5 | AF3: =VLOOKUP(AE3,[1]المرجع!$D$3:$E$12,2) -> أ+ | AG3: =AE3*AC3 -> 10 | AH3: 2 | AI3: 100 | AJ3: =VLOOKUP(AI3,[1]المرجع!$B$3:$C$12,2) -> 5 | AK3: =VLOOKUP(AJ3,[1]المرجع!$D$3:$E$12,2) -> أ+ | AL3: =AJ3*AH3 -> 10 | AM3: 2 | AN3: 95 | AO3: =VLOOKUP(AN3,[1]المرجع!$B$3:$C$12,2) -> 5 | AP3: =VLOOKUP(AO3,[1]المرجع!$D$3:$E$12,2) -> أ+ | AQ3: =AO3*AM3 -> 10 | AR3: 2 | AS3: 100 | AT3: =VLOOKUP(AS3,[1]المرجع!$B$3:$C$12,2) -> 5 | AU3: =VLOOKUP(AT3,[1]المرجع!$D$3:$E$12,2) -> أ+ | AV3: =AT3*AR3 -> 10 | AW3: 2 | AX3: 98 | AY3: =VLOOKUP(AX3,[1]المرجع!$B$3:$C$12,2) -> 5 | AZ3: =VLOOKUP(AY3,[1]المرجع!$D$3:$E$12,2) -> أ+ | BA3: =AY3*AW3 -> 10 | BB3: 2 | BC3: 90 | BD3: =VLOOKUP(BC3,[1]المرجع!$B$3:$C$12,2) -> 4.75 | BE3: =VLOOKUP(BD3,[1]المرجع!$D$3:$E$12,2) -> أ | BF3: =BD3*BB3 -> 9.5 | BG3: 2 | BH3: 100 | BI3: =VLOOKUP(BH3,[1]المرجع!$B$3:$C$12,2) -> 5 | BJ3: =VLOOKUP(BI3,[1]المرجع!$D$3:$E$12,2) -> أ+ | BK3: =BI3*BG3 -> 10 | BL3: =BK3+BF3+BA3+AV3+AQ3+AL3+AG3+AB3+W3+R3+M3+H3 -> 114.5 | BM3: =BG3+BB3+AW3+AR3+AM3+AH3+AC3+X3+S3+N3+I3+D3 -> 23 | BN3: =BL3/BM3 -> 4.9782609 | BP3: =VLOOKUP(BN3,[1]المرجع!D$3:F$12,3) -> ممتاز مرتفع | BQ3: =RANK(BN3,$BN$3:$BN$55) -> 1
B4: 2024154 | C4: عمر شريف ماني | D4: 1 | E4: 97 | F4: =VLOOKUP(E4,[1]المرجع!$B$3:$C$12,2) -> 5 | G4: =VLOOKUP(F4,[1]المرجع!$D$3:$E$12,2) -> أ+ | H4: =F4*D4 -> 5 | I4: 2 | J4: 98 | K4: =VLOOKUP(J4,[1]المرجع!$B$3:$C$12,2) -> 5 | L4: =VLOOKUP(K4,[1]المرجع!$D$3:$E$12,2) -> أ+ | M4: =K4*I4 -> 10 | N4: 2 | O4: 99.5 | P4: =VLOOKUP(O4,[1]المرجع!$B$3:$C$12,2) -> 5 | Q4: =VLOOKUP(P4,[1]المرجع!$D$3:$E$12,2) -> أ+ | R4: =P4*N4 -> 10 | S4: 2 | T4: 94 | U4: =VLOOKUP(T4,[1]المرجع!$B$3:$C$12,2) -> 4.75 | V4: =VLOOKUP(U4,[1]المرجع!$D$3:$E$12,2) -> أ | W4: =U4*S4 -> 9.5 | X4: 2 | Y4: 100 | Z4: =VLOOKUP(Y4,[1]المرجع!$B$3:$C$12,2) -> 5 | AA4: =VLOOKUP(Z4,[1]المرجع!$D$3:$E$12,2) -> أ+ | AB4: =Z4*X4 -> 10 | AC4: 2 | AD4: 75 | AE4: =VLOOKUP(AD4,[1]المرجع!$B$3:$C$12,2) -> 3.5 | AF4: =VLOOKUP(AE4,[1]المرجع!$D$3:$E$12,2) -> ج+ | AG4: =AE4*AC4 -> 7 | AH4: 2 | AI4: 97 | AJ4: =VLOOKUP(AI4,[1]المرجع!$B$3:$C$12,2) -> 5 | AK4: =VLOOKUP(AJ4,[1]المرجع!$D$3:$E$12,2) -> أ+ | AL4: =AJ4*AH4 -> 10 | AM4: 2 | AN4: 95 | AO4: =VLOOKUP(AN4,[1]المرجع!$B$3:$C$12,2) -> 5 | AP4: =VLOOKUP(AO4,[1]المرجع!$D$3:$E$12,2) -> أ+ | AQ4: =AO4*AM4 -> 10 | AR4: 2 | AS4: 100 | AT4: =VLOOKUP(AS4,[1]المرجع!$B$3:$C$12,2) -> 5 | AU4: =VLOOKUP(AT4,[1]المرجع!$D$3:$E$12,2) -> أ+ | AV4: =AT4*AR4 -> 10 | AW4: 2 | AX4: 75 | AY4: =VLOOKUP(AX4,[1]المرجع!$B$3:$C$12,2) -> 3.5 | AZ4: =VLOOKUP(AY4,[1]المرجع!$D$3:$E$12,2) -> ج+ | BA4: =AY4*AW4 -> 7 | BB4: 2 | BC4: 90 | BD4: =VLOOKUP(BC4,[1]المرجع!$B$3:$C$12,2) -> 4.75 | BE4: =VLOOKUP(BD4,[1]المرجع!$D$3:$E$12,2) -> أ | BF4: =BD4*BB4 -> 9.5 | BG4: 2 | BH4: 100 | BI4: =VLOOKUP(BH4,[1]المرجع!$B$3:$C$12,2) -> 5 | BJ4: =VLOOKUP(BI4,[1]المرجع!$D$3:$E$12,2) -> أ+ | BK4: =BI4*BG4 -> 10 | BL4: =BK4+BF4+BA4+AV4+AQ4+AL4+AG4+AB4+W4+R4+M4+H4 -> 108 | BM4: =BG4+BB4+AW4+AR4+AM4+AH4+AC4+X4+S4+N4+I4+D4 -> 23 | BN4: =BL4/BM4 -> 4.6956522 | BP4: =VLOOKUP(BN4,[1]المرجع!D$3:F$12,3) -> ممتاز | BQ4: =RANK(BN4,$BN$3:$BN$55) -> 5
B5: 2024153 | C5: مصطفى أبوبكر منجا | D5: 1 | E5: 98 | F5: =VLOOKUP(E5,[1]المرجع!$B$3:$C$12,2) -> 5 | G5: =VLOOKUP(F5,[1]المرجع!$D$3:$E$12,2) -> أ+ | H5: =F5*D5 -> 5 | I5: 2 | J5: 98 | K5: =VLOOKUP(J5,[1]المرجع!$B$3:$C$12,2) -> 5 | L5: =VLOOKUP(K5,[1]المرجع!$D$3:$E$12,2) -> أ+ | M5: =K5*I5 -> 10 | N5: 2 | O5: 97 | P5: =VLOOKUP(O5,[1]المرجع!$B$3:$C$12,2) -> 5 | Q5: =VLOOKUP(P5,[1]المرجع!$D$3:$E$12,2) -> أ+ | R5: =P5*N5 -> 10 | S5: 2 | T5: 94 | U5: =VLOOKUP(T5,[1]المرجع!$B$3:$C$12,2) -> 4.75 | V5: =VLOOKUP(U5,[1]المرجع!$D$3:$E$12,2) -> أ | W5: =U5*S5 -> 9.5 | X5: 2 | Y5: 96 | Z5: =VLOOKUP(Y5,[1]المرجع!$B$3:$C$12,2) -> 5 | AA5: =VLOOKUP(Z5,[1]المرجع!$D$3:$E$12,2) -> أ+ | AB5: =Z5*X5 -> 10 | AC5: 2 | AD5: 75 | AE5: =VLOOKUP(AD5,[1]المرجع!$B$3:$C$12,2) -> 3.5 | AF5: =VLOOKUP(AE5,[1]المرجع!$D$3:$E$12,2) -> ج+ | AG5: =AE5*AC5 -> 7 | AH5: 2 | AI5: 95 | AJ5: =VLOOKUP(AI5,[1]المرجع!$B$3:$C$12,2) -> 5 | AK5: =VLOOKUP(AJ5,[1]المرجع!$D$3:$E$12,2) -> أ+ | AL5: =AJ5*AH5 -> 10 | AM5: 2 | AN5: 95 | AO5: =VLOOKUP(AN5,[1]المرجع!$B$3:$C$12,2) -> 5 | AP5: =VLOOKUP(AO5,[1]المرجع!$D$3:$E$12,2) -> أ+ | AQ5: =AO5*AM5 -> 10 | AR5: 2 | AS5: 100 | AT5: =VLOOKUP(AS5,[1]المرجع!$B$3:$C$12,2) -> 5 | AU5: =VLOOKUP(AT5,[1]المرجع!$D$3:$E$12,2) -> أ+ | AV5: =AT5*AR5 -> 10 | AW5: 2 | AX5: 85 | AY5: =VLOOKUP(AX5,[1]المرجع!$B$3:$C$12,2) -> 4.5 | AZ5: =VLOOKUP(AY5,[1]المرجع!$D$3:$E$12,2) -> ب+ | BA5: =AY5*AW5 -> 9 | BB5: 2 | BC5: 90 | BD5: =VLOOKUP(BC5,[1]المرجع!$B$3:$C$12,2) -> 4.75 | BE5: =VLOOKUP(BD5,[1]المرجع!$D$3:$E$12,2) -> أ | BF5: =BD5*BB5 -> 9.5 | BG5: 2 | BH5: 92 | BI5: =VLOOKUP(BH5,[1]المرجع!$B$3:$C$12,2) -> 4.75 | BJ5: =VLOOKUP(BI5,[1]المرجع!$D$3:$E$12,2) -> أ | BK5: =BI5*BG5 -> 9.5 | BL5: =BK5+BF5+BA5+AV5+AQ5+AL5+AG5+AB5+W5+R5+M5+H5 -> 109.5 | BM5: =BG5+BB5+AW5+AR5+AM5+AH5+AC5+X5+S5+N5+I5+D5 -> 23 | BN5: =BL5/BM5 -> 4.7608696 | BP5: =VLOOKUP(BN5,[1]المرجع!D$3:F$12,3) -> ممتاز مرتفع | BQ5: =RANK(BN5,$BN$3:$BN$55) -> 3
B6: 2024155 | C6: مالا كيبا سيسي | D6: 1 | E6: 94 | F6: =VLOOKUP(E6,[1]المرجع!$B$3:$C$12,2) -> 4.75 | G6: =VLOOKUP(F6,[1]المرجع!$D$3:$E$12,2) -> أ | H6: =F6*D6 -> 4.75 | I6: 2 | J6: 94 | K6: =VLOOKUP(J6,[1]المرجع!$B$3:$C$12,2) -> 4.75 | L6: =VLOOKUP(K6,[1]المرجع!$D$3:$E$12,2) -> أ | M6: =K6*I6 -> 9.5 | N6: 2 | O6: 90 | P6: =VLOOKUP(O6,[1]المرجع!$B$3:$C$12,2) -> 4.75 | Q6: =VLOOKUP(P6,[1]المرجع!$D$3:$E$12,2) -> أ | R6: =P6*N6 -> 9.5 | S6: 2 | T6: 90 | U6: =VLOOKUP(T6,[1]المرجع!$B$3:$C$12,2) -> 4.75 | V6: =VLOOKUP(U6,[1]المرجع!$D$3:$E$12,2) -> أ | W6: =U6*S6 -> 9.5 | X6: 2 | Y6: 95 | Z6: =VLOOKUP(Y6,[1]المرجع!$B$3:$C$12,2) -> 5 | AA6: =VLOOKUP(Z6,[1]المرجع!$D$3:$E$12,2) -> أ+ | AB6: =Z6*X6 -> 10 | AC6: 2 | AD6: 92 | AE6: =VLOOKUP(AD6,[1]المرجع!$B$3:$C$12,2) -> 4.75 | AF6: =VLOOKUP(AE6,[1]المرجع!$D$3:$E$12,2) -> أ | AG6: =AE6*AC6 -> 9.5 | AH6: 2 | AI6: 95 | AJ6: =VLOOKUP(AI6,[1]المرجع!$B$3:$C$12,2) -> 5 | AK6: =VLOOKUP(AJ6,[1]المرجع!$D$3:$E$12,2) -> أ+ | AL6: =AJ6*AH6 -> 10 | AM6: 2 | AN6: 95 | AO6: =VLOOKUP(AN6,[1]المرجع!$B$3:$C$12,2) -> 5 | AP6: =VLOOKUP(AO6,[1]المرجع!$D$3:$E$12,2) -> أ+ | AQ6: =AO6*AM6 -> 10 | AR6: 2 | AS6: 100 | AT6: =VLOOKUP(AS6,[1]المرجع!$B$3:$C$12,2) -> 5 | AU6: =VLOOKUP(AT6,[1]المرجع!$D$3:$E$12,2) -> أ+ | AV6: =AT6*AR6 -> 10 | AW6: 2 | AX6: 80 | AY6: =VLOOKUP(AX6,[1]المرجع!$B$3:$C$12,2) -> 4 | AZ6: =VLOOKUP(AY6,[1]المرجع!$D$3:$E$12,2) -> ب | BA6: =AY6*AW6 -> 8 | BB6: 2 | BC6: 87 | BD6: =VLOOKUP(BC6,[1]المرجع!$B$3:$C$12,2) -> 4.5 | BE6: =VLOOKUP(BD6,[1]المرجع!$D$3:$E$12,2) -> ب+ | BF6: =BD6*BB6 -> 9 | BG6: 2 | BH6: 100 | BI6: =VLOOKUP(BH6,[1]المرجع!$B$3:$C$12,2) -> 5 | BJ6: =VLOOKUP(BI6,[1]المرجع!$D$3:$E$12,2) -> أ+ | BK6: =BI6*BG6 -> 10 | BL6: =BK6+BF6+BA6+AV6+AQ6+AL6+AG6+AB6+W6+R6+M6+H6 -> 109.75 | BM6: =BG6+BB6+AW6+AR6+AM6+AH6+AC6+X6+S6+N6+I6+D6 -> 23 | BN6: =BL6/BM6 -> 4.7717391 | BP6: =VLOOKUP(BN6,[1]المرجع!D$3:F$12,3) -> ممتاز مرتفع | BQ6: =RANK(BN6,$BN$3:$BN$55) -> 2
B7: 2024180 | C7: حليمة مجتبى جالو | D7: 1 | E7: 88 | F7: =VLOOKUP(E7,[1]المرجع!$B$3:$C$12,2) -> 4.5 | G7: =VLOOKUP(F7,[1]المرجع!$D$3:$E$12,2) -> ب+ | H7: =F7*D7 -> 4.5 | I7: 2 | J7: 96 | K7: =VLOOKUP(J7,[1]المرجع!$B$3:$C$12,2) -> 5 | L7: =VLOOKUP(K7,[1]المرجع!$D$3:$E$12,2) -> أ+ | M7: =K7*I7 -> 10 | N7: 2 | O7: 98 | P7: =VLOOKUP(O7,[1]المرجع!$B$3:$C$12,2) -> 5 | Q7: =VLOOKUP(P7,[1]المرجع!$D$3:$E$12,2) -> أ+ | R7: =P7*N7 -> 10 | S7: 2 | T7: 90 | U7: =VLOOKUP(T7,[1]المرجع!$B$3:$C$12,2) -> 4.75 | V7: =VLOOKUP(U7,[1]المرجع!$D$3:$E$12,2) -> أ | W7: =U7*S7 -> 9.5 | X7: 2 | Y7: 95 | Z7: =VLOOKUP(Y7,[1]المرجع!$B$3:$C$12,2) -> 5 | AA7: =VLOOKUP(Z7,[1]المرجع!$D$3:$E$12,2) -> أ+ | AB7: =Z7*X7 -> 10 | AC7: 2 | AD7: 87 | AE7: =VLOOKUP(AD7,[1]المرجع!$B$3:$C$12,2) -> 4.5 | AF7: =VLOOKUP(AE7,[1]المرجع!$D$3:$E$12,2) -> ب+ | AG7: =AE7*AC7 -> 9 | AH7: 2 | AI7: 99 | AJ7: =VLOOKUP(AI7,[1]المرجع!$B$3:$C$12,2) -> 5 | AK7: =VLOOKUP(AJ7,[1]المرجع!$D$3:$E$12,2) -> أ+ | AL7: =AJ7*AH7 -> 10 | AM7: 2 | AN7: 75 | AO7: =VLOOKUP(AN7,[1]المرجع!$B$3:$C$12,2) -> 3.5 | AP7: =VLOOKUP(AO7,[1]المرجع!$D$3:$E$12,2) -> ج+ | AQ7: =AO7*AM7 -> 7 | AR7: 2 | AS7: 100 | AT7: =VLOOKUP(AS7,[1]المرجع!$B$3:$C$12,2) -> 5 | AU7: =VLOOKUP(AT7,[1]المرجع!$D$3:$E$12,2) -> أ+ | AV7: =AT7*AR7 -> 10 | AW7: 2 | AX7: 95 | AY7: =VLOOKUP(AX7,[1]المرجع!$B$3:$C$12,2) -> 5 | AZ7: =VLOOKUP(AY7,[1]المرجع!$D$3:$E$12,2) -> أ+ | BA7: =AY7*AW7 -> 10 | BB7: 2 | BC7: 85 | BD7: =VLOOKUP(BC7,[1]المرجع!$B$3:$C$12,2) -> 4.5 | BE7: =VLOOKUP(BD7,[1]المرجع!$D$3:$E$12,2) -> ب+ | BF7: =BD7*BB7 -> 9 | BG7: 2 | BH7: 100 | BI7: =VLOOKUP(BH7,[1]المرجع!$B$3:$C$12,2) -> 5 | BJ7: =VLOOKUP(BI7,[1]المرجع!$D$3:$E$12,2) -> أ+ | BK7: =BI7*BG7 -> 10 | BL7: =BK7+BF7+BA7+AV7+AQ7+AL7+AG7+AB7+W7+R7+M7+H7 -> 109 | BM7: =BG7+BB7+AW7+AR7+AM7+AH7+AC7+X7+S7+N7+I7+D7 -> 23 | BN7: =BL7/BM7 -> 4.7391304 | BP7: =VLOOKUP(BN7,[1]المرجع!D$3:F$12,3) -> ممتاز | BQ7: =RANK(BN7,$BN$3:$BN$55) -> 4
B8: 2024152 | C8: عبدالله شعيب كروما | D8: 1 | E8: 98 | F8: =VLOOKUP(E8,[1]المرجع!$B$3:$C$12,2) -> 5 | G8: =VLOOKUP(F8,[1]المرجع!$D$3:$E$12,2) -> أ+ | H8: =F8*D8 -> 5 | I8: 2 | J8: 95 | K8: =VLOOKUP(J8,[1]المرجع!$B$3:$C$12,2) -> 5 | L8: =VLOOKUP(K8,[1]المرجع!$D$3:$E$12,2) -> أ+ | M8: =K8*I8 -> 10 | N8: 2 | O8: 95 | P8: =VLOOKUP(O8,[1]المرجع!$B$3:$C$12,2) -> 5 | Q8: =VLOOKUP(P8,[1]المرجع!$D$3:$E$12,2) -> أ+ | R8: =P8*N8 -> 10 | S8: 2 | T8: 95 | U8: =VLOOKUP(T8,[1]المرجع!$B$3:$C$12,2) -> 5 | V8: =VLOOKUP(U8,[1]المرجع!$D$3:$E$12,2) -> أ+ | W8: =U8*S8 -> 10 | X8: 2 | Y8: 93 | Z8: =VLOOKUP(Y8,[1]المرجع!$B$3:$C$12,2) -> 4.75 | AA8: =VLOOKUP(Z8,[1]المرجع!$D$3:$E$12,2) -> أ | AB8: =Z8*X8 -> 9.5 | AC8: 2 | AD8: 59 | AE8: =VLOOKUP(AD8,[1]المرجع!$B$3:$C$12,2) -> 2 | AF8: =VLOOKUP(AE8,[1]المرجع!$D$3:$E$12,2) -> د | AG8: =AE8*AC8 -> 4 | AH8: 2 | AI8: 100 | AJ8: =VLOOKUP(AI8,[1]المرجع!$B$3:$C$12,2) -> 5 | AK8: =VLOOKUP(AJ8,[1]المرجع!$D$3:$E$12,2) -> أ+ | AL8: =AJ8*AH8 -> 10 | AM8: 2 | AN8: 96 | AO8: =VLOOKUP(AN8,[1]المرجع!$B$3:$C$12,2) -> 5 | AP8: =VLOOKUP(AO8,[1]المرجع!$D$3:$E$12,2) -> أ+ | AQ8: =AO8*AM8 -> 10 | AR8: 2 | AS8: 100 | AT8: =VLOOKUP(AS8,[1]المرجع!$B$3:$C$12,2) -> 5 | AU8: =VLOOKUP(AT8,[1]المرجع!$D$3:$E$12,2) -> أ+ | AV8: =AT8*AR8 -> 10 | AW8: 2 | AX8: 75 | AY8: =VLOOKUP(AX8,[1]المرجع!$B$3:$C$12,2) -> 3.5 | AZ8: =VLOOKUP(AY8,[1]المرجع!$D$3:$E$12,2) -> ج+ | BA8: =AY8*AW8 -> 7 | BB8: 2 | BC8: 85 | BD8: =VLOOKUP(BC8,[1]المرجع!$B$3:$C$12,2) -> 4.5 | BE8: =VLOOKUP(BD8,[1]المرجع!$D$3:$E$12,2) -> ب+ | BF8: =BD8*BB8 -> 9 | BG8: 2 | BH8: 95 | BI8: =VLOOKUP(BH8,[1]المرجع!$B$3:$C$12,2) -> 5 | BJ8: =VLOOKUP(BI8,[1]المرجع!$D$3:$E$12,2) -> أ+ | BK8: =BI8*BG8 -> 10 | BL8: =BK8+BF8+BA8+AV8+AQ8+AL8+AG8+AB8+W8+R8+M8+H8 -> 104.5 | BM8: =BG8+BB8+AW8+AR8+AM8+AH8+AC8+X8+S8+N8+I8+D8 -> 23 | BN8: =BL8/BM8 -> 4.5434783 | BP8: =VLOOKUP(BN8,[1]المرجع!D$3:F$12,3) -> جيد جد مرتفع | BQ8: =RANK(BN8,$BN$3:$BN$55) -> 6
B9: 2024178 | C9: عائشة مبارك ديكو | D9: 1 | E9: 95 | F9: =VLOOKUP(E9,[1]المرجع!$B$3:$C$12,2) -> 5 | G9: =VLOOKUP(F9,[1]المرجع!$D$3:$E$12,2) -> أ+ | H9: =F9*D9 -> 5 | I9: 2 | J9: 95 | K9: =VLOOKUP(J9,[1]المرجع!$B$3:$C$12,2) -> 5 | L9: =VLOOKUP(K9,[1]المرجع!$D$3:$E$12,2) -> أ+ | M9: =K9*I9 -> 10 | N9: 2 | O9: 97 | P9: =VLOOKUP(O9,[1]المرجع!$B$3:$C$12,2) -> 5 | Q9: =VLOOKUP(P9,[1]المرجع!$D$3:$E$12,2) -> أ+ | R9: =P9*N9 -> 10 | S9: 2 | T9: 90 | U9: =VLOOKUP(T9,[1]المرجع!$B$3:$C$12,2) -> 4.75 | V9: =VLOOKUP(U9,[1]المرجع!$D$3:$E$12,2) -> أ | W9: =U9*S9 -> 9.5 | X9: 2 | Y9: 97 | Z9: =VLOOKUP(Y9,[1]المرجع!$B$3:$C$12,2) -> 5 | AA9: =VLOOKUP(Z9,[1]المرجع!$D$3:$E$12,2) -> أ+ | AB9: =Z9*X9 -> 10 | AC9: 2 | AD9: 76 | AE9: =VLOOKUP(AD9,[1]المرجع!$B$3:$C$12,2) -> 3.5 | AF9: =VLOOKUP(AE9,[1]المرجع!$D$3:$E$12,2) -> ج+ | AG9: =AE9*AC9 -> 7 | AH9: 2 | AI9: 99 | AJ9: =VLOOKUP(AI9,[1]المرجع!$B$3:$C$12,2) -> 5 | AK9: =VLOOKUP(AJ9,[1]المرجع!$D$3:$E$12,2) -> أ+ | AL9: =AJ9*AH9 -> 10 | AM9: 2 | AN9: 78 | AO9: =VLOOKUP(AN9,[1]المرجع!$B$3:$C$12,2) -> 3.5 | AP9: =VLOOKUP(AO9,[1]المرجع!$D$3:$E$12,2) -> ج+ | AQ9: =AO9*AM9 -> 7 | AR9: 2 | AS9: 100 | AT9: =VLOOKUP(AS9,[1]المرجع!$B$3:$C$12,2) -> 5 | AU9: =VLOOKUP(AT9,[1]المرجع!$D$3:$E$12,2) -> أ+ | AV9: =AT9*AR9 -> 10 | AW9: 2 | AX9: 70 | AY9: =VLOOKUP(AX9,[1]المرجع!$B$3:$C$12,2) -> 3 | AZ9: =VLOOKUP(AY9,[1]المرجع!$D$3:$E$12,2) -> ج | BA9: =AY9*AW9 -> 6 | BB9: 2 | BC9: 83 | BD9: =VLOOKUP(BC9,[1]المرجع!$B$3:$C$12,2) -> 4 | BE9: =VLOOKUP(BD9,[1]المرجع!$D$3:$E$12,2) -> ب | BF9: =BD9*BB9 -> 8 | BG9: 2 | BH9: 100 | BI9: =VLOOKUP(BH9,[1]المرجع!$B$3:$C$12,2) -> 5 | BJ9: =VLOOKUP(BI9,[1]المرجع!$D$3:$E$12,2) -> أ+ | BK9: =BI9*BG9 -> 10 | BL9: =BK9+BF9+BA9+AV9+AQ9+AL9+AG9+AB9+W9+R9+M9+H9 -> 102.5 | BM9: =BG9+BB9+AW9+AR9+AM9+AH9+AC9+X9+S9+N9+I9+D9 -> 23 | BN9: =BL9/BM9 -> 4.4565217 | BP9: =VLOOKUP(BN9,[1]المرجع!D$3:F$12,3) -> جيد جد مرتفع | BQ9: =RANK(BN9,$BN$3:$BN$55) -> 8
B10: 2024303 | C10: أم حواء سراج جالو | D10: 1 | E10: 96 | F10: =VLOOKUP(E10,[1]المرجع!$B$3:$C$12,2) -> 5 | G10: =VLOOKUP(F10,[1]المرجع!$D$3:$E$12,2) -> أ+ | H10: =F10*D10 -> 5 | I10: 2 | J10: 98 | K10: =VLOOKUP(J10,[1]المرجع!$B$3:$C$12,2) -> 5 | L10: =VLOOKUP(K10,[1]المرجع!$D$3:$E$12,2) -> أ+ | M10: =K10*I10 -> 10 | N10: 2 | O10: 88 | P10: =VLOOKUP(O10,[1]المرجع!$B$3:$C$12,2) -> 4.5 | Q10: =VLOOKUP(P10,[1]المرجع!$D$3:$E$12,2) -> ب+ | R10: =P10*N10 -> 9 | S10: 2 | T10: 90 | U10: =VLOOKUP(T10,[1]المرجع!$B$3:$C$12,2) -> 4.75 | V10: =VLOOKUP(U10,[1]المرجع!$D$3:$E$12,2) -> أ | W10: =U10*S10 -> 9.5 | X10: 2 | Y10: 99 | Z10: =VLOOKUP(Y10,[1]المرجع!$B$3:$C$12,2) -> 5 | AA10: =VLOOKUP(Z10,[1]المرجع!$D$3:$E$12,2) -> أ+ | AB10: =Z10*X10 -> 10 | AC10: 2 | AD10: 79 | AE10: =VLOOKUP(AD10,[1]المرجع!$B$3:$C$12,2) -> 3.5 | AF10: =VLOOKUP(AE10,[1]المرجع!$D$3:$E$12,2) -> ج+ | AG10: =AE10*AC10 -> 7 | AH10: 2 | AI10: 100 | AJ10: =VLOOKUP(AI10,[1]المرجع!$B$3:$C$12,2) -> 5 | AK10: =VLOOKUP(AJ10,[1]المرجع!$D$3:$E$12,2) -> أ+ | AL10: =AJ10*AH10 -> 10 | AM10: 2 | AN10: 70 | AO10: =VLOOKUP(AN10,[1]المرجع!$B$3:$C$12,2) -> 3 | AP10: =VLOOKUP(AO10,[1]المرجع!$D$3:$E$12,2) -> ج | AQ10: =AO10*AM10 -> 6 | AR10: 2 | AS10: 100 | AT10: =VLOOKUP(AS10,[1]المرجع!$B$3:$C$12,2) -> 5 | AU10: =VLOOKUP(AT10,[1]المرجع!$D$3:$E$12,2) -> أ+ | AV10: =AT10*AR10 -> 10 | AW10: 2 | AX10: 91 | AY10: =VLOOKUP(AX10,[1]المرجع!$B$3:$C$12,2) -> 4.75 | AZ10: =VLOOKUP(AY10,[1]المرجع!$D$3:$E$12,2) -> أ | BA10: =AY10*AW10 -> 9.5 | BB10: 2 | BC10: 85 | BD10: =VLOOKUP(BC10,[1]المرجع!$B$3:$C$12,2) -> 4.5 | BE10: =VLOOKUP(BD10,[1]المرجع!$D$3:$E$12,2) -> ب+ | BF10: =BD10*BB10 -> 9 | BG10: 2 | BH10: 82 | BI10: =VLOOKUP(BH10,[1]المرجع!$B$3:$C$12,2) -> 4 | BJ10: =VLOOKUP(BI10,[1]المرجع!$D$3:$E$12,2) -> ب | BK10: =BI10*BG10 -> 8 | BL10: =BK10+BF10+BA10+AV10+AQ10+AL10+AG10+AB10+W10+R10+M10+H10 -> 103 | BM10: =BG10+BB10+AW10+AR10+AM10+AH10+AC10+X10+S10+N10+I10+D10 -> 23 | BN10: =BL10/BM10 -> 4.4782609 | BP10: =VLOOKUP(BN10,[1]المرجع!D$3:F$12,3) -> جيد جد مرتفع | BQ10: =RANK(BN10,$BN$3:$BN$55) -> 7
B11: 2024162 | C11: عثمان الحاج باكيبا ديباسي | D11: 1 | E11: 98 | F11: =VLOOKUP(E11,[1]المرجع!$B$3:$C$12,2) -> 5 | G11: =VLOOKUP(F11,[1]المرجع!$D$3:$E$12,2) -> أ+ | H11: =F11*D11 -> 5 | I11: 2 | J11: 96 | K11: =VLOOKUP(J11,[1]المرجع!$B$3:$C$12,2) -> 5 | L11: =VLOOKUP(K11,[1]المرجع!$D$3:$E$12,2) -> أ+ | M11: =K11*I11 -> 10 | N11: 2 | O11: 93 | P11: =VLOOKUP(O11,[1]المرجع!$B$3:$C$12,2) -> 4.75 | Q11: =VLOOKUP(P11,[1]المرجع!$D$3:$E$12,2) -> أ | R11: =P11*N11 -> 9.5 | S11: 2 | T11: 95 | U11: =VLOOKUP(T11,[1]المرجع!$B$3:$C$12,2) -> 5 | V11: =VLOOKUP(U11,[1]المرجع!$D$3:$E$12,2) -> أ+ | W11: =U11*S11 -> 10 | X11: 2 | Y11: 96 | Z11: =VLOOKUP(Y11,[1]المرجع!$B$3:$C$12,2) -> 5 | AA11: =VLOOKUP(Z11,[1]المرجع!$D$3:$E$12,2) -> أ+ | AB11: =Z11*X11 -> 10 | AC11: 2 | AD11: 61 | AE11: =VLOOKUP(AD11,[1]المرجع!$B$3:$C$12,2) -> 2 | AF11: =VLOOKUP(AE11,[1]المرجع!$D$3:$E$12,2) -> د | AG11: =AE11*AC11 -> 4 | AH11: 2 | AI11: 90 | AJ11: =VLOOKUP(AI11,[1]المرجع!$B$3:$C$12,2) -> 4.75 | AK11: =VLOOKUP(AJ11,[1]المرجع!$D$3:$E$12,2) -> أ | AL11: =AJ11*AH11 -> 9.5 | AM11: 2 | AN11: 95 | AO11: =VLOOKUP(AN11,[1]المرجع!$B$3:$C$12,2) -> 5 | AP11: =VLOOKUP(AO11,[1]المرجع!$D$3:$E$12,2) -> أ+ | AQ11: =AO11*AM11 -> 10 | AR11: 2 | AS11: 100 | AT11: =VLOOKUP(AS11,[1]المرجع!$B$3:$C$12,2) -> 5 | AU11: =VLOOKUP(AT11,[1]المرجع!$D$3:$E$12,2) -> أ+ | AV11: =AT11*AR11 -> 10 | AW11: 2 | AX11: 81 | AY11: =VLOOKUP(AX11,[1]المرجع!$B$3:$C$12,2) -> 4 | AZ11: =VLOOKUP(AY11,[1]المرجع!$D$3:$E$12,2) -> ب | BA11: =AY11*AW11 -> 8 | BB11: 2 | BC11: 79 | BD11: =VLOOKUP(BC11,[1]المرجع!$B$3:$C$12,2) -> 3.5 | BE11: =VLOOKUP(BD11,[1]المرجع!$D$3:$E$12,2) -> ج+ | BF11: =BD11*BB11 -> 7 | BG11: 2 | BH11: 84 | BI11: =VLOOKUP(BH11,[1]المرجع!$B$3:$C$12,2) -> 4 | BJ11: =VLOOKUP(BI11,[1]المرجع!$D$3:$E$12,2) -> ب | BK11: =BI11*BG11 -> 8 | BL11: =BK11+BF11+BA11+AV11+AQ11+AL11+AG11+AB11+W11+R11+M11+H11 -> 101 | BM11: =BG11+BB11+AW11+AR11+AM11+AH11+AC11+X11+S11+N11+I11+D11 -> 23 | BN11: =BL11/BM11 -> 4.3913043 | BP11: =VLOOKUP(BN11,[1]المرجع!D$3:F$12,3) -> جيد جد مرتفع | BQ11: =RANK(BN11,$BN$3:$BN$55) -> 9
B12: 2024156 | C12: مختار إبراهيم كمارا | D12: 1 | E12: 97 | F12: =VLOOKUP(E12,[1]المرجع!$B$3:$C$12,2) -> 5 | G12: =VLOOKUP(F12,[1]المرجع!$D$3:$E$12,2) -> أ+ | H12: =F12*D12 -> 5 | I12: 2 | J12: 96 | K12: =VLOOKUP(J12,[1]المرجع!$B$3:$C$12,2) -> 5 | L12: =VLOOKUP(K12,[1]المرجع!$D$3:$E$12,2) -> أ+ | M12: =K12*I12 -> 10 | N12: 2 | O12: 96 | P12: =VLOOKUP(O12,[1]المرجع!$B$3:$C$12,2) -> 5 | Q12: =VLOOKUP(P12,[1]المرجع!$D$3:$E$12,2) -> أ+ | R12: =P12*N12 -> 10 | S12: 2 | T12: 91 | U12: =VLOOKUP(T12,[1]المرجع!$B$3:$C$12,2) -> 4.75 | V12: =VLOOKUP(U12,[1]المرجع!$D$3:$E$12,2) -> أ | W12: =U12*S12 -> 9.5 | X12: 2 | Y12: 97 | Z12: =VLOOKUP(Y12,[1]المرجع!$B$3:$C$12,2) -> 5 | AA12: =VLOOKUP(Z12,[1]المرجع!$D$3:$E$12,2) -> أ+ | AB12: =Z12*X12 -> 10 | AC12: 2 | AD12: 62 | AE12: =VLOOKUP(AD12,[1]المرجع!$B$3:$C$12,2) -> 2 | AF12: =VLOOKUP(AE12,[1]المرجع!$D$3:$E$12,2) -> د | AG12: =AE12*AC12 -> 4 | AH12: 2 | AI12: 100 | AJ12: =VLOOKUP(AI12,[1]المرجع!$B$3:$C$12,2) -> 5 | AK12: =VLOOKUP(AJ12,[1]المرجع!$D$3:$E$12,2) -> أ+ | AL12: =AJ12*AH12 -> 10 | AM12: 2 | AN12: 95 | AO12: =VLOOKUP(AN12,[1]المرجع!$B$3:$C$12,2) -> 5 | AP12: =VLOOKUP(AO12,[1]المرجع!$D$3:$E$12,2) -> أ+ | AQ12: =AO12*AM12 -> 10 | AR12: 2 | AS12: 100 | AT12: =VLOOKUP(AS12,[1]المرجع!$B$3:$C$12,2) -> 5 | AU12: =VLOOKUP(AT12,[1]المرجع!$D$3:$E$12,2) -> أ+ | AV12: =AT12*AR12 -> 10 | AW12: 2 | AX12: 59 | AY12: =VLOOKUP(AX12,[1]المرجع!$B$3:$C$12,2) -> 2 | AZ12: =VLOOKUP(AY12,[1]المرجع!$D$3:$E$12,2) -> د | BA12: =AY12*AW12 -> 4 | BB12: 2 | BC12: 70 | BD12: =VLOOKUP(BC12,[1]المرجع!$B$3:$C$12,2) -> 3 | BE12: =VLOOKUP(BD12,[1]المرجع!$D$3:$E$12,2) -> ج | BF12: =BD12*BB12 -> 6 | BG12: 2 | BH12: 100 | BI12: =VLOOKUP(BH12,[1]المرجع!$B$3:$C$12,2) -> 5 | BJ12: =VLOOKUP(BI12,[1]المرجع!$D$3:$E$12,2) -> أ+ | BK12: =BI12*BG12 -> 10 | BL12: =BK12+BF12+BA12+AV12+AQ12+AL12+AG12+AB12+W12+R12+M12+H12 -> 98.5 | BM12: =BG12+BB12+AW12+AR12+AM12+AH12+AC12+X12+S12+N12+I12+D12 -> 23 | BN12: =BL12/BM12 -> 4.2826087 | BP12: =VLOOKUP(BN12,[1]المرجع!D$3:F$12,3) -> جيد جد مرتفع | BQ12: =RANK(BN12,$BN$3:$BN$55) -> 10
B13: 2024161 | C13: فامر فاندن ساني | D13: 1 | E13: 93 | F13: =VLOOKUP(E13,[1]المرجع!$B$3:$C$12,2) -> 4.75 | G13: =VLOOKUP(F13,[1]المرجع!$D$3:$E$12,2) -> أ | H13: =F13*D13 -> 4.75 | I13: 2 | J13: 94 | K13: =VLOOKUP(J13,[1]المرجع!$B$3:$C$12,2) -> 4.75 | L13: =VLOOKUP(K13,[1]المرجع!$D$3:$E$12,2) -> أ | M13: =K13*I13 -> 9.5 | N13: 2 | O13: 96 | P13: =VLOOKUP(O13,[1]المرجع!$B$3:$C$12,2) -> 5 | Q13: =VLOOKUP(P13,[1]المرجع!$D$3:$E$12,2) -> أ+ | R13: =P13*N13 -> 10 | S13: 2 | T13: 89 | U13: =VLOOKUP(T13,[1]المرجع!$B$3:$C$12,2) -> 4.5 | V13: =VLOOKUP(U13,[1]المرجع!$D$3:$E$12,2) -> ب+ | W13: =U13*S13 -> 9 | X13: 2 | Y13: 95 | Z13: =VLOOKUP(Y13,[1]المرجع!$B$3:$C$12,2) -> 5 | AA13: =VLOOKUP(Z13,[1]المرجع!$D$3:$E$12,2) -> أ+ | AB13: =Z13*X13 -> 10 | AC13: 2 | AD13: 60 | AE13: =VLOOKUP(AD13,[1]المرجع!$B$3:$C$12,2) -> 2 | AF13: =VLOOKUP(AE13,[1]المرجع!$D$3:$E$12,2) -> د | AG13: =AE13*AC13 -> 4 | AH13: 2 | AI13: 100 | AJ13: =VLOOKUP(AI13,[1]المرجع!$B$3:$C$12,2) -> 5 | AK13: =VLOOKUP(AJ13,[1]المرجع!$D$3:$E$12,2) -> أ+ | AL13: =AJ13*AH13 -> 10 | AM13: 2 | AN13: 80 | AO13: =VLOOKUP(AN13,[1]المرجع!$B$3:$C$12,2) -> 4 | AP13: =VLOOKUP(AO13,[1]المرجع!$D$3:$E$12,2) -> ب | AQ13: =AO13*AM13 -> 8 | AR13: 2 | AS13: 95 | AT13: =VLOOKUP(AS13,[1]المرجع!$B$3:$C$12,2) -> 5 | AU13: =VLOOKUP(AT13,[1]المرجع!$D$3:$E$12,2) -> أ+ | AV13: =AT13*AR13 -> 10 | AW13: 2 | AX13: 72 | AY13: =VLOOKUP(AX13,[1]المرجع!$B$3:$C$12,2) -> 3 | AZ13: =VLOOKUP(AY13,[1]المرجع!$D$3:$E$12,2) -> ج | BA13: =AY13*AW13 -> 6 | BB13: 2 | BC13: 75 | BD13: =VLOOKUP(BC13,[1]المرجع!$B$3:$C$12,2) -> 3.5 | BE13: =VLOOKUP(BD13,[1]المرجع!$D$3:$E$12,2) -> ج+ | BF13: =BD13*BB13 -> 7 | BG13: 2 | BH13: 90 | BI13: =VLOOKUP(BH13,[1]المرجع!$B$3:$C$12,2) -> 4.75 | BJ13: =VLOOKUP(BI13,[1]المرجع!$D$3:$E$12,2) -> أ | BK13: =BI13*BG13 -> 9.5 | BL13: =BK13+BF13+BA13+AV13+AQ13+AL13+AG13+AB13+W13+R13+M13+H13 -> 97.75 | BM13: =BG13+BB13+AW13+AR13+AM13+AH13+AC13+X13+S13+N13+I13+D13 -> 23 | BN13: =BL13/BM13 -> 4.25 | BP13: =VLOOKUP(BN13,[1]المرجع!D$3:F$12,3) -> جيد جد مرتفع | BQ13: =RANK(BN13,$BN$3:$BN$55) -> 11
B14: 2024304 | C14: زينب محمد كمارا | D14: 1 | E14: 98 | F14: =VLOOKUP(E14,[1]المرجع!$B$3:$C$12,2) -> 5 | G14: =VLOOKUP(F14,[1]المرجع!$D$3:$E$12,2) -> أ+ | H14: =F14*D14 -> 5 | I14: 2 | J14: 93 | K14: =VLOOKUP(J14,[1]المرجع!$B$3:$C$12,2) -> 4.75 | L14: =VLOOKUP(K14,[1]المرجع!$D$3:$E$12,2) -> أ | M14: =K14*I14 -> 9.5 | N14: 2 | O14: 94.5 | P14: =VLOOKUP(O14,[1]المرجع!$B$3:$C$12,2) -> 4.75 | Q14: =VLOOKUP(P14,[1]المرجع!$D$3:$E$12,2) -> أ | R14: =P14*N14 -> 9.5 | S14: 2 | T14: 90 | U14: =VLOOKUP(T14,[1]المرجع!$B$3:$C$12,2) -> 4.75 | V14: =VLOOKUP(U14,[1]المرجع!$D$3:$E$12,2) -> أ | W14: =U14*S14 -> 9.5 | X14: 2 | Y14: 97 | Z14: =VLOOKUP(Y14,[1]المرجع!$B$3:$C$12,2) -> 5 | AA14: =VLOOKUP(Z14,[1]المرجع!$D$3:$E$12,2) -> أ+ | AB14: =Z14*X14 -> 10 | AC14: 2 | AD14: 69 | AE14: =VLOOKUP(AD14,[1]المرجع!$B$3:$C$12,2) -> 2.5 | AF14: =VLOOKUP(AE14,[1]المرجع!$D$3:$E$12,2) -> د+ | AG14: =AE14*AC14 -> 5 | AH14: 2 | AI14: 99 | AJ14: =VLOOKUP(AI14,[1]المرجع!$B$3:$C$12,2) -> 5 | AK14: =VLOOKUP(AJ14,[1]المرجع!$D$3:$E$12,2) -> أ+ | AL14: =AJ14*AH14 -> 10 | AM14: 2 | AN14: 70 | AO14: =VLOOKUP(AN14,[1]المرجع!$B$3:$C$12,2) -> 3 | AP14: =VLOOKUP(AO14,[1]المرجع!$D$3:$E$12,2) -> ج | AQ14: =AO14*AM14 -> 6 | AR14: 2 | AS14: 100 | AT14: =VLOOKUP(AS14,[1]المرجع!$B$3:$C$12,2) -> 5 | AU14: =VLOOKUP(AT14,[1]المرجع!$D$3:$E$12,2) -> أ+ | AV14: =AT14*AR14 -> 10 | AW14: 2 | AX14: 68 | AY14: =VLOOKUP(AX14,[1]المرجع!$B$3:$C$12,2) -> 2.5 | AZ14: =VLOOKUP(AY14,[1]المرجع!$D$3:$E$12,2) -> د+ | BA14: =AY14*AW14 -> 5 | BB14: 2 | BC14: 75 | BD14: =VLOOKUP(BC14,[1]المرجع!$B$3:$C$12,2) -> 3.5 | BE14: =VLOOKUP(BD14,[1]المرجع!$D$3:$E$12,2) -> ج+ | BF14: =BD14*BB14 -> 7 | BG14: 2 | BH14: 84 | BI14: =VLOOKUP(BH14,[1]المرجع!$B$3:$C$12,2) -> 4 | BJ14: =VLOOKUP(BI14,[1]المرجع!$D$3:$E$12,2) -> ب | BK14: =BI14*BG14 -> 8 | BL14: =BK14+BF14+BA14+AV14+AQ14+AL14+AG14+AB14+W14+R14+M14+H14 -> 94.5 | BM14: =BG14+BB14+AW14+AR14+AM14+AH14+AC14+X14+S14+N14+I14+D14 -> 23 | BN14: =BL14/BM14 -> 4.1086957 | BP14: =VLOOKUP(BN14,[1]المرجع!D$3:F$12,3) -> جيد جد مرتفع | BQ14: =RANK(BN14,$BN$3:$BN$55) -> 17
... B55: 2024171 | C55: يوسف بابا دكوري | D55: 1 | E55: 23 | F55: =VLOOKUP(E55,[1]المرجع!$B$3:$C$12,2) -> 0 | G55: =VLOOKUP(F55,[1]المرجع!$D$3:$E$12,2) -> ه | H55: =F55*D55 -> 0 | I55: 2 | J55: 53 | K55: =VLOOKUP(J55,[1]المرجع!$B$3:$C$12,2) -> 2 | L55: =VLOOKUP(K55,[1]المرجع!$D$3:$E$12,2) -> د | M55: =K55*I55 -> 4 | N55: 2 | O55: 0 | P55: =VLOOKUP(O55,[1]المرجع!$B$3:$C$12,2) -> 0 | Q55: =VLOOKUP(P55,[1]المرجع!$D$3:$E$12,2) -> ه | R55: =P55*N55 -> 0 | S55: 2 | T55: 30 | U55: =VLOOKUP(T55,[1]المرجع!$B$3:$C$12,2) -> 0 | V55: =VLOOKUP(U55,[1]المرجع!$D$3:$E$12,2) -> ه | W55: =U55*S55 -> 0 | X55: 2 | Y55: 15 | Z55: =VLOOKUP(Y55,[1]المرجع!$B$3:$C$12,2) -> 0 | AA55: =VLOOKUP(Z55,[1]المرجع!$D$3:$E$12,2) -> ه | AB55: =Z55*X55 -> 0 | AC55: 2 | AD55: 0 | AE55: =VLOOKUP(AD55,[1]المرجع!$B$3:$C$12,2) -> 0 | AF55: =VLOOKUP(AE55,[1]المرجع!$D$3:$E$12,2) -> ه | AG55: =AE55*AC55 -> 0 | AH55: 2 | AI55: 35 | AJ55: =VLOOKUP(AI55,[1]المرجع!$B$3:$C$12,2) -> 0 | AK55: =VLOOKUP(AJ55,[1]المرجع!$D$3:$E$12,2) -> ه | AL55: =AJ55*AH55 -> 0 | AM55: 2 | AN55: 15 | AO55: =VLOOKUP(AN55,[1]المرجع!$B$3:$C$12,2) -> 0 | AP55: =VLOOKUP(AO55,[1]المرجع!$D$3:$E$12,2) -> ه | AQ55: =AO55*AM55 -> 0 | AR55: 2 | AS55: 50 | AT55: =VLOOKUP(AS55,[1]المرجع!$B$3:$C$12,2) -> 2 | AU55: =VLOOKUP(AT55,[1]المرجع!$D$3:$E$12,2) -> د | AV55: =AT55*AR55 -> 4 | AW55: 2 | AX55: 21 | AY55: =VLOOKUP(AX55,[1]المرجع!$B$3:$C$12,2) -> 0 | AZ55: =VLOOKUP(AY55,[1]المرجع!$D$3:$E$12,2) -> ه | BA55: =AY55*AW55 -> 0 | BB55: 2 | BC55: 35 | BD55: =VLOOKUP(BC55,[1]المرجع!$B$3:$C$12,2) -> 0 | BE55: =VLOOKUP(BD55,[1]المرجع!$D$3:$E$12,2) -> ه | BF55: =BD55*BB55 -> 0 | BG55: 2 | BH55: 66 | BI55: =VLOOKUP(BH55,[1]المرجع!$B$3:$C$12,2) -> 2.5 | BJ55: =VLOOKUP(BI55,[1]المرجع!$D$3:$E$12,2) -> د+ | BK55: =BI55*BG55 -> 5 | BL55: =BK55+BF55+BA55+AV55+AQ55+AL55+AG55+AB55+W55+R55+M55+H55 -> 13 | BM55: =BG55+BB55+AW55+AR55+AM55+AH55+AC55+X55+S55+N55+I55+D55 -> 23 | BN55: =BL55/BM55 -> 0.56521739 | BP55: =VLOOKUP(BN55,[1]المرجع!D$3:F$12,3) -> راسب | BQ55: =RANK(BN55,$BN$3:$BN$55) -> 53

Sheet المستوى الثاني 
B1: رقم الجامعي | C1: أسماء الطلبة | D1: الساعة | E1: القرآن الكريم | F1: الوزن | G1: الرمز | H1: النقاط | I1: الساعة | J1: رواة الحديث | K1: الوزن | L1: الرمز | M1: النقاط | N1: الساعة | O1: مصطلح الحديث | P1: الوزن | Q1: الرمز | R1: النقاط | S1: الساعة | T1: مناهج المحديثن | U1: الوزن | V1: الرمز | W1: النقاط | X1: الساعة | Y1: الحديث التحليلي | Z1: الوزن | AA1: الرمز | AB1: النقاط | AC1: الساعة | AD1: التفسير1 | AE1: الوزن | AF1: الرمز | AG1: النقاط | AH1: الساعة | AI1: الفقه 2 | AJ1: الوزن | AK1: الرمز | AL1: النقاط | AM1: الساعة | AN1: النحو (2) | AO1: الوزن | AP1: الرمز | AQ1: النقاط | AR1: الساعة | AS1: الحاسوب | AT1: الوزن | AU1: الرمز | AV1: النقاط | AW1: الساعة | AX1: English(2) | AY1: الوزن | AZ1: الرمز | BA1: النقاط | BB1: مجموع النقاط | BC1: مجموع الساعات | BD1: المعدل الفصلي | BE1: المعدل التراكمي | BF1: التقدير | BG1: الترتيب
B2: 2024174 | C2: حمزة أبوبكر كابا | D2: 1 | E2: 100 | F2: =VLOOKUP(E2,المرجع!$B$2:$C$11,2) -> 5 | G2: =VLOOKUP(F2,المرجع!$D$2:$E$11,2) -> أ+ | H2: =F2*D2 -> 5 | I2: 2 | J2: 100 | K2: =VLOOKUP(J2,المرجع!$B$2:$C$11,2) -> 5 | L2: =VLOOKUP(K2,[1]المرجع!$D$3:$E$12,2) -> أ+ | M2: =K2*I2 -> 10 | N2: 3 | O2: 100 | P2: =VLOOKUP(O2,المرجع!$B$2:$C$11,2) -> 5 | Q2: =VLOOKUP(P2,[1]المرجع!$D$3:$E$12,2) -> أ+ | R2: =P2*N2 -> 15 | S2: 3 | T2: 100 | U2: =VLOOKUP(T2,المرجع!$B$2:$C$11,2) -> 5 | V2: =VLOOKUP(U2,[1]المرجع!$D$3:$E$12,2) -> أ+ | W2: =U2*S2 -> 15 | X2: 3 | Y2: 100 | Z2: =VLOOKUP(Y2,المرجع!$B$2:$C$11,2) -> 5 | AA2: =VLOOKUP(Z2,[1]المرجع!$D$3:$E$12,2) -> أ+ | AB2: =Z2*X2 -> 15 | AC2: 2 | AD2: 100 | AE2: =VLOOKUP(AD2,المرجع!$B$2:$C$11,2) -> 5 | AF2: =VLOOKUP(AE2,[1]المرجع!$D$3:$E$12,2) -> أ+ | AG2: =AE2*AC2 -> 10 | AH2: 2 | AI2: 99 | AJ2: =VLOOKUP(AI2,المرجع!$B$2:$C$11,2) -> 5 | AK2: =VLOOKUP(AJ2,[1]المرجع!$D$3:$E$12,2) -> أ+ | AL2: =AJ2*AH2 -> 10 | AM2: 2 | AN2: 100 | AO2: =VLOOKUP(AN2,المرجع!$B$2:$C$11,2) -> 5 | AP2: =VLOOKUP(AO2,[1]المرجع!$D$3:$E$12,2) -> أ+ | AQ2: =AO2*AM2 -> 10 | AR2: 2 | AS2: 100 | AT2: =VLOOKUP(AS2,المرجع!$B$2:$C$11,2) -> 5 | AU2: =VLOOKUP(AT2,[1]المرجع!$D$3:$E$12,2) -> أ+ | AV2: =AT2*AR2 -> 10 | AW2: 2 | AX2: 94 | AY2: =VLOOKUP(AX2,المرجع!$B$2:$C$11,2) -> 4.75 | AZ2: =VLOOKUP(AY2,[1]المرجع!$D$3:$E$12,2) -> أ | BA2: =AY2*AW2 -> 9.5 | BB2: =BA2+AV2+AQ2+AL2+AG2+AB2+W2+R2+M2+H2 -> 109.5 | BC2: =AW2+AR2+AM2+AH2+AC2+X2+S2+N2+I2+D2 -> 22 | BD2: =BB2/BC2 -> 4.9772727 | BE2: =(BB2+'المستوى الأول '!BL3)/('المستوى الأول '!BM3+'المستوى الثاني '!BC2) -> 4.9777778 | BF2: =VLOOKUP(BE2,المرجع!$D$3:$F$11,3,TRUE) -> ممتاز مرتفع | BG2: =RANK(BD2,$BD$2:$BD$46) -> 1
B3: 2024156 | C3: مختار إبراهيم كمارا | D3: 1 | E3: 99 | F3: =VLOOKUP(E3,المرجع!$B$2:$C$11,2) -> 5 | G3: =VLOOKUP(F3,المرجع!$D$2:$E$11,2) -> أ+ | H3: =F3*D3 -> 5 | I3: 2 | J3: 87 | K3: =VLOOKUP(J3,المرجع!$B$2:$C$11,2) -> 4.5 | L3: =VLOOKUP(K3,[1]المرجع!$D$3:$E$12,2) -> ب+ | M3: =K3*I3 -> 9 | N3: 3 | O3: 99 | P3: =VLOOKUP(O3,المرجع!$B$2:$C$11,2) -> 5 | Q3: =VLOOKUP(P3,[1]المرجع!$D$3:$E$12,2) -> أ+ | R3: =P3*N3 -> 15 | S3: 3 | T3: 96 | U3: =VLOOKUP(T3,المرجع!$B$2:$C$11,2) -> 5 | V3: =VLOOKUP(U3,[1]المرجع!$D$3:$E$12,2) -> أ+ | W3: =U3*S3 -> 15 | X3: 3 | Y3: 100 | Z3: =VLOOKUP(Y3,المرجع!$B$2:$C$11,2) -> 5 | AA3: =VLOOKUP(Z3,[1]المرجع!$D$3:$E$12,2) -> أ+ | AB3: =Z3*X3 -> 15 | AC3: 2 | AD3: 89 | AE3: =VLOOKUP(AD3,المرجع!$B$2:$C$11,2) -> 4.5 | AF3: =VLOOKUP(AE3,[1]المرجع!$D$3:$E$12,2) -> ب+ | AG3: =AE3*AC3 -> 9 | AH3: 2 | AI3: 91 | AJ3: =VLOOKUP(AI3,المرجع!$B$2:$C$11,2) -> 4.75 | AK3: =VLOOKUP(AJ3,[1]المرجع!$D$3:$E$12,2) -> أ | AL3: =AJ3*AH3 -> 9.5 | AM3: 2 | AN3: 95 | AO3: =VLOOKUP(AN3,المرجع!$B$2:$C$11,2) -> 5 | AP3: =VLOOKUP(AO3,[1]المرجع!$D$3:$E$12,2) -> أ+ | AQ3: =AO3*AM3 -> 10 | AR3: 2 | AS3: 100 | AT3: =VLOOKUP(AS3,المرجع!$B$2:$C$11,2) -> 5 | AU3: =VLOOKUP(AT3,[1]المرجع!$D$3:$E$12,2) -> أ+ | AV3: =AT3*AR3 -> 10 | AW3: 2 | AX3: 100 | AY3: =VLOOKUP(AX3,المرجع!$B$2:$C$11,2) -> 5 | AZ3: =VLOOKUP(AY3,[1]المرجع!$D$3:$E$12,2) -> أ+ | BA3: =AY3*AW3 -> 10 | BB3: =BA3+AV3+AQ3+AL3+AG3+AB3+W3+R3+M3+H3 -> 107.5 | BC3: =AW3+AR3+AM3+AH3+AC3+X3+S3+N3+I3+D3 -> 22 | BD3: =BB3/BC3 -> 4.8863636 | BE3: =(BB3+'المستوى الأول '!BL4)/('المستوى الأول '!BM4+'المستوى الثاني '!BC3) -> 4.7888889 | BF3: =VLOOKUP(BE3,المرجع!$D$3:$F$11,3,TRUE) -> ممتاز مرتفع | BG3: =RANK(BD3,$BD$2:$BD$46) -> 2
B4: 2024154 | C4: عمر شريف ماني | D4: 1 | E4: 96 | F4: =VLOOKUP(E4,المرجع!$B$2:$C$11,2) -> 5 | G4: =VLOOKUP(F4,المرجع!$D$2:$E$11,2) -> أ+ | H4: =F4*D4 -> 5 | I4: 2 | J4: 82 | K4: =VLOOKUP(J4,المرجع!$B$2:$C$11,2) -> 4 | L4: =VLOOKUP(K4,[1]المرجع!$D$3:$E$12,2) -> ب | M4: =K4*I4 -> 8 | N4: 3 | O4: 100 | P4: =VLOOKUP(O4,المرجع!$B$2:$C$11,2) -> 5 | Q4: =VLOOKUP(P4,[1]المرجع!$D$3:$E$12,2) -> أ+ | R4: =P4*N4 -> 15 | S4: 3 | T4: 92 | U4: =VLOOKUP(T4,المرجع!$B$2:$C$11,2) -> 4.75 | V4: =VLOOKUP(U4,[1]المرجع!$D$3:$E$12,2) -> أ | W4: =U4*S4 -> 14.25 | X4: 3 | Y4: 100 | Z4: =VLOOKUP(Y4,المرجع!$B$2:$C$11,2) -> 5 | AA4: =VLOOKUP(Z4,[1]المرجع!$D$3:$E$12,2) -> أ+ | AB4: =Z4*X4 -> 15 | AC4: 2 | AD4: 89 | AE4: =VLOOKUP(AD4,المرجع!$B$2:$C$11,2) -> 4.5 | AF4: =VLOOKUP(AE4,[1]المرجع!$D$3:$E$12,2) -> ب+ | AG4: =AE4*AC4 -> 9 | AH4: 2 | AI4: 90 | AJ4: =VLOOKUP(AI4,المرجع!$B$2:$C$11,2) -> 4.75 | AK4: =VLOOKUP(AJ4,[1]المرجع!$D$3:$E$12,2) -> أ | AL4: =AJ4*AH4 -> 9.5 | AM4: 2 | AN4: 95 | AO4: =VLOOKUP(AN4,المرجع!$B$2:$C$11,2) -> 5 | AP4: =VLOOKUP(AO4,[1]المرجع!$D$3:$E$12,2) -> أ+ | AQ4: =AO4*AM4 -> 10 | AR4: 2 | AS4: 90 | AT4: =VLOOKUP(AS4,المرجع!$B$2:$C$11,2) -> 4.75 | AU4: =VLOOKUP(AT4,[1]المرجع!$D$3:$E$12,2) -> أ | AV4: =AT4*AR4 -> 9.5 | AW4: 2 | AX4: 94 | AY4: =VLOOKUP(AX4,المرجع!$B$2:$C$11,2) -> 4.75 | AZ4: =VLOOKUP(AY4,[1]المرجع!$D$3:$E$12,2) -> أ | BA4: =AY4*AW4 -> 9.5 | BB4: =BA4+AV4+AQ4+AL4+AG4+AB4+W4+R4+M4+H4 -> 104.75 | BC4: =AW4+AR4+AM4+AH4+AC4+X4+S4+N4+I4+D4 -> 22 | BD4: =BB4/BC4 -> 4.7613636 | BE4: =(BB4+'المستوى الأول '!BL5)/('المستوى الأول '!BM5+'المستوى الثاني '!BC4) -> 4.7611111 | BF4: =VLOOKUP(BE4,المرجع!$D$3:$F$11,3,TRUE) -> ممتاز مرتفع | BG4: =RANK(BD4,$BD$2:$BD$46) -> 4
B5: 2024153 | C5: مصطفى أبوبكر منجا | D5: 1 | E5: 97 | F5: =VLOOKUP(E5,المرجع!$B$2:$C$11,2) -> 5 | G5: =VLOOKUP(F5,المرجع!$D$2:$E$11,2) -> أ+ | H5: =F5*D5 -> 5 | I5: 2 | J5: 83 | K5: =VLOOKUP(J5,المرجع!$B$2:$C$11,2) -> 4 | L5: =VLOOKUP(K5,[1]المرجع!$D$3:$E$12,2) -> ب | M5: =K5*I5 -> 8 | N5: 3 | O5: 100 | P5: =VLOOKUP(O5,المرجع!$B$2:$C$11,2) -> 5 | Q5: =VLOOKUP(P5,[1]المرجع!$D$3:$E$12,2) -> أ+ | R5: =P5*N5 -> 15 | S5: 3 | T5: 97 | U5: =VLOOKUP(T5,المرجع!$B$2:$C$11,2) -> 5 | V5: =VLOOKUP(U5,[1]المرجع!$D$3:$E$12,2) -> أ+ | W5: =U5*S5 -> 15 | X5: 3 | Y5: 95 | Z5: =VLOOKUP(Y5,المرجع!$B$2:$C$11,2) -> 5 | AA5: =VLOOKUP(Z5,[1]المرجع!$D$3:$E$12,2) -> أ+ | AB5: =Z5*X5 -> 15 | AC5: 2 | AD5: 92 | AE5: =VLOOKUP(AD5,المرجع!$B$2:$C$11,2) -> 4.75 | AF5: =VLOOKUP(AE5,[1]المرجع!$D$3:$E$12,2) -> أ | AG5: =AE5*AC5 -> 9.5 | AH5: 2 | AI5: 90 | AJ5: =VLOOKUP(AI5,المرجع!$B$2:$C$11,2) -> 4.75 | AK5: =VLOOKUP(AJ5,[1]المرجع!$D$3:$E$12,2) -> أ | AL5: =AJ5*AH5 -> 9.5 | AM5: 2 | AN5: 94 | AO5: =VLOOKUP(AN5,المرجع!$B$2:$C$11,2) -> 4.75 | AP5: =VLOOKUP(AO5,[1]المرجع!$D$3:$E$12,2) -> أ | AQ5: =AO5*AM5 -> 9.5 | AR5: 2 | AS5: 85 | AT5: =VLOOKUP(AS5,المرجع!$B$2:$C$11,2) -> 4.5 | AU5: =VLOOKUP(AT5,[1]المرجع!$D$3:$E$12,2) -> ب+ | AV5: =AT5*AR5 -> 9 | AW5: 2 | AX5: 94 | AY5: =VLOOKUP(AX5,المرجع!$B$2:$C$11,2) -> 4.75 | AZ5: =VLOOKUP(AY5,[1]المرجع!$D$3:$E$12,2) -> أ | BA5: =AY5*AW5 -> 9.5 | BB5: =BA5+AV5+AQ5+AL5+AG5+AB5+W5+R5+M5+H5 -> 105 | BC5: =AW5+AR5+AM5+AH5+AC5+X5+S5+N5+I5+D5 -> 22 | BD5: =BB5/BC5 -> 4.7727273 | BE5: =(BB5+'المستوى الأول '!BL6)/('المستوى الأول '!BM6+'المستوى الثاني '!BC5) -> 4.7722222 | BF5: =VLOOKUP(BE5,المرجع!$D$3:$F$11,3,TRUE) -> ممتاز مرتفع | BG5: =RANK(BD5,$BD$2:$BD$46) -> 3
B6: 2024180 | C6: حليمة مجتبى جالو | D6: 1 | E6: 90 | F6: =VLOOKUP(E6,المرجع!$B$2:$C$11,2) -> 4.75 | G6: =VLOOKUP(F6,المرجع!$D$2:$E$11,2) -> أ | H6: =F6*D6 -> 4.75 | I6: 2 | J6: 64 | K6: =VLOOKUP(J6,المرجع!$B$2:$C$11,2) -> 2 | L6: =VLOOKUP(K6,[1]المرجع!$D$3:$E$12,2) -> د | M6: =K6*I6 -> 4 | N6: 3 | O6: 95 | P6: =VLOOKUP(O6,المرجع!$B$2:$C$11,2) -> 5 | Q6: =VLOOKUP(P6,[1]المرجع!$D$3:$E$12,2) -> أ+ | R6: =P6*N6 -> 15 | S6: 3 | T6: 96 | U6: =VLOOKUP(T6,المرجع!$B$2:$C$11,2) -> 5 | V6: =VLOOKUP(U6,[1]المرجع!$D$3:$E$12,2) -> أ+ | W6: =U6*S6 -> 15 | X6: 3 | Y6: 95 | Z6: =VLOOKUP(Y6,المرجع!$B$2:$C$11,2) -> 5 | AA6: =VLOOKUP(Z6,[1]المرجع!$D$3:$E$12,2) -> أ+ | AB6: =Z6*X6 -> 15 | AC6: 2 | AD6: 93 | AE6: =VLOOKUP(AD6,المرجع!$B$2:$C$11,2) -> 4.75 | AF6: =VLOOKUP(AE6,[1]المرجع!$D$3:$E$12,2) -> أ | AG6: =AE6*AC6 -> 9.5 | AH6: 2 | AI6: 100 | AJ6: =VLOOKUP(AI6,المرجع!$B$2:$C$11,2) -> 5 | AK6: =VLOOKUP(AJ6,[1]المرجع!$D$3:$E$12,2) -> أ+ | AL6: =AJ6*AH6 -> 10 | AM6: 2 | AN6: 85 | AO6: =VLOOKUP(AN6,المرجع!$B$2:$C$11,2) -> 4.5 | AP6: =VLOOKUP(AO6,[1]المرجع!$D$3:$E$12,2) -> ب+ | AQ6: =AO6*AM6 -> 9 | AR6: 2 | AS6: 100 | AT6: =VLOOKUP(AS6,المرجع!$B$2:$C$11,2) -> 5 | AU6: =VLOOKUP(AT6,[1]المرجع!$D$3:$E$12,2) -> أ+ | AV6: =AT6*AR6 -> 10 | AW6: 2 | AX6: 94 | AY6: =VLOOKUP(AX6,المرجع!$B$2:$C$11,2) -> 4.75 | AZ6: =VLOOKUP(AY6,[1]المرجع!$D$3:$E$12,2) -> أ | BA6: =AY6*AW6 -> 9.5 | BB6: =BA6+AV6+AQ6+AL6+AG6+AB6+W6+R6+M6+H6 -> 101.75 | BC6: =AW6+AR6+AM6+AH6+AC6+X6+S6+N6+I6+D6 -> 22 | BD6: =BB6/BC6 -> 4.625 | BE6: =(BB6+'المستوى الأول '!BL7)/('المستوى الأول '!BM7+'المستوى الثاني '!BC6) -> 4.6833333 | BF6: =VLOOKUP(BE6,المرجع!$D$3:$F$11,3,TRUE) -> ممتاز | BG6: =RANK(BD6,$BD$2:$BD$46) -> 6
B7: 2024205 | C7: فاطمة بنغالي جاورى | D7: 1 | E7: 92 | F7: =VLOOKUP(E7,المرجع!$B$2:$C$11,2) -> 4.75 | G7: =VLOOKUP(F7,المرجع!$D$2:$E$11,2) -> أ | H7: =F7*D7 -> 4.75 | I7: 2 | J7: 82 | K7: =VLOOKUP(J7,المرجع!$B$2:$C$11,2) -> 4 | L7: =VLOOKUP(K7,[1]المرجع!$D$3:$E$12,2) -> ب | M7: =K7*I7 -> 8 | N7: 3 | O7: 87 | P7: =VLOOKUP(O7,المرجع!$B$2:$C$11,2) -> 4.5 | Q7: =VLOOKUP(P7,[1]المرجع!$D$3:$E$12,2) -> ب+ | R7: =P7*N7 -> 13.5 | S7: 3 | T7: 93 | U7: =VLOOKUP(T7,المرجع!$B$2:$C$11,2) -> 4.75 | V7: =VLOOKUP(U7,[1]المرجع!$D$3:$E$12,2) -> أ | W7: =U7*S7 -> 14.25 | X7: 3 | Y7: 95 | Z7: =VLOOKUP(Y7,المرجع!$B$2:$C$11,2) -> 5 | AA7: =VLOOKUP(Z7,[1]المرجع!$D$3:$E$12,2) -> أ+ | AB7: =Z7*X7 -> 15 | AC7: 2 | AD7: 88 | AE7: =VLOOKUP(AD7,المرجع!$B$2:$C$11,2) -> 4.5 | AF7: =VLOOKUP(AE7,[1]المرجع!$D$3:$E$12,2) -> ب+ | AG7: =AE7*AC7 -> 9 | AH7: 2 | AI7: 100 | AJ7: =VLOOKUP(AI7,المرجع!$B$2:$C$11,2) -> 5 | AK7: =VLOOKUP(AJ7,[1]المرجع!$D$3:$E$12,2) -> أ+ | AL7: =AJ7*AH7 -> 10 | AM7: 2 | AN7: 90 | AO7: =VLOOKUP(AN7,المرجع!$B$2:$C$11,2) -> 4.75 | AP7: =VLOOKUP(AO7,[1]المرجع!$D$3:$E$12,2) -> أ | AQ7: =AO7*AM7 -> 9.5 | AR7: 2 | AS7: 97 | AT7: =VLOOKUP(AS7,المرجع!$B$2:$C$11,2) -> 5 | AU7: =VLOOKUP(AT7,[1]المرجع!$D$3:$E$12,2) -> أ+ | AV7: =AT7*AR7 -> 10 | AW7: 2 | AX7: 81 | AY7: =VLOOKUP(AX7,المرجع!$B$2:$C$11,2) -> 4 | AZ7: =VLOOKUP(AY7,[1]المرجع!$D$3:$E$12,2) -> ب | BA7: =AY7*AW7 -> 8 | BB7: =BA7+AV7+AQ7+AL7+AG7+AB7+W7+R7+M7+H7 -> 102 | BC7: =AW7+AR7+AM7+AH7+AC7+X7+S7+N7+I7+D7 -> 22 | BD7: =BB7/BC7 -> 4.6363636 | BE7: =(BB7+'المستوى الأول '!BL8)/('المستوى الأول '!BM8+'المستوى الثاني '!BC7) -> 4.5888889 | BF7: =VLOOKUP(BE7,المرجع!$D$3:$F$11,3,TRUE) -> جيد جد مرتفع | BG7: =RANK(BD7,$BD$2:$BD$46) -> 5
B8: 2024178 | C8: عائشة مبارك ديكو | D8: 1 | E8: 90 | F8: =VLOOKUP(E8,المرجع!$B$2:$C$11,2) -> 4.75 | G8: =VLOOKUP(F8,المرجع!$D$2:$E$11,2) -> أ | H8: =F8*D8 -> 4.75 | I8: 2 | J8: 68 | K8: =VLOOKUP(J8,المرجع!$B$2:$C$11,2) -> 2.5 | L8: =VLOOKUP(K8,[1]المرجع!$D$3:$E$12,2) -> د+ | M8: =K8*I8 -> 5 | N8: 3 | O8: 93 | P8: =VLOOKUP(O8,المرجع!$B$2:$C$11,2) -> 4.75 | Q8: =VLOOKUP(P8,[1]المرجع!$D$3:$E$12,2) -> أ | R8: =P8*N8 -> 14.25 | S8: 3 | T8: 96 | U8: =VLOOKUP(T8,المرجع!$B$2:$C$11,2) -> 5 | V8: =VLOOKUP(U8,[1]المرجع!$D$3:$E$12,2) -> أ+ | W8: =U8*S8 -> 15 | X8: 3 | Y8: 97 | Z8: =VLOOKUP(Y8,المرجع!$B$2:$C$11,2) -> 5 | AA8: =VLOOKUP(Z8,[1]المرجع!$D$3:$E$12,2) -> أ+ | AB8: =Z8*X8 -> 15 | AC8: 2 | AD8: 87 | AE8: =VLOOKUP(AD8,المرجع!$B$2:$C$11,2) -> 4.5 | AF8: =VLOOKUP(AE8,[1]المرجع!$D$3:$E$12,2) -> ب+ | AG8: =AE8*AC8 -> 9 | AH8: 2 | AI8: 100 | AJ8: =VLOOKUP(AI8,المرجع!$B$2:$C$11,2) -> 5 | AK8: =VLOOKUP(AJ8,[1]المرجع!$D$3:$E$12,2) -> أ+ | AL8: =AJ8*AH8 -> 10 | AM8: 2 | AN8: 85 | AO8: =VLOOKUP(AN8,المرجع!$B$2:$C$11,2) -> 4.5 | AP8: =VLOOKUP(AO8,[1]المرجع!$D$3:$E$12,2) -> ب+ | AQ8: =AO8*AM8 -> 9 | AR8: 2 | AS8: 85 | AT8: =VLOOKUP(AS8,المرجع!$B$2:$C$11,2) -> 4.5 | AU8: =VLOOKUP(AT8,[1]المرجع!$D$3:$E$12,2) -> ب+ | AV8: =AT8*AR8 -> 9 | AW8: 2 | AX8: 100 | AY8: =VLOOKUP(AX8,المرجع!$B$2:$C$11,2) -> 5 | AZ8: =VLOOKUP(AY8,[1]المرجع!$D$3:$E$12,2) -> أ+ | BA8: =AY8*AW8 -> 10 | BB8: =BA8+AV8+AQ8+AL8+AG8+AB8+W8+R8+M8+H8 -> 101 | BC8: =AW8+AR8+AM8+AH8+AC8+X8+S8+N8+I8+D8 -> 22 | BD8: =BB8/BC8 -> 4.5909091 | BE8: =(BB8+'المستوى الأول '!BL9)/('المستوى الأول '!BM9+'المستوى الثاني '!BC8) -> 4.5222222 | BF8: =VLOOKUP(BE8,المرجع!$D$3:$F$11,3,TRUE) -> جيد جد مرتفع | BG8: =RANK(BD8,$BD$2:$BD$46) -> 7
B9: 2024304 | C9: زينب محمد كمارا | D9: 1 | E9: 96 | F9: =VLOOKUP(E9,المرجع!$B$2:$C$11,2) -> 5 | G9: =VLOOKUP(F9,المرجع!$D$2:$E$11,2) -> أ+ | H9: =F9*D9 -> 5 | I9: 2 | J9: 73 | K9: =VLOOKUP(J9,المرجع!$B$2:$C$11,2) -> 3 | L9: =VLOOKUP(K9,[1]المرجع!$D$3:$E$12,2) -> ج | M9: =K9*I9 -> 6 | N9: 3 | O9: 80 | P9: =VLOOKUP(O9,المرجع!$B$2:$C$11,2) -> 4 | Q9: =VLOOKUP(P9,[1]المرجع!$D$3:$E$12,2) -> ب | R9: =P9*N9 -> 12 | S9: 3 | T9: 100 | U9: =VLOOKUP(T9,المرجع!$B$2:$C$11,2) -> 5 | V9: =VLOOKUP(U9,[1]المرجع!$D$3:$E$12,2) -> أ+ | W9: =U9*S9 -> 15 | X9: 3 | Y9: 92 | Z9: =VLOOKUP(Y9,المرجع!$B$2:$C$11,2) -> 4.75 | AA9: =VLOOKUP(Z9,[1]المرجع!$D$3:$E$12,2) -> أ | AB9: =Z9*X9 -> 14.25 | AC9: 2 | AD9: 92 | AE9: =VLOOKUP(AD9,المرجع!$B$2:$C$11,2) -> 4.75 | AF9: =VLOOKUP(AE9,[1]المرجع!$D$3:$E$12,2) -> أ | AG9: =AE9*AC9 -> 9.5 | AH9: 2 | AI9: 100 | AJ9: =VLOOKUP(AI9,المرجع!$B$2:$C$11,2) -> 5 | AK9: =VLOOKUP(AJ9,[1]المرجع!$D$3:$E$12,2) -> أ+ | AL9: =AJ9*AH9 -> 10 | AM9: 2 | AN9: 90 | AO9: =VLOOKUP(AN9,المرجع!$B$2:$C$11,2) -> 4.75 | AP9: =VLOOKUP(AO9,[1]المرجع!$D$3:$E$12,2) -> أ | AQ9: =AO9*AM9 -> 9.5 | AR9: 2 | AS9: 88 | AT9: =VLOOKUP(AS9,المرجع!$B$2:$C$11,2) -> 4.5 | AU9: =VLOOKUP(AT9,[1]المرجع!$D$3:$E$12,2) -> ب+ | AV9: =AT9*AR9 -> 9 | AW9: 2 | AX9: 81 | AY9: =VLOOKUP(AX9,المرجع!$B$2:$C$11,2) -> 4 | AZ9: =VLOOKUP(AY9,[1]المرجع!$D$3:$E$12,2) -> ب | BA9: =AY9*AW9 -> 8 | BB9: =BA9+AV9+AQ9+AL9+AG9+AB9+W9+R9+M9+H9 -> 98.25 | BC9: =AW9+AR9+AM9+AH9+AC9+X9+S9+N9+I9+D9 -> 22 | BD9: =BB9/BC9 -> 4.4659091 | BE9: =(BB9+'المستوى الأول '!BL10)/('المستوى الأول '!BM10+'المستوى الثاني '!BC9) -> 4.4722222 | BF9: =VLOOKUP(BE9,المرجع!$D$3:$F$11,3,TRUE) -> جيد جد مرتفع | BG9: =RANK(BD9,$BD$2:$BD$46) -> 8
B10: 2024152 | C10: عبدالله شعيب كروما | D10: 1 | E10: 93 | F10: =VLOOKUP(E10,المرجع!$B$2:$C$11,2) -> 4.75 | G10: =VLOOKUP(F10,المرجع!$D$2:$E$11,2) -> أ | H10: =F10*D10 -> 4.75 | I10: 2 | J10: 72 | K10: =VLOOKUP(J10,المرجع!$B$2:$C$11,2) -> 3 | L10: =VLOOKUP(K10,[1]المرجع!$D$3:$E$12,2) -> ج | M10: =K10*I10 -> 6 | N10: 3 | O10: 97 | P10: =VLOOKUP(O10,المرجع!$B$2:$C$11,2) -> 5 | Q10: =VLOOKUP(P10,[1]المرجع!$D$3:$E$12,2) -> أ+ | R10: =P10*N10 -> 15 | S10: 3 | T10: 99 | U10: =VLOOKUP(T10,المرجع!$B$2:$C$11,2) -> 5 | V10: =VLOOKUP(U10,[1]المرجع!$D$3:$E$12,2) -> أ+ | W10: =U10*S10 -> 15 | X10: 3 | Y10: 100 | Z10: =VLOOKUP(Y10,المرجع!$B$2:$C$11,2) -> 5 | AA10: =VLOOKUP(Z10,[1]المرجع!$D$3:$E$12,2) -> أ+ | AB10: =Z10*X10 -> 15 | AC10: 2 | AD10: 89 | AE10: =VLOOKUP(AD10,المرجع!$B$2:$C$11,2) -> 4.5 | AF10: =VLOOKUP(AE10,[1]المرجع!$D$3:$E$12,2) -> ب+ | AG10: =AE10*AC10 -> 9 | AH10: 2 | AI10: 88 | AJ10: =VLOOKUP(AI10,المرجع!$B$2:$C$11,2) -> 4.5 | AK10: =VLOOKUP(AJ10,[1]المرجع!$D$3:$E$12,2) -> ب+ | AL10: =AJ10*AH10 -> 9 | AM10: 2 | AN10: 88 | AO10: =VLOOKUP(AN10,المرجع!$B$2:$C$11,2) -> 4.5 | AP10: =VLOOKUP(AO10,[1]المرجع!$D$3:$E$12,2) -> ب+ | AQ10: =AO10*AM10 -> 9 | AR10: 2 | AS10: 86 | AT10: =VLOOKUP(AS10,المرجع!$B$2:$C$11,2) -> 4.5 | AU10: =VLOOKUP(AT10,[1]المرجع!$D$3:$E$12,2) -> ب+ | AV10: =AT10*AR10 -> 9 | AW10: 2 | AX10: 68 | AY10: =VLOOKUP(AX10,المرجع!$B$2:$C$11,2) -> 2.5 | AZ10: =VLOOKUP(AY10,[1]المرجع!$D$3:$E$12,2) -> د+ | BA10: =AY10*AW10 -> 5 | BB10: =BA10+AV10+AQ10+AL10+AG10+AB10+W10+R10+M10+H10 -> 96.75 | BC10: =AW10+AR10+AM10+AH10+AC10+X10+S10+N10+I10+D10 -> 22 | BD10: =BB10/BC10 -> 4.3977273 | BE10: =(BB10+'المستوى الأول '!BL11)/('المستوى الأول '!BM11+'المستوى الثاني '!BC10) -> 4.3944444 | BF10: =VLOOKUP(BE10,المرجع!$D$3:$F$11,3,TRUE) -> جيد جد مرتفع | BG10: =RANK(BD10,$BD$2:$BD$46) -> 9
B11: 2024210 | C11: أمر محمد تنكارا | D11: 1 | E11: 95 | F11: =VLOOKUP(E11,المرجع!$B$2:$C$11,2) -> 5 | G11: =VLOOKUP(F11,المرجع!$D$2:$E$11,2) -> أ+ | H11: =F11*D11 -> 5 | I11: 2 | J11: 80 | K11: =VLOOKUP(J11,المرجع!$B$2:$C$11,2) -> 4 | L11: =VLOOKUP(K11,[1]المرجع!$D$3:$E$12,2) -> ب | M11: =K11*I11 -> 8 | N11: 3 | O11: 95 | P11: =VLOOKUP(O11,المرجع!$B$2:$C$11,2) -> 5 | Q11: =VLOOKUP(P11,[1]المرجع!$D$3:$E$12,2) -> أ+ | R11: =P11*N11 -> 15 | S11: 3 | T11: 94 | U11: =VLOOKUP(T11,المرجع!$B$2:$C$11,2) -> 4.75 | V11: =VLOOKUP(U11,[1]المرجع!$D$3:$E$12,2) -> أ | W11: =U11*S11 -> 14.25 | X11: 3 | Y11: 100 | Z11: =VLOOKUP(Y11,المرجع!$B$2:$C$11,2) -> 5 | AA11: =VLOOKUP(Z11,[1]المرجع!$D$3:$E$12,2) -> أ+ | AB11: =Z11*X11 -> 15 | AC11: 2 | AD11: 92 | AE11: =VLOOKUP(AD11,المرجع!$B$2:$C$11,2) -> 4.75 | AF11: =VLOOKUP(AE11,[1]المرجع!$D$3:$E$12,2) -> أ | AG11: =AE11*AC11 -> 9.5 | AH11: 2 | AI11: 73 | AJ11: =VLOOKUP(AI11,المرجع!$B$2:$C$11,2) -> 3 | AK11: =VLOOKUP(AJ11,[1]المرجع!$D$3:$E$12,2) -> ج | AL11: =AJ11*AH11 -> 6 | AM11: 2 | AN11: 100 | AO11: =VLOOKUP(AN11,المرجع!$B$2:$C$11,2) -> 5 | AP11: =VLOOKUP(AO11,[1]المرجع!$D$3:$E$12,2) -> أ+ | AQ11: =AO11*AM11 -> 10 | AR11: 2 | AS11: 90 | AT11: =VLOOKUP(AS11,المرجع!$B$2:$C$11,2) -> 4.75 | AU11: =VLOOKUP(AT11,[1]المرجع!$D$3:$E$12,2) -> أ | AV11: =AT11*AR11 -> 9.5 | AW11: 2 | AX11: 50 | AY11: =VLOOKUP(AX11,المرجع!$B$2:$C$11,2) -> 2 | AZ11: =VLOOKUP(AY11,[1]المرجع!$D$3:$E$12,2) -> د | BA11: =AY11*AW11 -> 4 | BB11: =BA11+AV11+AQ11+AL11+AG11+AB11+W11+R11+M11+H11 -> 96.25 | BC11: =AW11+AR11+AM11+AH11+AC11+X11+S11+N11+I11+D11 -> 22 | BD11: =BB11/BC11 -> 4.375 | BE11: =(BB11+'المستوى الأول '!BL12)/('المستوى الأول '!BM12+'المستوى الثاني '!BC11) -> 4.3277778 | BF11: =VLOOKUP(BE11,المرجع!$D$3:$F$11,3,TRUE) -> جيد جد مرتفع | BG11: =RANK(BD11,$BD$2:$BD$46) -> 10
B12: 2024157 | C12: جعفر موسى درامي | D12: 1 | E12: 90 | F12: =VLOOKUP(E12,المرجع!$B$2:$C$11,2) -> 4.75 | G12: =VLOOKUP(F12,المرجع!$D$2:$E$11,2) -> أ | H12: =F12*D12 -> 4.75 | I12: 2 | J12: 74 | K12: =VLOOKUP(J12,المرجع!$B$2:$C$11,2) -> 3 | L12: =VLOOKUP(K12,[1]المرجع!$D$3:$E$12,2) -> ج | M12: =K12*I12 -> 6 | N12: 3 | O12: 100 | P12: =VLOOKUP(O12,المرجع!$B$2:$C$11,2) -> 5 | Q12: =VLOOKUP(P12,[1]المرجع!$D$3:$E$12,2) -> أ+ | R12: =P12*N12 -> 15 | S12: 3 | T12: 96 | U12: =VLOOKUP(T12,المرجع!$B$2:$C$11,2) -> 5 | V12: =VLOOKUP(U12,[1]المرجع!$D$3:$E$12,2) -> أ+ | W12: =U12*S12 -> 15 | X12: 3 | Y12: 95 | Z12: =VLOOKUP(Y12,المرجع!$B$2:$C$11,2) -> 5 | AA12: =VLOOKUP(Z12,[1]المرجع!$D$3:$E$12,2) -> أ+ | AB12: =Z12*X12 -> 15 | AC12: 2 | AD12: 84 | AE12: =VLOOKUP(AD12,المرجع!$B$2:$C$11,2) -> 4 | AF12: =VLOOKUP(AE12,[1]المرجع!$D$3:$E$12,2) -> ب | AG12: =AE12*AC12 -> 8 | AH12: 2 | AI12: 92 | AJ12: =VLOOKUP(AI12,المرجع!$B$2:$C$11,2) -> 4.75 | AK12: =VLOOKUP(AJ12,[1]المرجع!$D$3:$E$12,2) -> أ | AL12: =AJ12*AH12 -> 9.5 | AM12: 2 | AN12: 85 | AO12: =VLOOKUP(AN12,المرجع!$B$2:$C$11,2) -> 4.5 | AP12: =VLOOKUP(AO12,[1]المرجع!$D$3:$E$12,2) -> ب+ | AQ12: =AO12*AM12 -> 9 | AR12: 2 | AS12: 90 | AT12: =VLOOKUP(AS12,المرجع!$B$2:$C$11,2) -> 4.75 | AU12: =VLOOKUP(AT12,[1]المرجع!$D$3:$E$12,2) -> أ | AV12: =AT12*AR12 -> 9.5 | AW12: 2 | AX12: 60 | AY12: =VLOOKUP(AX12,المرجع!$B$2:$C$11,2) -> 2 | AZ12: =VLOOKUP(AY12,[1]المرجع!$D$3:$E$12,2) -> د | BA12: =AY12*AW12 -> 4 | BB12: =BA12+AV12+AQ12+AL12+AG12+AB12+W12+R12+M12+H12 -> 95.75 | BC12: =AW12+AR12+AM12+AH12+AC12+X12+S12+N12+I12+D12 -> 22 | BD12: =BB12/BC12 -> 4.3522727 | BE12: =(BB12+'المستوى الأول '!BL13)/('المستوى الأول '!BM13+'المستوى الثاني '!BC12) -> 4.3 | BF12: =VLOOKUP(BE12,المرجع!$D$3:$F$11,3,TRUE) -> جيد جد مرتفع | BG12: =RANK(BD12,$BD$2:$BD$46) -> 11
B13: 2024155 | C13: مالا كيبا سيسي | D13: 1 | E13: 75 | F13: =VLOOKUP(E13,المرجع!$B$2:$C$11,2) -> 3.5 | G13: =VLOOKUP(F13,المرجع!$D$2:$E$11,2) -> ج+ | H13: =F13*D13 -> 3.5 | I13: 2 | J13: 79 | K13: =VLOOKUP(J13,المرجع!$B$2:$C$11,2) -> 3.5 | L13: =VLOOKUP(K13,[1]المرجع!$D$3:$E$12,2) -> ج+ | M13: =K13*I13 -> 7 | N13: 3 | O13: 81 | P13: =VLOOKUP(O13,المرجع!$B$2:$C$11,2) -> 4 | Q13: =VLOOKUP(P13,[1]المرجع!$D$3:$E$12,2) -> ب | R13: =P13*N13 -> 12 | S13: 3 | T13: 89 | U13: =VLOOKUP(T13,المرجع!$B$2:$C$11,2) -> 4.5 | V13: =VLOOKUP(U13,[1]المرجع!$D$3:$E$12,2) -> ب+ | W13: =U13*S13 -> 13.5 | X13: 3 | Y13: 95 | Z13: =VLOOKUP(Y13,المرجع!$B$2:$C$11,2) -> 5 | AA13: =VLOOKUP(Z13,[1]المرجع!$D$3:$E$12,2) -> أ+ | AB13: =Z13*X13 -> 15 | AC13: 2 | AD13: 83 | AE13: =VLOOKUP(AD13,المرجع!$B$2:$C$11,2) -> 4 | AF13: =VLOOKUP(AE13,[1]المرجع!$D$3:$E$12,2) -> ب | AG13: =AE13*AC13 -> 8 | AH13: 2 | AI13: 97 | AJ13: =VLOOKUP(AI13,المرجع!$B$2:$C$11,2) -> 5 | AK13: =VLOOKUP(AJ13,[1]المرجع!$D$3:$E$12,2) -> أ+ | AL13: =AJ13*AH13 -> 10 | AM13: 2 | AN13: 95 | AO13: =VLOOKUP(AN13,المرجع!$B$2:$C$11,2) -> 5 | AP13: =VLOOKUP(AO13,[1]المرجع!$D$3:$E$12,2) -> أ+ | AQ13: =AO13*AM13 -> 10 | AR13: 2 | AS13: 77 | AT13: =VLOOKUP(AS13,المرجع!$B$2:$C$11,2) -> 3.5 | AU13: =VLOOKUP(AT13,[1]المرجع!$D$3:$E$12,2) -> ج+ | AV13: =AT13*AR13 -> 7 | AW13: 2 | AX13: 90 | AY13: =VLOOKUP(AX13,المرجع!$B$2:$C$11,2) -> 4.75 | AZ13: =VLOOKUP(AY13,[1]المرجع!$D$3:$E$12,2) -> أ | BA13: =AY13*AW13 -> 9.5 | BB13: =BA13+AV13+AQ13+AL13+AG13+AB13+W13+R13+M13+H13 -> 95.5 | BC13: =AW13+AR13+AM13+AH13+AC13+X13+S13+N13+I13+D13 -> 22 | BD13: =BB13/BC13 -> 4.3409091 | BE13: =(BB13+'المستوى الأول '!BL14)/('المستوى الأول '!BM14+'المستوى الثاني '!BC13) -> 4.2222222 | BF13: =VLOOKUP(BE13,المرجع!$D$3:$F$11,3,TRUE) -> جيد جد مرتفع | BG13: =RANK(BD13,$BD$2:$BD$46) -> 12
... B46: 2024192 | C46: عيسى بلي تنكارا | D46: 1 | E46: 20 | F46: =VLOOKUP(E46,المرجع!$B$2:$C$11,2) -> 0 | G46: =VLOOKUP(F46,المرجع!$D$2:$E$11,2) -> ه | H46: =F46*D46 -> 0 | I46: 2 | J46: 10 | K46: =VLOOKUP(J46,المرجع!$B$2:$C$11,2) -> 0 | L46: =VLOOKUP(K46,[1]المرجع!$D$3:$E$12,2) -> ه | M46: =K46*I46 -> 0 | N46: 3 | O46: 21 | P46: =VLOOKUP(O46,المرجع!$B$2:$C$11,2) -> 0 | Q46: =VLOOKUP(P46,[1]المرجع!$D$3:$E$12,2) -> ه | R46: =P46*N46 -> 0 | S46: 3 | T46: 61 | U46: =VLOOKUP(T46,المرجع!$B$2:$C$11,2) -> 2 | V46: =VLOOKUP(U46,[1]المرجع!$D$3:$E$12,2) -> د | W46: =U46*S46 -> 6 | X46: 3 | Y46: 0 | Z46: =VLOOKUP(Y46,المرجع!$B$2:$C$11,2) -> 0 | AA46: =VLOOKUP(Z46,[1]المرجع!$D$3:$E$12,2) -> ه | AB46: =Z46*X46 -> 0 | AC46: 2 | AD46: 52 | AE46: =VLOOKUP(AD46,المرجع!$B$2:$C$11,2) -> 2 | AF46: =VLOOKUP(AE46,[1]المرجع!$D$3:$E$12,2) -> د | AG46: =AE46*AC46 -> 4 | AH46: 2 | AI46: 30 | AJ46: =VLOOKUP(AI46,المرجع!$B$2:$C$11,2) -> 0 | AK46: =VLOOKUP(AJ46,[1]المرجع!$D$3:$E$12,2) -> ه | AL46: =AJ46*AH46 -> 0 | AM46: 2 | AN46: 60 | AO46: =VLOOKUP(AN46,المرجع!$B$2:$C$11,2) -> 2 | AP46: =VLOOKUP(AO46,[1]المرجع!$D$3:$E$12,2) -> د | AQ46: =AO46*AM46 -> 4 | AR46: 2 | AS46: 55 | AT46: =VLOOKUP(AS46,المرجع!$B$2:$C$11,2) -> 2 | AU46: =VLOOKUP(AT46,[1]المرجع!$D$3:$E$12,2) -> د | AV46: =AT46*AR46 -> 4 | AW46: 2 | AX46: 0 | AY46: =VLOOKUP(AX46,المرجع!$B$2:$C$11,2) -> 0 | AZ46: =VLOOKUP(AY46,[1]المرجع!$D$3:$E$12,2) -> ه | BA46: =AY46*AW46 -> 0 | BB46: =BA46+AV46+AQ46+AL46+AG46+AB46+W46+R46+M46+H46 -> 18 | BC46: =AW46+AR46+AM46+AH46+AC46+X46+S46+N46+I46+D46 -> 22 | BD46: =BB46/BC46 -> 0.81818182 | BE46: =(BB46+'المستوى الأول '!BL47)/('المستوى الأول '!BM47+'المستوى الثاني '!BC46) -> 1.4944444 | BF46: =VLOOKUP(BE46,المرجع!$D$3:$F$11,3,TRUE) -> راسب | BG46: =RANK(BD46,$BD$2:$BD$46) -> 45

Sheet المستوى الثالث 
A1: رقم الجامعي | B1: أسماء الطلبة | C1: الساعة (م ق) | D1: القرآن الكريم | E1: الوزن (م ق) | F1: الرمز (م ق) | G1: النقاط (م ق) | H1: الساعة (م رح) | I1: رواة الحديث 2 | J1: الوزن (م رح) | K1: الرمز (م رح) | L1: النقاط (م رح) | M1: الساعة ( م ح) | N1: مصطلح الحديث 2 | O1: الوزن ( م ح) | P1: الرمز ( م ح) | Q1: النقاط ( م ح) | R1: الساعة (م ك س) | S1: كتب السنة1 (م ك س) | T1: الوزن (م ك س) | U1: الرمز (م ك س) | V1: النقاط (م ك س) | W1: الساعة (م أ ق) | X1: أصول الفقه 1 | Y1: الوزن (م أ ق) | Z1: الرمز (م أ ق) | AA1: النقاط (م أ ق) | AB1: الساعة (ح ت2) | AC1: الحديث التحليلي 2 | AD1: الوزن (ح ت2) | AE1: الرمز (ح ت2) | AF1: النقاط (ح ت2) | AG1: الساعة (م ت 2) | AH1: التوحيد 2 | AI1: الوزن (م ت 2) | AJ1: الرمز (م ت 2) | AK1: النقاط (م ت 2) | AL1: الساعة | AM1: النحو (2) | AN1: الوزن ( م ن 2) | AO1: الرمزر( م ن 2) | AP1: النقاط ( م ن 2) | AQ1: الساعة (م د غ) | AR1: دراسات غامبيا | AS1: الوزن (م د غ) | AT1: الرمز (م د غ) | AU1: النقاط (م د غ) | AV1: الساعة(ENG) | AW1: English(3) | AX1: الوزن (ENG) | AY1: الرمز (ENG) | AZ1: النقاط (ENG) | BA1: مجموع النقاط | BB1: مجموع الساعات | BC1: المعدل الفصلي | BD1: المعدل التراكمي | BE1: التقدير | BF1: الترتيب
A2: 2024174 | B2: حمزة أبوبكر كابا | C2: 1 | D2: 99 | E2: =VLOOKUP(D2,المرجع!$B$2:$C$11,2) -> 5 | F2: =VLOOKUP(E2,المرجع!$D$2:$E$11,2) -> أ+ | G2: =E2*C2 -> 5 | H2: 3 | I2: 100 | J2: =VLOOKUP(I2,المرجع!$B$2:$C$11,2) -> 5 | K2: =VLOOKUP(J2,المرجع!$D$2:$E$11,2) -> أ+ | L2: =J2*H2 -> 15 | M2: 3 | N2: 100 | O2: =VLOOKUP(N2,المرجع!$B$2:$C$11,2) -> 5 | P2: =VLOOKUP(O2,المرجع!$D$2:$E$11,2) -> أ+ | Q2: =O2*M2 -> 15 | R2: 3 | S2: 100 | T2: =VLOOKUP(S2,المرجع!$B$2:$C$11,2) -> 5 | U2: =VLOOKUP(T2,المرجع!$D$2:$E$11,2) -> أ+ | V2: =T2*R2 -> 15 | W2: 2 | X2: 100 | Y2: =VLOOKUP(X2,المرجع!$B$2:$C$11,2) -> 5 | Z2: =VLOOKUP(Y2,المرجع!$D$2:$E$11,2) -> أ+ | AA2: =Y2*W2 -> 10 | AB2: 3 | AC2: 100 | AD2: =VLOOKUP(AC2,المرجع!$B$2:$C$11,2) -> 5 | AE2: =VLOOKUP(AD2,المرجع!$D$2:$E$11,2) -> أ+ | AF2: =AD2*AB2 -> 15 | AG2: 2 | AH2: 100 | AI2: =VLOOKUP(AH2,المرجع!$B$2:$C$11,2) -> 5 | AJ2: =VLOOKUP(AI2,المرجع!$D$2:$E$11,2) -> أ+ | AK2: =AI2*AG2 -> 10 | AL2: 2 | AM2: 100 | AN2: =VLOOKUP(AM2,المرجع!$B$2:$C$11,2) -> 5 | AO2: =VLOOKUP(AN2,المرجع!$D$2:$E$11,2) -> أ+ | AP2: =AN2*AL2 -> 10 | AQ2: 2 | AR2: 100 | AS2: =VLOOKUP(AR2,المرجع!$B$2:$C$11,2) -> 5 | AT2: =VLOOKUP(AS2,المرجع!$D$2:$E$11,2) -> أ+ | AU2: =AS2*AQ2 -> 10 | AV2: 2 | AW2: 98 | AX2: =VLOOKUP(AW2,المرجع!$B$2:$C$11,2) -> 5 | AY2: =VLOOKUP(AX2,المرجع!$D$2:$E$11,2) -> أ+ | AZ2: =AX2*AV2 -> 10 | BA2: =AZ2+AU2+AP2+AK2+AF2+AA2+V2+Q2+L2+G2 -> 115 | BB2: =AV2+AQ2+AL2+AG2+AB2+W2+R2+M2+H2+C2 -> 23 | BC2: =BA2/BB2 -> 5 | BD2: =(BA2+'المستوى الثاني '!BB2+'المستوى الأول '!BL3)/('المستوى الأول '!BM3+'المستوى الثاني '!BC2+'المستوى الثالث '!BB2) -> 4.9852941 | BE2: =VLOOKUP(BD2,المرجع!$D$3:$F$11,3,TRUE) -> ممتاز مرتفع | BF2: =RANK(BD2,$BD$2:$BD$41) -> 1
A3: 2024180 | B3: حليمة مجتبى جالو | C3: 1 | D3: 82 | E3: =VLOOKUP(D3,المرجع!$B$2:$C$11,2) -> 4 | F3: =VLOOKUP(E3,المرجع!$D$2:$E$11,2) -> ب | G3: =E3*C3 -> 4 | H3: 3 | I3: 99 | J3: =VLOOKUP(I3,المرجع!$B$2:$C$11,2) -> 5 | K3: =VLOOKUP(J3,المرجع!$D$2:$E$11,2) -> أ+ | L3: =J3*H3 -> 15 | M3: 3 | N3: 100 | O3: =VLOOKUP(N3,المرجع!$B$2:$C$11,2) -> 5 | P3: =VLOOKUP(O3,المرجع!$D$2:$E$11,2) -> أ+ | Q3: =O3*M3 -> 15 | R3: 3 | S3: 96 | T3: =VLOOKUP(S3,المرجع!$B$2:$C$11,2) -> 5 | U3: =VLOOKUP(T3,المرجع!$D$2:$E$11,2) -> أ+ | V3: =T3*R3 -> 15 | W3: 2 | X3: 97 | Y3: =VLOOKUP(X3,المرجع!$B$2:$C$11,2) -> 5 | Z3: =VLOOKUP(Y3,المرجع!$D$2:$E$11,2) -> أ+ | AA3: =Y3*W3 -> 10 | AB3: 3 | AC3: 99 | AD3: =VLOOKUP(AC3,المرجع!$B$2:$C$11,2) -> 5 | AE3: =VLOOKUP(AD3,المرجع!$D$2:$E$11,2) -> أ+ | AF3: =AD3*AB3 -> 15 | AG3: 2 | AH3: 90 | AI3: =VLOOKUP(AH3,المرجع!$B$2:$C$11,2) -> 4.75 | AJ3: =VLOOKUP(AI3,المرجع!$D$2:$E$11,2) -> أ | AK3: =AI3*AG3 -> 9.5 | AL3: 2 | AM3: 94 | AN3: =VLOOKUP(AM3,المرجع!$B$2:$C$11,2) -> 4.75 | AO3: =VLOOKUP(AN3,المرجع!$D$2:$E$11,2) -> أ | AP3: =AN3*AL3 -> 9.5 | AQ3: 2 | AR3: 93 | AS3: =VLOOKUP(AR3,المرجع!$B$2:$C$11,2) -> 4.75 | AT3: =VLOOKUP(AS3,المرجع!$D$2:$E$11,2) -> أ | AU3: =AS3*AQ3 -> 9.5 | AV3: 2 | AW3: 94 | AX3: =VLOOKUP(AW3,المرجع!$B$2:$C$11,2) -> 4.75 | AY3: =VLOOKUP(AX3,المرجع!$D$2:$E$11,2) -> أ | AZ3: =AX3*AV3 -> 9.5 | BA3: =AZ3+AU3+AP3+AK3+AF3+AA3+V3+Q3+L3+G3 -> 112 | BB3: =AV3+AQ3+AL3+AG3+AB3+W3+R3+M3+H3+C3 -> 23 | BC3: =BA3/BB3 -> 4.8695652 | BD3: =(BA3+'المستوى الثاني '!BB3+'المستوى الأول '!BL4)/('المستوى الأول '!BM4+'المستوى الثاني '!BC3+'المستوى الثالث '!BB3) -> 4.8161765 | BE3: =VLOOKUP(BD3,المرجع!$D$3:$F$11,3,TRUE) -> ممتاز مرتفع | BF3: =RANK(BD3,$BD$2:$BD$41) -> 2
A4: 2024178 | B4: عائشة مبارك ديكو | C4: 1 | D4: 80 | E4: =VLOOKUP(D4,المرجع!$B$2:$C$11,2) -> 4 | F4: =VLOOKUP(E4,المرجع!$D$2:$E$11,2) -> ب | G4: =E4*C4 -> 4 | H4: 3 | I4: 97 | J4: =VLOOKUP(I4,المرجع!$B$2:$C$11,2) -> 5 | K4: =VLOOKUP(J4,المرجع!$D$2:$E$11,2) -> أ+ | L4: =J4*H4 -> 15 | M4: 3 | N4: 97 | O4: =VLOOKUP(N4,المرجع!$B$2:$C$11,2) -> 5 | P4: =VLOOKUP(O4,المرجع!$D$2:$E$11,2) -> أ+ | Q4: =O4*M4 -> 15 | R4: 3 | S4: 98 | T4: =VLOOKUP(S4,المرجع!$B$2:$C$11,2) -> 5 | U4: =VLOOKUP(T4,المرجع!$D$2:$E$11,2) -> أ+ | V4: =T4*R4 -> 15 | W4: 2 | X4: 84 | Y4: =VLOOKUP(X4,المرجع!$B$2:$C$11,2) -> 4 | Z4: =VLOOKUP(Y4,المرجع!$D$2:$E$11,2) -> ب | AA4: =Y4*W4 -> 8 | AB4: 3 | AC4: 100 | AD4: =VLOOKUP(AC4,المرجع!$B$2:$C$11,2) -> 5 | AE4: =VLOOKUP(AD4,المرجع!$D$2:$E$11,2) -> أ+ | AF4: =AD4*AB4 -> 15 | AG4: 2 | AH4: 92 | AI4: =VLOOKUP(AH4,المرجع!$B$2:$C$11,2) -> 4.75 | AJ4: =VLOOKUP(AI4,المرجع!$D$2:$E$11,2) -> أ | AK4: =AI4*AG4 -> 9.5 | AL4: 2 | AM4: 87 | AN4: =VLOOKUP(AM4,المرجع!$B$2:$C$11,2) -> 4.5 | AO4: =VLOOKUP(AN4,المرجع!$D$2:$E$11,2) -> ب+ | AP4: =AN4*AL4 -> 9 | AQ4: 2 | AR4: 100 | AS4: =VLOOKUP(AR4,المرجع!$B$2:$C$11,2) -> 5 | AT4: =VLOOKUP(AS4,المرجع!$D$2:$E$11,2) -> أ+ | AU4: =AS4*AQ4 -> 10 | AV4: 2 | AW4: 97 | AX4: =VLOOKUP(AW4,المرجع!$B$2:$C$11,2) -> 5 | AY4: =VLOOKUP(AX4,المرجع!$D$2:$E$11,2) -> أ+ | AZ4: =AX4*AV4 -> 10 | BA4: =AZ4+AU4+AP4+AK4+AF4+AA4+V4+Q4+L4+G4 -> 110.5 | BB4: =AV4+AQ4+AL4+AG4+AB4+W4+R4+M4+H4+C4 -> 23 | BC4: =BA4/BB4 -> 4.8043478 | BD4: =(BA4+'المستوى الثاني '!BB5+'المستوى الأول '!BL6)/('المستوى الأول '!BM6+'المستوى الثاني '!BC5+'المستوى الثالث '!BB5) -> 4.7830882 | BE4: =VLOOKUP(BD4,المرجع!$D$3:$F$11,3,TRUE) -> ممتاز مرتفع | BF4: =RANK(BD4,$BD$2:$BD$41) -> 3
A5: 2024154 | B5: عمر شريف ماني | C5: 1 | D5: 95 | E5: =VLOOKUP(D5,المرجع!$B$2:$C$11,2) -> 5 | F5: =VLOOKUP(E5,المرجع!$D$2:$E$11,2) -> أ+ | G5: =E5*C5 -> 5 | H5: 3 | I5: 100 | J5: =VLOOKUP(I5,المرجع!$B$2:$C$11,2) -> 5 | K5: =VLOOKUP(J5,المرجع!$D$2:$E$11,2) -> أ+ | L5: =J5*H5 -> 15 | M5: 3 | N5: 100 | O5: =VLOOKUP(N5,المرجع!$B$2:$C$11,2) -> 5 | P5: =VLOOKUP(O5,المرجع!$D$2:$E$11,2) -> أ+ | Q5: =O5*M5 -> 15 | R5: 3 | S5: 98 | T5: =VLOOKUP(S5,المرجع!$B$2:$C$11,2) -> 5 | U5: =VLOOKUP(T5,المرجع!$D$2:$E$11,2) -> أ+ | V5: =T5*R5 -> 15 | W5: 2 | X5: 92 | Y5: =VLOOKUP(X5,المرجع!$B$2:$C$11,2) -> 4.75 | Z5: =VLOOKUP(Y5,المرجع!$D$2:$E$11,2) -> أ | AA5: =Y5*W5 -> 9.5 | AB5: 3 | AC5: 97 | AD5: =VLOOKUP(AC5,المرجع!$B$2:$C$11,2) -> 5 | AE5: =VLOOKUP(AD5,المرجع!$D$2:$E$11,2) -> أ+ | AF5: =AD5*AB5 -> 15 | AG5: 2 | AH5: 99 | AI5: =VLOOKUP(AH5,المرجع!$B$2:$C$11,2) -> 5 | AJ5: =VLOOKUP(AI5,المرجع!$D$2:$E$11,2) -> أ+ | AK5: =AI5*AG5 -> 10 | AL5: 2 | AM5: 89 | AN5: =VLOOKUP(AM5,المرجع!$B$2:$C$11,2) -> 4.5 | AO5: =VLOOKUP(AN5,المرجع!$D$2:$E$11,2) -> ب+ | AP5: =AN5*AL5 -> 9 | AQ5: 2 | AR5: 89 | AS5: =VLOOKUP(AR5,المرجع!$B$2:$C$11,2) -> 4.5 | AT5: =VLOOKUP(AS5,المرجع!$D$2:$E$11,2) -> ب+ | AU5: =AS5*AQ5 -> 9 | AV5: 2 | AW5: 82 | AX5: =VLOOKUP(AW5,المرجع!$B$2:$C$11,2) -> 4 | AY5: =VLOOKUP(AX5,المرجع!$D$2:$E$11,2) -> ب | AZ5: =AX5*AV5 -> 8 | BA5: =AZ5+AU5+AP5+AK5+AF5+AA5+V5+Q5+L5+G5 -> 110.5 | BB5: =AV5+AQ5+AL5+AG5+AB5+W5+R5+M5+H5+C5 -> 23 | BC5: =BA5/BB5 -> 4.8043478 | BD5: =(BA5+'المستوى الثاني '!BB4+'المستوى الأول '!BL5)/('المستوى الأول '!BM5+'المستوى الثاني '!BC4+'المستوى الثالث '!BB4) -> 4.7757353 | BE5: =VLOOKUP(BD5,المرجع!$D$3:$F$11,3,TRUE) -> ممتاز مرتفع | BF5: =RANK(BD5,$BD$2:$BD$41) -> 4
A6: 2024209 | B6: آدم مبارك ديكو | C6: 1 | D6: 99 | E6: =VLOOKUP(D6,المرجع!$B$2:$C$11,2) -> 5 | F6: =VLOOKUP(E6,المرجع!$D$2:$E$11,2) -> أ+ | G6: =E6*C6 -> 5 | H6: 3 | I6: 98 | J6: =VLOOKUP(I6,المرجع!$B$2:$C$11,2) -> 5 | K6: =VLOOKUP(J6,المرجع!$D$2:$E$11,2) -> أ+ | L6: =J6*H6 -> 15 | M6: 3 | N6: 99 | O6: =VLOOKUP(N6,المرجع!$B$2:$C$11,2) -> 5 | P6: =VLOOKUP(O6,المرجع!$D$2:$E$11,2) -> أ+ | Q6: =O6*M6 -> 15 | R6: 3 | S6: 100 | T6: =VLOOKUP(S6,المرجع!$B$2:$C$11,2) -> 5 | U6: =VLOOKUP(T6,المرجع!$D$2:$E$11,2) -> أ+ | V6: =T6*R6 -> 15 | W6: 2 | X6: 97 | Y6: =VLOOKUP(X6,المرجع!$B$2:$C$11,2) -> 5 | Z6: =VLOOKUP(Y6,المرجع!$D$2:$E$11,2) -> أ+ | AA6: =Y6*W6 -> 10 | AB6: 3 | AC6: 100 | AD6: =VLOOKUP(AC6,المرجع!$B$2:$C$11,2) -> 5 | AE6: =VLOOKUP(AD6,المرجع!$D$2:$E$11,2) -> أ+ | AF6: =AD6*AB6 -> 15 | AG6: 2 | AH6: 100 | AI6: =VLOOKUP(AH6,المرجع!$B$2:$C$11,2) -> 5 | AJ6: =VLOOKUP(AI6,المرجع!$D$2:$E$11,2) -> أ+ | AK6: =AI6*AG6 -> 10 | AL6: 2 | AM6: 99 | AN6: =VLOOKUP(AM6,المرجع!$B$2:$C$11,2) -> 5 | AO6: =VLOOKUP(AN6,المرجع!$D$2:$E$11,2) -> أ+ | AP6: =AN6*AL6 -> 10 | AQ6: 2 | AR6: 86 | AS6: =VLOOKUP(AR6,المرجع!$B$2:$C$11,2) -> 4.5 | AT6: =VLOOKUP(AS6,المرجع!$D$2:$E$11,2) -> ب+ | AU6: =AS6*AQ6 -> 9 | AV6: 2 | AW6: 74 | AX6: =VLOOKUP(AW6,المرجع!$B$2:$C$11,2) -> 3 | AY6: =VLOOKUP(AX6,المرجع!$D$2:$E$11,2) -> ج | AZ6: =AX6*AV6 -> 6 | BA6: =AZ6+AU6+AP6+AK6+AF6+AA6+V6+Q6+L6+G6 -> 110 | BB6: =AV6+AQ6+AL6+AG6+AB6+W6+R6+M6+H6+C6 -> 23 | BC6: =BA6/BB6 -> 4.7826087 | BD6: =(BA6+'المستوى الثاني '!BB6+'المستوى الأول '!BL7)/('المستوى الأول '!BM7+'المستوى الثاني '!BC6+'المستوى الثالث '!BB6) -> 4.7169118 | BE6: =VLOOKUP(BD6,المرجع!$D$3:$F$11,3,TRUE) -> ممتاز | BF6: =RANK(BD6,$BD$2:$BD$41) -> 5
