Workbook

Sheet المستوى الأول 2022
B2: رقم التسلسل | C2: الإسم | D2: الساعات | E2: القرأن الكريم (1) | F2: الوزن | G2: الرمز | H2: النقاط | I2: الساعات | J2: المدخل إلى علوم القرآن | K2: الوزن | L2: الرمز | M2: النقاط | N2: الساعات | O2: الفقه (1) | P2: الوزن | Q2: الرمز | R2: النقاط | S2: الساعات | T2: المدخل إلى الحديث التحليلي | U2: الوزن | V2: الرمز | W2: النقاط | X2: الساعات | Y2: تاريخ السنة | Z2: الوزن | AA2: الرمز | AB2: النقاط | AC2: الساعات | AD2: المدخل إلى علوم الحديث | AE2: الوزن | AF2: الرمز | AG2: النقاط | AH2: الساعات | AI2: النحو (1) | AJ2: الوزن | AK2: الرمز | AL2: النقاط | AM2: الساعات | AN2: مناهج البحث | AO2: الوزن | AP2: الرمز | AQ2: النقاط | AR2: الساعات | AS2: التوحيد | AT2: الوزن | AU2: الرمز | AV2: النقاط | AW2: الساعات | AX2: التحرير العربي | AY2: الوزن | AZ2: الرمز | BA2: النقاط | BB2: الساعات | BC2: التجويد | BD2: الوزن | BE2: الرمز | BF2: النقاط | BG2: الساعات | BH2: English | BI2: الوزن | BJ2: الرمز | BK2: النقاط | BL2: مجموع النقاط | BM2: مجموع الساعات | BN2: المعدل الفصلي | BO2: المعدل التراكمي | BP2: التقدير | BQ2: الترتيب
B3: 2023002 | C3: ديالو إبراهيم | D3: 1 | E3: 98 | F3: =VLOOKUP(E3,المرجع!$B$3:$C$12,2) -> 5 | G3: =VLOOKUP(F3,المرجع!$D$3:$E$12,2) -> أ+ | H3: =F3*D3 -> 5 | I3: 2 | J3: 98 | K3: =VLOOKUP(J3,المرجع!$B$3:$C$12,2) -> 5 | L3: =VLOOKUP(K3,المرجع!$D$3:$E$12,2) -> أ+ | M3: =K3*I3 -> 10 | N3: 2 | O3: 90 | P3: =VLOOKUP(O3,المرجع!$B$3:$C$12,2) -> 4.75 | Q3: =VLOOKUP(P3,المرجع!$D$3:$E$12,2) -> أ | R3: =P3*N3 -> 9.5 | S3: 2 | T3: 99 | U3: =VLOOKUP(T3,المرجع!$B$3:$C$12,2) -> 5 | V3: =VLOOKUP(U3,المرجع!$D$3:$E$12,2) -> أ+ | W3: =U3*S3 -> 10 | X3: 2 | Y3: 100 | Z3: =VLOOKUP(Y3,المرجع!$B$3:$C$12,2) -> 5 | AA3: =VLOOKUP(Z3,المرجع!$D$3:$E$12,2) -> أ+ | AB3: =Z3*X3 -> 10 | AC3: 2 | AD3: 84 | AE3: =VLOOKUP(AD3,المرجع!$B$3:$C$12,2) -> 4 | AF3: =VLOOKUP(AE3,المرجع!$D$3:$E$12,2) -> ب | AG3: =AE3*AC3 -> 8 | AH3: 2 | AI3: 89 | AJ3: =VLOOKUP(AI3,المرجع!$B$3:$C$12,2) -> 4.5 | AK3: =VLOOKUP(AJ3,المرجع!$D$3:$E$12,2) -> ب+ | AL3: =AJ3*AH3 -> 9 | AM3: 2 | AN3: 95 | AO3: =VLOOKUP(AN3,المرجع!$B$3:$C$12,2) -> 5 | AP3: =VLOOKUP(AO3,المرجع!$D$3:$E$12,2) -> أ+ | AQ3: =AO3*AM3 -> 10 | AR3: 2 | AS3: 84 | AT3: =VLOOKUP(AS3,المرجع!$B$3:$C$12,2) -> 4 | AU3: =VLOOKUP(AT3,المرجع!$D$3:$E$12,2) -> ب | AV3: =AT3*AR3 -> 8 | AW3: 2 | AX3: 90 | AY3: =VLOOKUP(AX3,المرجع!$B$3:$C$12,2) -> 4.75 | AZ3: =VLOOKUP(AY3,المرجع!$D$3:$E$12,2) -> أ | BA3: =AY3*AW3 -> 9.5 | BB3: 2 | BC3: 95 | BD3: =VLOOKUP(BC3,المرجع!$B$3:$C$12,2) -> 5 | BE3: =VLOOKUP(BD3,المرجع!$D$3:$E$12,2) -> أ+ | BF3: =BD3*BB3 -> 10 | BG3: 2 | BH3: 96 | BI3: =VLOOKUP(BH3,المرجع!$B$3:$C$12,2) -> 5 | BJ3: =VLOOKUP(BI3,المرجع!$D$3:$E$12,2) -> أ+ | BK3: =BI3*BG3 -> 10 | BL3: =-BK3+BF3+BA3+AV3+AQ3+AL3+AG3+AB3+W3+R3+M3+H3 -> 89 | BM3: =SUM(BG3+BB3+AW3+AR3+AM3+AH3+AC3+X3+S3+N3+I3+D3) -> 23 | BN3: =BL3/BM3 -> 3.8695652 | BP3: =VLOOKUP(BN3,المرجع!$D$3:$F$12,3) -> جيد جدا | BQ3: =RANK(BN3,$BN$3:$BN$98) -> 2
B4: 2023035 | C4: بنت موسى | D4: 1 | E4: 95 | F4: =VLOOKUP(E4,المرجع!$B$3:$C$12,2) -> 5 | G4: =VLOOKUP(F4,المرجع!$D$3:$E$12,2) -> أ+ | H4: =F4*D4 -> 5 | I4: 2 | J4: 100 | K4: =VLOOKUP(J4,المرجع!$B$3:$C$12,2) -> 5 | L4: =VLOOKUP(K4,المرجع!$D$3:$E$12,2) -> أ+ | M4: =K4*I4 -> 10 | N4: 2 | O4: 95 | P4: =VLOOKUP(O4,المرجع!$B$3:$C$12,2) -> 5 | Q4: =VLOOKUP(P4,المرجع!$D$3:$E$12,2) -> أ+ | R4: =P4*N4 -> 10 | S4: 2 | T4: 97 | U4: =VLOOKUP(T4,المرجع!$B$3:$C$12,2) -> 5 | V4: =VLOOKUP(U4,المرجع!$D$3:$E$12,2) -> أ+ | W4: =U4*S4 -> 10 | X4: 2 | Y4: 100 | Z4: =VLOOKUP(Y4,المرجع!$B$3:$C$12,2) -> 5 | AA4: =VLOOKUP(Z4,المرجع!$D$3:$E$12,2) -> أ+ | AB4: =Z4*X4 -> 10 | AC4: 2 | AD4: 96 | AE4: =VLOOKUP(AD4,المرجع!$B$3:$C$12,2) -> 5 | AF4: =VLOOKUP(AE4,المرجع!$D$3:$E$12,2) -> أ+ | AG4: =AE4*AC4 -> 10 | AH4: 2 | AI4: 98 | AJ4: =VLOOKUP(AI4,المرجع!$B$3:$C$12,2) -> 5 | AK4: =VLOOKUP(AJ4,المرجع!$D$3:$E$12,2) -> أ+ | AL4: =AJ4*AH4 -> 10 | AM4: 2 | AN4: 93 | AO4: =VLOOKUP(AN4,المرجع!$B$3:$C$12,2) -> 4.75 | AP4: =VLOOKUP(AO4,المرجع!$D$3:$E$12,2) -> أ | AQ4: =AO4*AM4 -> 9.5 | AR4: 2 | AS4: 93 | AT4: =VLOOKUP(AS4,المرجع!$B$3:$C$12,2) -> 4.75 | AU4: =VLOOKUP(AT4,المرجع!$D$3:$E$12,2) -> أ | AV4: =AT4*AR4 -> 9.5 | AW4: 2 | AX4: 65 | AY4: =VLOOKUP(AX4,المرجع!$B$3:$C$12,2) -> 2.5 | AZ4: =VLOOKUP(AY4,المرجع!$D$3:$E$12,2) -> د+ | BA4: =AY4*AW4 -> 5 | BB4: 2 | BC4: 100 | BD4: =VLOOKUP(BC4,المرجع!$B$3:$C$12,2) -> 5 | BE4: =VLOOKUP(BD4,المرجع!$D$3:$E$12,2) -> أ+ | BF4: =BD4*BB4 -> 10 | BG4: 2 | BH4: 100 | BI4: =VLOOKUP(BH4,المرجع!$B$3:$C$12,2) -> 5 | BJ4: =VLOOKUP(BI4,المرجع!$D$3:$E$12,2) -> أ+ | BK4: =BI4*BG4 -> 10 | BL4: =-BK4+BF4+BA4+AV4+AQ4+AL4+AG4+AB4+W4+R4+M4+H4 -> 89 | BM4: =SUM(BG4+BB4+AW4+AR4+AM4+AH4+AC4+X4+S4+N4+I4+D4) -> 23 | BN4: =BL4/BM4 -> 3.8695652 | BP4: =VLOOKUP(BN4,المرجع!$D$3:$F$12,3) -> جيد جدا | BQ4: =RANK(BN4,$BN$3:$BN$98) -> 2
B5: 2023085 | C5: فاطمة صغرى محمد جابي | D5: 1 | E5: 95 | F5: =VLOOKUP(E5,المرجع!$B$3:$C$12,2) -> 5 | G5: =VLOOKUP(F5,المرجع!$D$3:$E$12,2) -> أ+ | H5: =F5*D5 -> 5 | I5: 2 | J5: 100 | K5: =VLOOKUP(J5,المرجع!$B$3:$C$12,2) -> 5 | L5: =VLOOKUP(K5,المرجع!$D$3:$E$12,2) -> أ+ | M5: =K5*I5 -> 10 | N5: 2 | O5: 94 | P5: =VLOOKUP(O5,المرجع!$B$3:$C$12,2) -> 4.75 | Q5: =VLOOKUP(P5,المرجع!$D$3:$E$12,2) -> أ | R5: =P5*N5 -> 9.5 | S5: 2 | T5: 99 | U5: =VLOOKUP(T5,المرجع!$B$3:$C$12,2) -> 5 | V5: =VLOOKUP(U5,المرجع!$D$3:$E$12,2) -> أ+ | W5: =U5*S5 -> 10 | X5: 2 | Y5: 99 | Z5: =VLOOKUP(Y5,المرجع!$B$3:$C$12,2) -> 5 | AA5: =VLOOKUP(Z5,المرجع!$D$3:$E$12,2) -> أ+ | AB5: =Z5*X5 -> 10 | AC5: 2 | AD5: 95 | AE5: =VLOOKUP(AD5,المرجع!$B$3:$C$12,2) -> 5 | AF5: =VLOOKUP(AE5,المرجع!$D$3:$E$12,2) -> أ+ | AG5: =AE5*AC5 -> 10 | AH5: 2 | AI5: 99 | AJ5: =VLOOKUP(AI5,المرجع!$B$3:$C$12,2) -> 5 | AK5: =VLOOKUP(AJ5,المرجع!$D$3:$E$12,2) -> أ+ | AL5: =AJ5*AH5 -> 10 | AM5: 2 | AN5: 96 | AO5: =VLOOKUP(AN5,المرجع!$B$3:$C$12,2) -> 5 | AP5: =VLOOKUP(AO5,المرجع!$D$3:$E$12,2) -> أ+ | AQ5: =AO5*AM5 -> 10 | AR5: 2 | AS5: 100 | AT5: =VLOOKUP(AS5,المرجع!$B$3:$C$12,2) -> 5 | AU5: =VLOOKUP(AT5,المرجع!$D$3:$E$12,2) -> أ+ | AV5: =AT5*AR5 -> 10 | AW5: 2 | AX5: 55 | AY5: =VLOOKUP(AX5,المرجع!$B$3:$C$12,2) -> 2 | AZ5: =VLOOKUP(AY5,المرجع!$D$3:$E$12,2) -> د | BA5: =AY5*AW5 -> 4 | BB5: 2 | BC5: 100 | BD5: =VLOOKUP(BC5,المرجع!$B$3:$C$12,2) -> 5 | BE5: =VLOOKUP(BD5,المرجع!$D$3:$E$12,2) -> أ+ | BF5: =BD5*BB5 -> 10 | BG5: 2 | BH5: 100 | BI5: =VLOOKUP(BH5,المرجع!$B$3:$C$12,2) -> 5 | BJ5: =VLOOKUP(BI5,المرجع!$D$3:$E$12,2) -> أ+ | BK5: =BI5*BG5 -> 10 | BL5: =-BK5+BF5+BA5+AV5+AQ5+AL5+AG5+AB5+W5+R5+M5+H5 -> 88.5 | BM5: =SUM(BG5+BB5+AW5+AR5+AM5+AH5+AC5+X5+S5+N5+I5+D5) -> 23 | BN5: =BL5/BM5 -> 3.8478261 | BP5: =VLOOKUP(BN5,المرجع!$D$3:$F$12,3) -> جيد جدا | BQ5: =RANK(BN5,$BN$3:$BN$98) -> 5
B6: 2023097 | C6: محمد بن سمبر دكوري | D6: 1 | E6: 96 | F6: =VLOOKUP(E6,المرجع!$B$3:$C$12,2) -> 5 | G6: =VLOOKUP(F6,المرجع!$D$3:$E$12,2) -> أ+ | H6: =F6*D6 -> 5 | I6: 2 | J6: 100 | K6: =VLOOKUP(J6,المرجع!$B$3:$C$12,2) -> 5 | L6: =VLOOKUP(K6,المرجع!$D$3:$E$12,2) -> أ+ | M6: =K6*I6 -> 10 | N6: 2 | O6: 90 | P6: =VLOOKUP(O6,المرجع!$B$3:$C$12,2) -> 4.75 | Q6: =VLOOKUP(P6,المرجع!$D$3:$E$12,2) -> أ | R6: =P6*N6 -> 9.5 | S6: 2 | T6: 98 | U6: =VLOOKUP(T6,المرجع!$B$3:$C$12,2) -> 5 | V6: =VLOOKUP(U6,المرجع!$D$3:$E$12,2) -> أ+ | W6: =U6*S6 -> 10 | X6: 2 | Y6: 100 | Z6: =VLOOKUP(Y6,المرجع!$B$3:$C$12,2) -> 5 | AA6: =VLOOKUP(Z6,المرجع!$D$3:$E$12,2) -> أ+ | AB6: =Z6*X6 -> 10 | AC6: 2 | AD6: 93 | AE6: =VLOOKUP(AD6,المرجع!$B$3:$C$12,2) -> 4.75 | AF6: =VLOOKUP(AE6,المرجع!$D$3:$E$12,2) -> أ | AG6: =AE6*AC6 -> 9.5 | AH6: 2 | AI6: 100 | AJ6: =VLOOKUP(AI6,المرجع!$B$3:$C$12,2) -> 5 | AK6: =VLOOKUP(AJ6,المرجع!$D$3:$E$12,2) -> أ+ | AL6: =AJ6*AH6 -> 10 | AM6: 2 | AN6: 94 | AO6: =VLOOKUP(AN6,المرجع!$B$3:$C$12,2) -> 4.75 | AP6: =VLOOKUP(AO6,المرجع!$D$3:$E$12,2) -> أ | AQ6: =AO6*AM6 -> 9.5 | AR6: 2 | AS6: 86 | AT6: =VLOOKUP(AS6,المرجع!$B$3:$C$12,2) -> 4.5 | AU6: =VLOOKUP(AT6,المرجع!$D$3:$E$12,2) -> ب+ | AV6: =AT6*AR6 -> 9 | AW6: 2 | AX6: 80 | AY6: =VLOOKUP(AX6,المرجع!$B$3:$C$12,2) -> 4 | AZ6: =VLOOKUP(AY6,المرجع!$D$3:$E$12,2) -> ب | BA6: =AY6*AW6 -> 8 | BB6: 2 | BC6: 98 | BD6: =VLOOKUP(BC6,المرجع!$B$3:$C$12,2) -> 5 | BE6: =VLOOKUP(BD6,المرجع!$D$3:$E$12,2) -> أ+ | BF6: =BD6*BB6 -> 10 | BG6: 2 | BH6: 66 | BI6: =VLOOKUP(BH6,المرجع!$B$3:$C$12,2) -> 2.5 | BJ6: =VLOOKUP(BI6,المرجع!$D$3:$E$12,2) -> د+ | BK6: =BI6*BG6 -> 5 | BL6: =-BK6+BF6+BA6+AV6+AQ6+AL6+AG6+AB6+W6+R6+M6+H6 -> 95.5 | BM6: =SUM(BG6+BB6+AW6+AR6+AM6+AH6+AC6+X6+S6+N6+I6+D6) -> 23 | BN6: =BL6/BM6 -> 4.1521739 | BP6: =VLOOKUP(BN6,المرجع!$D$3:$F$12,3) -> جيد جد مرتفع | BQ6: =RANK(BN6,$BN$3:$BN$98) -> 1
B7: 2023027 | C7: آدم عبد الحميد سنكارا | D7: 1 | E7: 100 | F7: =VLOOKUP(E7,المرجع!$B$3:$C$12,2) -> 5 | G7: =VLOOKUP(F7,المرجع!$D$3:$E$12,2) -> أ+ | H7: =F7*D7 -> 5 | I7: 2 | J7: 100 | K7: =VLOOKUP(J7,المرجع!$B$3:$C$12,2) -> 5 | L7: =VLOOKUP(K7,المرجع!$D$3:$E$12,2) -> أ+ | M7: =K7*I7 -> 10 | N7: 2 | O7: 67 | P7: =VLOOKUP(O7,المرجع!$B$3:$C$12,2) -> 2.5 | Q7: =VLOOKUP(P7,المرجع!$D$3:$E$12,2) -> د+ | R7: =P7*N7 -> 5 | S7: 2 | T7: 100 | U7: =VLOOKUP(T7,المرجع!$B$3:$C$12,2) -> 5 | V7: =VLOOKUP(U7,المرجع!$D$3:$E$12,2) -> أ+ | W7: =U7*S7 -> 10 | X7: 2 | Y7: 100 | Z7: =VLOOKUP(Y7,المرجع!$B$3:$C$12,2) -> 5 | AA7: =VLOOKUP(Z7,المرجع!$D$3:$E$12,2) -> أ+ | AB7: =Z7*X7 -> 10 | AC7: 2 | AD7: 93 | AE7: =VLOOKUP(AD7,المرجع!$B$3:$C$12,2) -> 4.75 | AF7: =VLOOKUP(AE7,المرجع!$D$3:$E$12,2) -> أ | AG7: =AE7*AC7 -> 9.5 | AH7: 2 | AI7: 98 | AJ7: =VLOOKUP(AI7,المرجع!$B$3:$C$12,2) -> 5 | AK7: =VLOOKUP(AJ7,المرجع!$D$3:$E$12,2) -> أ+ | AL7: =AJ7*AH7 -> 10 | AM7: 2 | AN7: 94 | AO7: =VLOOKUP(AN7,المرجع!$B$3:$C$12,2) -> 4.75 | AP7: =VLOOKUP(AO7,المرجع!$D$3:$E$12,2) -> أ | AQ7: =AO7*AM7 -> 9.5 | AR7: 2 | AS7: 89 | AT7: =VLOOKUP(AS7,المرجع!$B$3:$C$12,2) -> 4.5 | AU7: =VLOOKUP(AT7,المرجع!$D$3:$E$12,2) -> ب+ | AV7: =AT7*AR7 -> 9 | AW7: 2 | AX7: 85 | AY7: =VLOOKUP(AX7,المرجع!$B$3:$C$12,2) -> 4.5 | AZ7: =VLOOKUP(AY7,المرجع!$D$3:$E$12,2) -> ب+ | BA7: =AY7*AW7 -> 9 | BB7: 2 | BC7: 96 | BD7: =VLOOKUP(BC7,المرجع!$B$3:$C$12,2) -> 5 | BE7: =VLOOKUP(BD7,المرجع!$D$3:$E$12,2) -> أ+ | BF7: =BD7*BB7 -> 10 | BG7: 2 | BH7: 83 | BI7: =VLOOKUP(BH7,المرجع!$B$3:$C$12,2) -> 4 | BJ7: =VLOOKUP(BI7,المرجع!$D$3:$E$12,2) -> ب | BK7: =BI7*BG7 -> 8 | BL7: =-BK7+BF7+BA7+AV7+AQ7+AL7+AG7+AB7+W7+R7+M7+H7 -> 89 | BM7: =SUM(BG7+BB7+AW7+AR7+AM7+AH7+AC7+X7+S7+N7+I7+D7) -> 23 | BN7: =BL7/BM7 -> 3.8695652 | BP7: =VLOOKUP(BN7,المرجع!$D$3:$F$12,3) -> جيد جدا | BQ7: =RANK(BN7,$BN$3:$BN$98) -> 2
B8: 2023023 | C8: أمي بابا جاورا | D8: 1 | E8: 95 | F8: =VLOOKUP(E8,المرجع!$B$3:$C$12,2) -> 5 | G8: =VLOOKUP(F8,المرجع!$D$3:$E$12,2) -> أ+ | H8: =F8*D8 -> 5 | I8: 2 | J8: 100 | K8: =VLOOKUP(J8,المرجع!$B$3:$C$12,2) -> 5 | L8: =VLOOKUP(K8,المرجع!$D$3:$E$12,2) -> أ+ | M8: =K8*I8 -> 10 | N8: 2 | O8: 60 | P8: =VLOOKUP(O8,المرجع!$B$3:$C$12,2) -> 2 | Q8: =VLOOKUP(P8,المرجع!$D$3:$E$12,2) -> د | R8: =P8*N8 -> 4 | S8: 2 | T8: 96 | U8: =VLOOKUP(T8,المرجع!$B$3:$C$12,2) -> 5 | V8: =VLOOKUP(U8,المرجع!$D$3:$E$12,2) -> أ+ | W8: =U8*S8 -> 10 | X8: 2 | Y8: 99 | Z8: =VLOOKUP(Y8,المرجع!$B$3:$C$12,2) -> 5 | AA8: =VLOOKUP(Z8,المرجع!$D$3:$E$12,2) -> أ+ | AB8: =Z8*X8 -> 10 | AC8: 2 | AD8: 80 | AE8: =VLOOKUP(AD8,المرجع!$B$3:$C$12,2) -> 4 | AF8: =VLOOKUP(AE8,المرجع!$D$3:$E$12,2) -> ب | AG8: =AE8*AC8 -> 8 | AH8: 2 | AI8: 89 | AJ8: =VLOOKUP(AI8,المرجع!$B$3:$C$12,2) -> 4.5 | AK8: =VLOOKUP(AJ8,المرجع!$D$3:$E$12,2) -> ب+ | AL8: =AJ8*AH8 -> 9 | AM8: 2 | AN8: 88 | AO8: =VLOOKUP(AN8,المرجع!$B$3:$C$12,2) -> 4.5 | AP8: =VLOOKUP(AO8,المرجع!$D$3:$E$12,2) -> ب+ | AQ8: =AO8*AM8 -> 9 | AR8: 2 | AS8: 86 | AT8: =VLOOKUP(AS8,المرجع!$B$3:$C$12,2) -> 4.5 | AU8: =VLOOKUP(AT8,المرجع!$D$3:$E$12,2) -> ب+ | AV8: =AT8*AR8 -> 9 | AW8: 2 | AX8: 80 | AY8: =VLOOKUP(AX8,المرجع!$B$3:$C$12,2) -> 4 | AZ8: =VLOOKUP(AY8,المرجع!$D$3:$E$12,2) -> ب | BA8: =AY8*AW8 -> 8 | BB8: 2 | BC8: 95 | BD8: =VLOOKUP(BC8,المرجع!$B$3:$C$12,2) -> 5 | BE8: =VLOOKUP(BD8,المرجع!$D$3:$E$12,2) -> أ+ | BF8: =BD8*BB8 -> 10 | BG8: 2 | BH8: 100 | BI8: =VLOOKUP(BH8,المرجع!$B$3:$C$12,2) -> 5 | BJ8: =VLOOKUP(BI8,المرجع!$D$3:$E$12,2) -> أ+ | BK8: =BI8*BG8 -> 10 | BL8: =-BK8+BF8+BA8+AV8+AQ8+AL8+AG8+AB8+W8+R8+M8+H8 -> 82 | BM8: =SUM(BG8+BB8+AW8+AR8+AM8+AH8+AC8+X8+S8+N8+I8+D8) -> 23 | BN8: =BL8/BM8 -> 3.5652174 | BP8: =VLOOKUP(BN8,المرجع!$D$3:$F$12,3) -> جيد مرتفع | BQ8: =RANK(BN8,$BN$3:$BN$98) -> 9
B9: 2023050 | C9: شيخ كسما تنكارا | D9: 1 | E9: 98 | F9: =VLOOKUP(E9,المرجع!$B$3:$C$12,2) -> 5 | G9: =VLOOKUP(F9,المرجع!$D$3:$E$12,2) -> أ+ | H9: =F9*D9 -> 5 | I9: 2 | J9: 100 | K9: =VLOOKUP(J9,المرجع!$B$3:$C$12,2) -> 5 | L9: =VLOOKUP(K9,المرجع!$D$3:$E$12,2) -> أ+ | M9: =K9*I9 -> 10 | N9: 2 | O9: 65 | P9: =VLOOKUP(O9,المرجع!$B$3:$C$12,2) -> 2.5 | Q9: =VLOOKUP(P9,المرجع!$D$3:$E$12,2) -> د+ | R9: =P9*N9 -> 5 | S9: 2 | T9: 100 | U9: =VLOOKUP(T9,المرجع!$B$3:$C$12,2) -> 5 | V9: =VLOOKUP(U9,المرجع!$D$3:$E$12,2) -> أ+ | W9: =U9*S9 -> 10 | X9: 2 | Y9: 100 | Z9: =VLOOKUP(Y9,المرجع!$B$3:$C$12,2) -> 5 | AA9: =VLOOKUP(Z9,المرجع!$D$3:$E$12,2) -> أ+ | AB9: =Z9*X9 -> 10 | AC9: 2 | AD9: 97 | AE9: =VLOOKUP(AD9,المرجع!$B$3:$C$12,2) -> 5 | AF9: =VLOOKUP(AE9,المرجع!$D$3:$E$12,2) -> أ+ | AG9: =AE9*AC9 -> 10 | AH9: 2 | AI9: 88 | AJ9: =VLOOKUP(AI9,المرجع!$B$3:$C$12,2) -> 4.5 | AK9: =VLOOKUP(AJ9,المرجع!$D$3:$E$12,2) -> ب+ | AL9: =AJ9*AH9 -> 9 | AM9: 2 | AN9: 90 | AO9: =VLOOKUP(AN9,المرجع!$B$3:$C$12,2) -> 4.75 | AP9: =VLOOKUP(AO9,المرجع!$D$3:$E$12,2) -> أ | AQ9: =AO9*AM9 -> 9.5 | AR9: 2 | AS9: 86 | AT9: =VLOOKUP(AS9,المرجع!$B$3:$C$12,2) -> 4.5 | AU9: =VLOOKUP(AT9,المرجع!$D$3:$E$12,2) -> ب+ | AV9: =AT9*AR9 -> 9 | AW9: 2 | AX9: 60 | AY9: =VLOOKUP(AX9,المرجع!$B$3:$C$12,2) -> 2 | AZ9: =VLOOKUP(AY9,المرجع!$D$3:$E$12,2) -> د | BA9: =AY9*AW9 -> 4 | BB9: 2 | BC9: 86 | BD9: =VLOOKUP(BC9,المرجع!$B$3:$C$12,2) -> 4.5 | BE9: =VLOOKUP(BD9,المرجع!$D$3:$E$12,2) -> ب+ | BF9: =BD9*BB9 -> 9 | BG9: 2 | BH9: 98 | BI9: =VLOOKUP(BH9,المرجع!$B$3:$C$12,2) -> 5 | BJ9: =VLOOKUP(BI9,المرجع!$D$3:$E$12,2) -> أ+ | BK9: =BI9*BG9 -> 10 | BL9: =-BK9+BF9+BA9+AV9+AQ9+AL9+AG9+AB9+W9+R9+M9+H9 -> 80.5 | BM9: =SUM(BG9+BB9+AW9+AR9+AM9+AH9+AC9+X9+S9+N9+I9+D9) -> 23 | BN9: =BL9/BM9 -> 3.5 | BP9: =VLOOKUP(BN9,المرجع!$D$3:$F$12,3) -> جيد مرتفع | BQ9: =RANK(BN9,$BN$3:$BN$98) -> 12
B10: 2023041 | C10: زينب شيخ أحمد تيجان بلدي | D10: 1 | E10: 95 | F10: =VLOOKUP(E10,المرجع!$B$3:$C$12,2) -> 5 | G10: =VLOOKUP(F10,المرجع!$D$3:$E$12,2) -> أ+ | H10: =F10*D10 -> 5 | I10: 2 | J10: 100 | K10: =VLOOKUP(J10,المرجع!$B$3:$C$12,2) -> 5 | L10: =VLOOKUP(K10,المرجع!$D$3:$E$12,2) -> أ+ | M10: =K10*I10 -> 10 | N10: 2 | O10: 89 | P10: =VLOOKUP(O10,المرجع!$B$3:$C$12,2) -> 4.5 | Q10: =VLOOKUP(P10,المرجع!$D$3:$E$12,2) -> ب+ | R10: =P10*N10 -> 9 | S10: 2 | T10: 98 | U10: =VLOOKUP(T10,المرجع!$B$3:$C$12,2) -> 5 | V10: =VLOOKUP(U10,المرجع!$D$3:$E$12,2) -> أ+ | W10: =U10*S10 -> 10 | X10: 2 | Y10: 98 | Z10: =VLOOKUP(Y10,المرجع!$B$3:$C$12,2) -> 5 | AA10: =VLOOKUP(Z10,المرجع!$D$3:$E$12,2) -> أ+ | AB10: =Z10*X10 -> 10 | AC10: 2 | AD10: 87 | AE10: =VLOOKUP(AD10,المرجع!$B$3:$C$12,2) -> 4.5 | AF10: =VLOOKUP(AE10,المرجع!$D$3:$E$12,2) -> ب+ | AG10: =AE10*AC10 -> 9 | AH10: 2 | AI10: 76 | AJ10: =VLOOKUP(AI10,المرجع!$B$3:$C$12,2) -> 3.5 | AK10: =VLOOKUP(AJ10,المرجع!$D$3:$E$12,2) -> ج+ | AL10: =AJ10*AH10 -> 7 | AM10: 2 | AN10: 79 | AO10: =VLOOKUP(AN10,المرجع!$B$3:$C$12,2) -> 3.5 | AP10: =VLOOKUP(AO10,المرجع!$D$3:$E$12,2) -> ج+ | AQ10: =AO10*AM10 -> 7 | AR10: 2 | AS10: 78 | AT10: =VLOOKUP(AS10,المرجع!$B$3:$C$12,2) -> 3.5 | AU10: =VLOOKUP(AT10,المرجع!$D$3:$E$12,2) -> ج+ | AV10: =AT10*AR10 -> 7 | AW10: 2 | AX10: 75 | AY10: =VLOOKUP(AX10,المرجع!$B$3:$C$12,2) -> 3.5 | AZ10: =VLOOKUP(AY10,المرجع!$D$3:$E$12,2) -> ج+ | BA10: =AY10*AW10 -> 7 | BB10: 2 | BC10: 100 | BD10: =VLOOKUP(BC10,المرجع!$B$3:$C$12,2) -> 5 | BE10: =VLOOKUP(BD10,المرجع!$D$3:$E$12,2) -> أ+ | BF10: =BD10*BB10 -> 10 | BG10: 2 | BH10: 94 | BI10: =VLOOKUP(BH10,المرجع!$B$3:$C$12,2) -> 4.75 | BJ10: =VLOOKUP(BI10,المرجع!$D$3:$E$12,2) -> أ | BK10: =BI10*BG10 -> 9.5 | BL10: =-BK10+BF10+BA10+AV10+AQ10+AL10+AG10+AB10+W10+R10+M10+H10 -> 81.5 | BM10: =SUM(BG10+BB10+AW10+AR10+AM10+AH10+AC10+X10+S10+N10+I10+D10) -> 23 | BN10: =BL10/BM10 -> 3.5434783 | BP10: =VLOOKUP(BN10,المرجع!$D$3:$F$12,3) -> جيد مرتفع | BQ10: =RANK(BN10,$BN$3:$BN$98) -> 10
B11: 2023084 | C11: فاطمة شيخ تونكارا | D11: 1 | E11: 95 | F11: =VLOOKUP(E11,المرجع!$B$3:$C$12,2) -> 5 | G11: =VLOOKUP(F11,المرجع!$D$3:$E$12,2) -> أ+ | H11: =F11*D11 -> 5 | I11: 2 | J11: 100 | K11: =VLOOKUP(J11,المرجع!$B$3:$C$12,2) -> 5 | L11: =VLOOKUP(K11,المرجع!$D$3:$E$12,2) -> أ+ | M11: =K11*I11 -> 10 | N11: 2 | O11: 91 | P11: =VLOOKUP(O11,المرجع!$B$3:$C$12,2) -> 4.75 | Q11: =VLOOKUP(P11,المرجع!$D$3:$E$12,2) -> أ | R11: =P11*N11 -> 9.5 | S11: 2 | T11: 100 | U11: =VLOOKUP(T11,المرجع!$B$3:$C$12,2) -> 5 | V11: =VLOOKUP(U11,المرجع!$D$3:$E$12,2) -> أ+ | W11: =U11*S11 -> 10 | X11: 2 | Y11: 90 | Z11: =VLOOKUP(Y11,المرجع!$B$3:$C$12,2) -> 4.75 | AA11: =VLOOKUP(Z11,المرجع!$D$3:$E$12,2) -> أ | AB11: =Z11*X11 -> 9.5 | AC11: 2 | AD11: 73 | AE11: =VLOOKUP(AD11,المرجع!$B$3:$C$12,2) -> 3 | AF11: =VLOOKUP(AE11,المرجع!$D$3:$E$12,2) -> ج | AG11: =AE11*AC11 -> 6 | AH11: 2 | AI11: 83 | AJ11: =VLOOKUP(AI11,المرجع!$B$3:$C$12,2) -> 4 | AK11: =VLOOKUP(AJ11,المرجع!$D$3:$E$12,2) -> ب | AL11: =AJ11*AH11 -> 8 | AM11: 2 | AN11: 91 | AO11: =VLOOKUP(AN11,المرجع!$B$3:$C$12,2) -> 4.75 | AP11: =VLOOKUP(AO11,المرجع!$D$3:$E$12,2) -> أ | AQ11: =AO11*AM11 -> 9.5 | AR11: 2 | AS11: 75 | AT11: =VLOOKUP(AS11,المرجع!$B$3:$C$12,2) -> 3.5 | AU11: =VLOOKUP(AT11,المرجع!$D$3:$E$12,2) -> ج+ | AV11: =AT11*AR11 -> 7 | AW11: 2 | AX11: 60 | AY11: =VLOOKUP(AX11,المرجع!$B$3:$C$12,2) -> 2 | AZ11: =VLOOKUP(AY11,المرجع!$D$3:$E$12,2) -> د | BA11: =AY11*AW11 -> 4 | BB11: 2 | BC11: 100 | BD11: =VLOOKUP(BC11,المرجع!$B$3:$C$12,2) -> 5 | BE11: =VLOOKUP(BD11,المرجع!$D$3:$E$12,2) -> أ+ | BF11: =BD11*BB11 -> 10 | BG11: 2 | BH11: 98 | BI11: =VLOOKUP(BH11,المرجع!$B$3:$C$12,2) -> 5 | BJ11: =VLOOKUP(BI11,المرجع!$D$3:$E$12,2) -> أ+ | BK11: =BI11*BG11 -> 10 | BL11: =-BK11+BF11+BA11+AV11+AQ11+AL11+AG11+AB11+W11+R11+M11+H11 -> 78.5 | BM11: =SUM(BG11+BB11+AW11+AR11+AM11+AH11+AC11+X11+S11+N11+I11+D11) -> 23 | BN11: =BL11/BM11 -> 3.4130435 | BP11: =VLOOKUP(BN11,المرجع!$D$3:$F$12,3) -> جيد مرتفع | BQ11: =RANK(BN11,$BN$3:$BN$98) -> 15
B12: 2023087 | C12: فودي بندا سيلا | D12: 1 | E12: 92 | F12: =VLOOKUP(E12,المرجع!$B$3:$C$12,2) -> 4.75 | G12: =VLOOKUP(F12,المرجع!$D$3:$E$12,2) -> أ | H12: =F12*D12 -> 4.75 | I12: 2 | J12: 100 | K12: =VLOOKUP(J12,المرجع!$B$3:$C$12,2) -> 5 | L12: =VLOOKUP(K12,المرجع!$D$3:$E$12,2) -> أ+ | M12: =K12*I12 -> 10 | N12: 2 | O12: 83 | P12: =VLOOKUP(O12,المرجع!$B$3:$C$12,2) -> 4 | Q12: =VLOOKUP(P12,المرجع!$D$3:$E$12,2) -> ب | R12: =P12*N12 -> 8 | S12: 2 | T12: 97 | U12: =VLOOKUP(T12,المرجع!$B$3:$C$12,2) -> 5 | V12: =VLOOKUP(U12,المرجع!$D$3:$E$12,2) -> أ+ | W12: =U12*S12 -> 10 | X12: 2 | Y12: 100 | Z12: =VLOOKUP(Y12,المرجع!$B$3:$C$12,2) -> 5 | AA12: =VLOOKUP(Z12,المرجع!$D$3:$E$12,2) -> أ+ | AB12: =Z12*X12 -> 10 | AC12: 2 | AD12: 76 | AE12: =VLOOKUP(AD12,المرجع!$B$3:$C$12,2) -> 3.5 | AF12: =VLOOKUP(AE12,المرجع!$D$3:$E$12,2) -> ج+ | AG12: =AE12*AC12 -> 7 | AH12: 2 | AI12: 84 | AJ12: =VLOOKUP(AI12,المرجع!$B$3:$C$12,2) -> 4 | AK12: =VLOOKUP(AJ12,المرجع!$D$3:$E$12,2) -> ب | AL12: =AJ12*AH12 -> 8 | AM12: 2 | AN12: 90 | AO12: =VLOOKUP(AN12,المرجع!$B$3:$C$12,2) -> 4.75 | AP12: =VLOOKUP(AO12,المرجع!$D$3:$E$12,2) -> أ | AQ12: =AO12*AM12 -> 9.5 | AR12: 2 | AS12: 93 | AT12: =VLOOKUP(AS12,المرجع!$B$3:$C$12,2) -> 4.75 | AU12: =VLOOKUP(AT12,المرجع!$D$3:$E$12,2) -> أ | AV12: =AT12*AR12 -> 9.5 | AW12: 2 | AX12: 65 | AY12: =VLOOKUP(AX12,المرجع!$B$3:$C$12,2) -> 2.5 | AZ12: =VLOOKUP(AY12,المرجع!$D$3:$E$12,2) -> د+ | BA12: =AY12*AW12 -> 5 | BB12: 2 | BC12: 86 | BD12: =VLOOKUP(BC12,المرجع!$B$3:$C$12,2) -> 4.5 | BE12: =VLOOKUP(BD12,المرجع!$D$3:$E$12,2) -> ب+ | BF12: =BD12*BB12 -> 9 | BG12: 2 | BH12: 81 | BI12: =VLOOKUP(BH12,المرجع!$B$3:$C$12,2) -> 4 | BJ12: =VLOOKUP(BI12,المرجع!$D$3:$E$12,2) -> ب | BK12: =BI12*BG12 -> 8 | BL12: =-BK12+BF12+BA12+AV12+AQ12+AL12+AG12+AB12+W12+R12+M12+H12 -> 82.75 | BM12: =SUM(BG12+BB12+AW12+AR12+AM12+AH12+AC12+X12+S12+N12+I12+D12) -> 23 | BN12: =BL12/BM12 -> 3.5978261 | BP12: =VLOOKUP(BN12,المرجع!$D$3:$F$12,3) -> جيد مرتفع | BQ12: =RANK(BN12,$BN$3:$BN$98) -> 7
B13: 2023051 | C13: صالح سيدي فاتي | D13: 1 | E13: 95 | F13: =VLOOKUP(E13,المرجع!$B$3:$C$12,2) -> 5 | G13: =VLOOKUP(F13,المرجع!$D$3:$E$12,2) -> أ+ | H13: =F13*D13 -> 5 | I13: 2 | J13: 100 | K13: =VLOOKUP(J13,المرجع!$B$3:$C$12,2) -> 5 | L13: =VLOOKUP(K13,المرجع!$D$3:$E$12,2) -> أ+ | M13: =K13*I13 -> 10 | N13: 2 | O13: 70 | P13: =VLOOKUP(O13,المرجع!$B$3:$C$12,2) -> 3 | Q13: =VLOOKUP(P13,المرجع!$D$3:$E$12,2) -> ج | R13: =P13*N13 -> 6 | S13: 2 | T13: 100 | U13: =VLOOKUP(T13,المرجع!$B$3:$C$12,2) -> 5 | V13: =VLOOKUP(U13,المرجع!$D$3:$E$12,2) -> أ+ | W13: =U13*S13 -> 10 | X13: 2 | Y13: 100 | Z13: =VLOOKUP(Y13,المرجع!$B$3:$C$12,2) -> 5 | AA13: =VLOOKUP(Z13,المرجع!$D$3:$E$12,2) -> أ+ | AB13: =Z13*X13 -> 10 | AC13: 2 | AD13: 95 | AE13: =VLOOKUP(AD13,المرجع!$B$3:$C$12,2) -> 5 | AF13: =VLOOKUP(AE13,المرجع!$D$3:$E$12,2) -> أ+ | AG13: =AE13*AC13 -> 10 | AH13: 2 | AI13: 85 | AJ13: =VLOOKUP(AI13,المرجع!$B$3:$C$12,2) -> 4.5 | AK13: =VLOOKUP(AJ13,المرجع!$D$3:$E$12,2) -> ب+ | AL13: =AJ13*AH13 -> 9 | AM13: 2 | AN13: 90 | AO13: =VLOOKUP(AN13,المرجع!$B$3:$C$12,2) -> 4.75 | AP13: =VLOOKUP(AO13,المرجع!$D$3:$E$12,2) -> أ | AQ13: =AO13*AM13 -> 9.5 | AR13: 2 | AS13: 79 | AT13: =VLOOKUP(AS13,المرجع!$B$3:$C$12,2) -> 3.5 | AU13: =VLOOKUP(AT13,المرجع!$D$3:$E$12,2) -> ج+ | AV13: =AT13*AR13 -> 7 | AW13: 2 | AX13: 65 | AY13: =VLOOKUP(AX13,المرجع!$B$3:$C$12,2) -> 2.5 | AZ13: =VLOOKUP(AY13,المرجع!$D$3:$E$12,2) -> د+ | BA13: =AY13*AW13 -> 5 | BB13: 2 | BC13: 80 | BD13: =VLOOKUP(BC13,المرجع!$B$3:$C$12,2) -> 4 | BE13: =VLOOKUP(BD13,المرجع!$D$3:$E$12,2) -> ب | BF13: =BD13*BB13 -> 8 | BG13: 2 | BH13: 84 | BI13: =VLOOKUP(BH13,المرجع!$B$3:$C$12,2) -> 4 | BJ13: =VLOOKUP(BI13,المرجع!$D$3:$E$12,2) -> ب | BK13: =BI13*BG13 -> 8 | BL13: =-BK13+BF13+BA13+AV13+AQ13+AL13+AG13+AB13+W13+R13+M13+H13 -> 81.5 | BM13: =SUM(BG13+BB13+AW13+AR13+AM13+AH13+AC13+X13+S13+N13+I13+D13) -> 23 | BN13: =BL13/BM13 -> 3.5434783 | BP13: =VLOOKUP(BN13,المرجع!$D$3:$F$12,3) -> جيد مرتفع | BQ13: =RANK(BN13,$BN$3:$BN$98) -> 10
B14: 2023072 | C14: عمر الأمين درامي | D14: 1 | E14: 98 | F14: =VLOOKUP(E14,المرجع!$B$3:$C$12,2) -> 5 | G14: =VLOOKUP(F14,المرجع!$D$3:$E$12,2) -> أ+ | H14: =F14*D14 -> 5 | I14: 2 | J14: 100 | K14: =VLOOKUP(J14,المرجع!$B$3:$C$12,2) -> 5 | L14: =VLOOKUP(K14,المرجع!$D$3:$E$12,2) -> أ+ | M14: =K14*I14 -> 10 | N14: 2 | O14: 50 | P14: =VLOOKUP(O14,المرجع!$B$3:$C$12,2) -> 2 | Q14: =VLOOKUP(P14,المرجع!$D$3:$E$12,2) -> د | R14: =P14*N14 -> 4 | S14: 2 | T14: 100 | U14: =VLOOKUP(T14,المرجع!$B$3:$C$12,2) -> 5 | V14: =VLOOKUP(U14,المرجع!$D$3:$E$12,2) -> أ+ | W14: =U14*S14 -> 10 | X14: 2 | Y14: 100 | Z14: =VLOOKUP(Y14,المرجع!$B$3:$C$12,2) -> 5 | AA14: =VLOOKUP(Z14,المرجع!$D$3:$E$12,2) -> أ+ | AB14: =Z14*X14 -> 10 | AC14: 2 | AD14: 91 | AE14: =VLOOKUP(AD14,المرجع!$B$3:$C$12,2) -> 4.75 | AF14: =VLOOKUP(AE14,المرجع!$D$3:$E$12,2) -> أ | AG14: =AE14*AC14 -> 9.5 | AH14: 2 | AI14: 83 | AJ14: =VLOOKUP(AI14,المرجع!$B$3:$C$12,2) -> 4 | AK14: =VLOOKUP(AJ14,المرجع!$D$3:$E$12,2) -> ب | AL14: =AJ14*AH14 -> 8 | AM14: 2 | AN14: 94 | AO14: =VLOOKUP(AN14,المرجع!$B$3:$C$12,2) -> 4.75 | AP14: =VLOOKUP(AO14,المرجع!$D$3:$E$12,2) -> أ | AQ14: =AO14*AM14 -> 9.5 | AR14: 2 | AS14: 83 | AT14: =VLOOKUP(AS14,المرجع!$B$3:$C$12,2) -> 4 | AU14: =VLOOKUP(AT14,المرجع!$D$3:$E$12,2) -> ب | AV14: =AT14*AR14 -> 8 | AW14: 2 | AX14: 75 | AY14: =VLOOKUP(AX14,المرجع!$B$3:$C$12,2) -> 3.5 | AZ14: =VLOOKUP(AY14,المرجع!$D$3:$E$12,2) -> ج+ | BA14: =AY14*AW14 -> 7 | BB14: 2 | BC14: 94 | BD14: =VLOOKUP(BC14,المرجع!$B$3:$C$12,2) -> 4.75 | BE14: =VLOOKUP(BD14,المرجع!$D$3:$E$12,2) -> أ | BF14: =BD14*BB14 -> 9.5 | BG14: 2 | BH14: 75 | BI14: =VLOOKUP(BH14,المرجع!$B$3:$C$12,2) -> 3.5 | BJ14: =VLOOKUP(BI14,المرجع!$D$3:$E$12,2) -> ج+ | BK14: =BI14*BG14 -> 7 | BL14: =-BK14+BF14+BA14+AV14+AQ14+AL14+AG14+AB14+W14+R14+M14+H14 -> 83.5 | BM14: =SUM(BG14+BB14+AW14+AR14+AM14+AH14+AC14+X14+S14+N14+I14+D14) -> 23 | BN14: =BL14/BM14 -> 3.6304348 | BP14: =VLOOKUP(BN14,المرجع!$D$3:$F$12,3) -> جيد جدا | BQ14: =RANK(BN14,$BN$3:$BN$98) -> 6
... B98: 2023086 | C98: فاطمة فندي سانيا | D98: 1 | E98: 0 | F98: =VLOOKUP(E98,المرجع!$B$3:$C$12,2) -> 0 | G98: =VLOOKUP(F98,المرجع!$D$3:$E$12,2) -> ه | H98: =F98*D98 -> 0 | I98: 2 | J98: 0 | K98: =VLOOKUP(J98,المرجع!$B$3:$C$12,2) -> 0 | L98: =VLOOKUP(K98,المرجع!$D$3:$E$12,2) -> ه | M98: =K98*I98 -> 0 | N98: 2 | O98: 5 | P98: =VLOOKUP(O98,المرجع!$B$3:$C$12,2) -> 0 | Q98: =VLOOKUP(P98,المرجع!$D$3:$E$12,2) -> ه | R98: =P98*N98 -> 0 | S98: 2 | T98: 0 | U98: =VLOOKUP(T98,المرجع!$B$3:$C$12,2) -> 0 | V98: =VLOOKUP(U98,المرجع!$D$3:$E$12,2) -> ه | W98: =U98*S98 -> 0 | X98: 2 | Y98: 0 | Z98: =VLOOKUP(Y98,المرجع!$B$3:$C$12,2) -> 0 | AA98: =VLOOKUP(Z98,المرجع!$D$3:$E$12,2) -> ه | AB98: =Z98*X98 -> 0 | AC98: 2 | AD98: 15 | AE98: =VLOOKUP(AD98,المرجع!$B$3:$C$12,2) -> 0 | AF98: =VLOOKUP(AE98,المرجع!$D$3:$E$12,2) -> ه | AG98: =AE98*AC98 -> 0 | AH98: 2 | AI98: 35 | AJ98: =VLOOKUP(AI98,المرجع!$B$3:$C$12,2) -> 0 | AK98: =VLOOKUP(AJ98,المرجع!$D$3:$E$12,2) -> ه | AL98: =AJ98*AH98 -> 0 | AM98: 2 | AN98: 61 | AO98: =VLOOKUP(AN98,المرجع!$B$3:$C$12,2) -> 2 | AP98: =VLOOKUP(AO98,المرجع!$D$3:$E$12,2) -> د | AQ98: =AO98*AM98 -> 4 | AR98: 2 | AS98: 35 | AT98: =VLOOKUP(AS98,المرجع!$B$3:$C$12,2) -> 0 | AU98: =VLOOKUP(AT98,المرجع!$D$3:$E$12,2) -> ه | AV98: =AT98*AR98 -> 0 | AW98: 2 | AX98: 40 | AY98: =VLOOKUP(AX98,المرجع!$B$3:$C$12,2) -> 0 | AZ98: =VLOOKUP(AY98,المرجع!$D$3:$E$12,2) -> ه | BA98: =AY98*AW98 -> 0 | BB98: 2 | BC98: 0 | BD98: =VLOOKUP(BC98,المرجع!$B$3:$C$12,2) -> 0 | BE98: =VLOOKUP(BD98,المرجع!$D$3:$E$12,2) -> ه | BF98: =BD98*BB98 -> 0 | BG98: 2 | BH98: 32 | BI98: =VLOOKUP(BH98,المرجع!$B$3:$C$12,2) -> 0 | BJ98: =VLOOKUP(BI98,المرجع!$D$3:$E$12,2) -> ه | BK98: =BI98*BG98 -> 0 | BL98: =-BK98+BF98+BA98+AV98+AQ98+AL98+AG98+AB98+W98+R98+M98+H98 -> 4 | BM98: =SUM(BG98+BB98+AW98+AR98+AM98+AH98+AC98+X98+S98+N98+I98+D98) -> 23 | BN98: =BL98/BM98 -> 0.17391304 | BP98: =VLOOKUP(BN98,المرجع!$D$3:$F$12,3) -> راسب | BQ98: =RANK(BN98,$BN$3:$BN$98) -> 96

Sheet المستوى الثاني 2023
B2: رقم التسلسل | C2: الإسم | D2: الساعات | E2: القرأن الكريم (2) | F2: الوزن | G2: الرمز | H2: النقاط | I2: الساعات | J2: التفسير (1) | K2: الوزن | L2: الرمز | M2: النقاط | N2: الساعات | O2: الفقه (2) | P2: الوزن | Q2: الرمز | R2: النقاط | S2: الساعات | T2: الحديث التحليلي (1) | U2: الوزن | V2: الرمز | W2: النقاط | X2: الساعات | Y2: روة الحديث (1) | Z2: الوزن | AA2: الرمز | AB2: النقاط | AC2: الساعات | AD2: مصطلح الحديث (1) | AE2: الوزن | AF2: الرمز | AG2: النقاط | AH2: الساعات | AI2: النحو (2) | AJ2: الوزن | AK2: الرمز | AL2: النقاط | AM2: الساعات | AN2: مناهج المحدثين (1) | AO2: الوزن | AP2: الرمز | AQ2: النقاط | AR2: الساعات | AS2: الحاسوب (1) | AT2: الوزن | AU2: الرمز | AV2: النقاط | AW2: الساعات | AX2: English(2) | AY2: الوزن | AZ2: الرمز | BA2: النقاط | BB2: مجموع النقاط | BC2: مجموع الساعات | BD2: المعدل الفصلي | BE2: المعدل التراكمي | BF2: التقدير | BG2: الترتيب
B3: 2023035 | C3: بنت موسى سماري | D3: 1 | E3: 100 | F3: =VLOOKUP(E3,المرجع!$B$3:$C$12,2) -> 5 | G3: =VLOOKUP(F3,المرجع!$D$3:$E$12,2) -> أ+ | H3: =F3*D3 -> 5 | I3: 2 | J3: 100 | K3: =VLOOKUP(J3,المرجع!$B$3:$C$12,2) -> 5 | L3: =VLOOKUP(K3,المرجع!$D$3:$E$12,2) -> أ+ | M3: =K3*I3 -> 10 | N3: 2 | O3: 100 | P3: =VLOOKUP(O3,المرجع!$B$3:$C$12,2) -> 5 | Q3: =VLOOKUP(P3,المرجع!$D$3:$E$12,2) -> أ+ | R3: =P3*N3 -> 10 | S3: 3 | T3: 100 | U3: =VLOOKUP(T3,المرجع!$B$3:$C$12,2) -> 5 | V3: =VLOOKUP(U3,المرجع!$D$3:$E$12,2) -> أ+ | W3: =U3*S3 -> 15 | X3: 2 | Y3: 100 | Z3: =VLOOKUP(Y3,المرجع!$B$3:$C$12,2) -> 5 | AA3: =VLOOKUP(Z3,المرجع!$D$3:$E$12,2) -> أ+ | AB3: =Z3*X3 -> 10 | AC3: 3 | AD3: 94 | AE3: =VLOOKUP(AD3,المرجع!$B$3:$C$12,2) -> 4.75 | AF3: =VLOOKUP(AE3,المرجع!$D$3:$E$12,2) -> أ | AG3: =AE3*AC3 -> 14.25 | AH3: 2 | AI3: 95 | AJ3: =VLOOKUP(AI3,المرجع!$B$3:$C$12,2) -> 5 | AK3: =VLOOKUP(AJ3,المرجع!$D$3:$E$12,2) -> أ+ | AL3: =AJ3*AH3 -> 10 | AM3: 3 | AN3: 92 | AO3: =VLOOKUP(AN3,المرجع!$B$3:$C$12,2) -> 4.75 | AP3: =VLOOKUP(AO3,المرجع!$D$3:$E$12,2) -> أ | AQ3: =AO3*AM3 -> 14.25 | AR3: 2 | AS3: 90 | AT3: =VLOOKUP(AS3,المرجع!$B$3:$C$12,2) -> 4.75 | AU3: =VLOOKUP(AT3,المرجع!$D$3:$E$12,2) -> أ | AV3: =AT3*AR3 -> 9.5 | AW3: 2 | AX3: 100 | AY3: =VLOOKUP(AX3,المرجع!$B$3:$C$12,2) -> 5 | AZ3: =VLOOKUP(AY3,المرجع!$D$3:$E$12,2) -> أ+ | BA3: =AY3*AW3 -> 10 | BB3: =BA3+AV3+AQ3+AL3+AG3+AB3+W3+R3+M3+H3 -> 108 | BC3: =AW3+AR3+AM3+AH3+AC3+X3+S3+N3+I3+D3 -> 22 | BD3: =BB3/BC3 -> 4.9090909 | BE3: =('المستوى الأول 2022'!BL3+'المستوى الثاني 2023'!BB3)/('المستوى الثاني 2023'!BC3+'المستوى الأول 2022'!BM3) -> 4.3777778 | BF3: =VLOOKUP(BE3,المرجع!$D$3:$F$12,3) -> جيد جد مرتفع | BG3: =RANK(BD3,$BD$3:$BD$87) -> 1
B4: 2023002 | C4: ديالو إبراهيم | D4: 1 | E4: 100 | F4: =VLOOKUP(E4,المرجع!$B$3:$C$12,2) -> 5 | G4: =VLOOKUP(F4,المرجع!$D$3:$E$12,2) -> أ+ | H4: =F4*D4 -> 5 | I4: 2 | J4: 97 | K4: =VLOOKUP(J4,المرجع!$B$3:$C$12,2) -> 5 | L4: =VLOOKUP(K4,المرجع!$D$3:$E$12,2) -> أ+ | M4: =K4*I4 -> 10 | N4: 2 | O4: 94 | P4: =VLOOKUP(O4,المرجع!$B$3:$C$12,2) -> 4.75 | Q4: =VLOOKUP(P4,المرجع!$D$3:$E$12,2) -> أ | R4: =P4*N4 -> 9.5 | S4: 3 | T4: 100 | U4: =VLOOKUP(T4,المرجع!$B$3:$C$12,2) -> 5 | V4: =VLOOKUP(U4,المرجع!$D$3:$E$12,2) -> أ+ | W4: =U4*S4 -> 15 | X4: 2 | Y4: 94 | Z4: =VLOOKUP(Y4,المرجع!$B$3:$C$12,2) -> 4.75 | AA4: =VLOOKUP(Z4,المرجع!$D$3:$E$12,2) -> أ | AB4: =Z4*X4 -> 9.5 | AC4: 3 | AD4: 86 | AE4: =VLOOKUP(AD4,المرجع!$B$3:$C$12,2) -> 4.5 | AF4: =VLOOKUP(AE4,المرجع!$D$3:$E$12,2) -> ب+ | AG4: =AE4*AC4 -> 13.5 | AH4: 2 | AI4: 90 | AJ4: =VLOOKUP(AI4,المرجع!$B$3:$C$12,2) -> 4.75 | AK4: =VLOOKUP(AJ4,المرجع!$D$3:$E$12,2) -> أ | AL4: =AJ4*AH4 -> 9.5 | AM4: 3 | AN4: 96 | AO4: =VLOOKUP(AN4,المرجع!$B$3:$C$12,2) -> 5 | AP4: =VLOOKUP(AO4,المرجع!$D$3:$E$12,2) -> أ+ | AQ4: =AO4*AM4 -> 15 | AR4: 2 | AS4: 100 | AT4: =VLOOKUP(AS4,المرجع!$B$3:$C$12,2) -> 5 | AU4: =VLOOKUP(AT4,المرجع!$D$3:$E$12,2) -> أ+ | AV4: =AT4*AR4 -> 10 | AW4: 2 | AX4: 100 | AY4: =VLOOKUP(AX4,المرجع!$B$3:$C$12,2) -> 5 | AZ4: =VLOOKUP(AY4,المرجع!$D$3:$E$12,2) -> أ+ | BA4: =AY4*AW4 -> 10 | BB4: =BA4+AV4+AQ4+AL4+AG4+AB4+W4+R4+M4+H4 -> 107 | BC4: =AW4+AR4+AM4+AH4+AC4+X4+S4+N4+I4+D4 -> 22 | BD4: =BB4/BC4 -> 4.8636364 | BE4: =('المستوى الأول 2022'!BL4+'المستوى الثاني 2023'!BB4)/('المستوى الثاني 2023'!BC4+'المستوى الأول 2022'!BM4) -> 4.3555556 | BF4: =VLOOKUP(BE4,المرجع!$D$3:$F$12,3) -> جيد جد مرتفع | BG4: =RANK(BD4,$BD$3:$BD$87) -> 2
B5: 2023085 | C5: فاطمة صغرى محمد جابي | D5: 1 | E5: 100 | F5: =VLOOKUP(E5,المرجع!$B$3:$C$12,2) -> 5 | G5: =VLOOKUP(F5,المرجع!$D$3:$E$12,2) -> أ+ | H5: =F5*D5 -> 5 | I5: 2 | J5: 100 | K5: =VLOOKUP(J5,المرجع!$B$3:$C$12,2) -> 5 | L5: =VLOOKUP(K5,المرجع!$D$3:$E$12,2) -> أ+ | M5: =K5*I5 -> 10 | N5: 2 | O5: 100 | P5: =VLOOKUP(O5,المرجع!$B$3:$C$12,2) -> 5 | Q5: =VLOOKUP(P5,المرجع!$D$3:$E$12,2) -> أ+ | R5: =P5*N5 -> 10 | S5: 3 | T5: 100 | U5: =VLOOKUP(T5,المرجع!$B$3:$C$12,2) -> 5 | V5: =VLOOKUP(U5,المرجع!$D$3:$E$12,2) -> أ+ | W5: =U5*S5 -> 15 | X5: 2 | Y5: 100 | Z5: =VLOOKUP(Y5,المرجع!$B$3:$C$12,2) -> 5 | AA5: =VLOOKUP(Z5,المرجع!$D$3:$E$12,2) -> أ+ | AB5: =Z5*X5 -> 10 | AC5: 3 | AD5: 89 | AE5: =VLOOKUP(AD5,المرجع!$B$3:$C$12,2) -> 4.5 | AF5: =VLOOKUP(AE5,المرجع!$D$3:$E$12,2) -> ب+ | AG5: =AE5*AC5 -> 13.5 | AH5: 2 | AI5: 94 | AJ5: =VLOOKUP(AI5,المرجع!$B$3:$C$12,2) -> 4.75 | AK5: =VLOOKUP(AJ5,المرجع!$D$3:$E$12,2) -> أ | AL5: =AJ5*AH5 -> 9.5 | AM5: 3 | AN5: 100 | AO5: =VLOOKUP(AN5,المرجع!$B$3:$C$12,2) -> 5 | AP5: =VLOOKUP(AO5,المرجع!$D$3:$E$12,2) -> أ+ | AQ5: =AO5*AM5 -> 15 | AR5: 2 | AS5: 80 | AT5: =VLOOKUP(AS5,المرجع!$B$3:$C$12,2) -> 4 | AU5: =VLOOKUP(AT5,المرجع!$D$3:$E$12,2) -> ب | AV5: =AT5*AR5 -> 8 | AW5: 2 | AX5: 100 | AY5: =VLOOKUP(AX5,المرجع!$B$3:$C$12,2) -> 5 | AZ5: =VLOOKUP(AY5,المرجع!$D$3:$E$12,2) -> أ+ | BA5: =AY5*AW5 -> 10 | BB5: =BA5+AV5+AQ5+AL5+AG5+AB5+W5+R5+M5+H5 -> 106 | BC5: =AW5+AR5+AM5+AH5+AC5+X5+S5+N5+I5+D5 -> 22 | BD5: =BB5/BC5 -> 4.8181818 | BE5: =('المستوى الأول 2022'!BL5+'المستوى الثاني 2023'!BB5)/('المستوى الثاني 2023'!BC5+'المستوى الأول 2022'!BM5) -> 4.3222222 | BF5: =VLOOKUP(BE5,المرجع!$D$3:$F$12,3) -> جيد جد مرتفع | BG5: =RANK(BD5,$BD$3:$BD$87) -> 3
B6: 2023062 | C6: عبد الله المام جكني | D6: 1 | E6: 98 | F6: =VLOOKUP(E6,المرجع!$B$3:$C$12,2) -> 5 | G6: =VLOOKUP(F6,المرجع!$D$3:$E$12,2) -> أ+ | H6: =F6*D6 -> 5 | I6: 2 | J6: 90 | K6: =VLOOKUP(J6,المرجع!$B$3:$C$12,2) -> 4.75 | L6: =VLOOKUP(K6,المرجع!$D$3:$E$12,2) -> أ | M6: =K6*I6 -> 9.5 | N6: 2 | O6: 94 | P6: =VLOOKUP(O6,المرجع!$B$3:$C$12,2) -> 4.75 | Q6: =VLOOKUP(P6,المرجع!$D$3:$E$12,2) -> أ | R6: =P6*N6 -> 9.5 | S6: 3 | T6: 100 | U6: =VLOOKUP(T6,المرجع!$B$3:$C$12,2) -> 5 | V6: =VLOOKUP(U6,المرجع!$D$3:$E$12,2) -> أ+ | W6: =U6*S6 -> 15 | X6: 2 | Y6: 91 | Z6: =VLOOKUP(Y6,المرجع!$B$3:$C$12,2) -> 4.75 | AA6: =VLOOKUP(Z6,المرجع!$D$3:$E$12,2) -> أ | AB6: =Z6*X6 -> 9.5 | AC6: 3 | AD6: 87 | AE6: =VLOOKUP(AD6,المرجع!$B$3:$C$12,2) -> 4.5 | AF6: =VLOOKUP(AE6,المرجع!$D$3:$E$12,2) -> ب+ | AG6: =AE6*AC6 -> 13.5 | AH6: 2 | AI6: 91 | AJ6: =VLOOKUP(AI6,المرجع!$B$3:$C$12,2) -> 4.75 | AK6: =VLOOKUP(AJ6,المرجع!$D$3:$E$12,2) -> أ | AL6: =AJ6*AH6 -> 9.5 | AM6: 3 | AN6: 91 | AO6: =VLOOKUP(AN6,المرجع!$B$3:$C$12,2) -> 4.75 | AP6: =VLOOKUP(AO6,المرجع!$D$3:$E$12,2) -> أ | AQ6: =AO6*AM6 -> 14.25 | AR6: 2 | AS6: 93 | AT6: =VLOOKUP(AS6,المرجع!$B$3:$C$12,2) -> 4.75 | AU6: =VLOOKUP(AT6,المرجع!$D$3:$E$12,2) -> أ | AV6: =AT6*AR6 -> 9.5 | AW6: 2 | AX6: 100 | AY6: =VLOOKUP(AX6,المرجع!$B$3:$C$12,2) -> 5 | AZ6: =VLOOKUP(AY6,المرجع!$D$3:$E$12,2) -> أ+ | BA6: =AY6*AW6 -> 10 | BB6: =BA6+AV6+AQ6+AL6+AG6+AB6+W6+R6+M6+H6 -> 105.25 | BC6: =AW6+AR6+AM6+AH6+AC6+X6+S6+N6+I6+D6 -> 22 | BD6: =BB6/BC6 -> 4.7840909 | BE6: =('المستوى الأول 2022'!BL6+'المستوى الثاني 2023'!BB6)/('المستوى الثاني 2023'!BC6+'المستوى الأول 2022'!BM6) -> 4.4611111 | BF6: =VLOOKUP(BE6,المرجع!$D$3:$F$12,3) -> جيد جد مرتفع | BG6: =RANK(BD6,$BD$3:$BD$87) -> 4
B7: 2023097 | C7: محمد بن سمبر دكوري | D7: 1 | E7: 100 | F7: =VLOOKUP(E7,المرجع!$B$3:$C$12,2) -> 5 | G7: =VLOOKUP(F7,المرجع!$D$3:$E$12,2) -> أ+ | H7: =F7*D7 -> 5 | I7: 2 | J7: 99 | K7: =VLOOKUP(J7,المرجع!$B$3:$C$12,2) -> 5 | L7: =VLOOKUP(K7,المرجع!$D$3:$E$12,2) -> أ+ | M7: =K7*I7 -> 10 | N7: 2 | O7: 98 | P7: =VLOOKUP(O7,المرجع!$B$3:$C$12,2) -> 5 | Q7: =VLOOKUP(P7,المرجع!$D$3:$E$12,2) -> أ+ | R7: =P7*N7 -> 10 | S7: 3 | T7: 100 | U7: =VLOOKUP(T7,المرجع!$B$3:$C$12,2) -> 5 | V7: =VLOOKUP(U7,المرجع!$D$3:$E$12,2) -> أ+ | W7: =U7*S7 -> 15 | X7: 2 | Y7: 100 | Z7: =VLOOKUP(Y7,المرجع!$B$3:$C$12,2) -> 5 | AA7: =VLOOKUP(Z7,المرجع!$D$3:$E$12,2) -> أ+ | AB7: =Z7*X7 -> 10 | AC7: 3 | AD7: 92 | AE7: =VLOOKUP(AD7,المرجع!$B$3:$C$12,2) -> 4.75 | AF7: =VLOOKUP(AE7,المرجع!$D$3:$E$12,2) -> أ | AG7: =AE7*AC7 -> 14.25 | AH7: 2 | AI7: 85 | AJ7: =VLOOKUP(AI7,المرجع!$B$3:$C$12,2) -> 4.5 | AK7: =VLOOKUP(AJ7,المرجع!$D$3:$E$12,2) -> ب+ | AL7: =AJ7*AH7 -> 9 | AM7: 3 | AN7: 100 | AO7: =VLOOKUP(AN7,المرجع!$B$3:$C$12,2) -> 5 | AP7: =VLOOKUP(AO7,المرجع!$D$3:$E$12,2) -> أ+ | AQ7: =AO7*AM7 -> 15 | AR7: 2 | AS7: 90 | AT7: =VLOOKUP(AS7,المرجع!$B$3:$C$12,2) -> 4.75 | AU7: =VLOOKUP(AT7,المرجع!$D$3:$E$12,2) -> أ | AV7: =AT7*AR7 -> 9.5 | AW7: 2 | AX7: 64 | AY7: =VLOOKUP(AX7,المرجع!$B$3:$C$12,2) -> 2 | AZ7: =VLOOKUP(AY7,المرجع!$D$3:$E$12,2) -> د | BA7: =AY7*AW7 -> 4 | BB7: =BA7+AV7+AQ7+AL7+AG7+AB7+W7+R7+M7+H7 -> 101.75 | BC7: =AW7+AR7+AM7+AH7+AC7+X7+S7+N7+I7+D7 -> 22 | BD7: =BB7/BC7 -> 4.625 | BE7: =('المستوى الأول 2022'!BL7+'المستوى الثاني 2023'!BB7)/('المستوى الثاني 2023'!BC7+'المستوى الأول 2022'!BM7) -> 4.2388889 | BF7: =VLOOKUP(BE7,المرجع!$D$3:$F$12,3) -> جيد جد مرتفع | BG7: =RANK(BD7,$BD$3:$BD$87) -> 8
B8: 2023053 | C8: عاتقة قطر أنيبل غلمسين | D8: 1 | E8: 100 | F8: =VLOOKUP(E8,المرجع!$B$3:$C$12,2) -> 5 | G8: =VLOOKUP(F8,المرجع!$D$3:$E$12,2) -> أ+ | H8: =F8*D8 -> 5 | I8: 2 | J8: 100 | K8: =VLOOKUP(J8,المرجع!$B$3:$C$12,2) -> 5 | L8: =VLOOKUP(K8,المرجع!$D$3:$E$12,2) -> أ+ | M8: =K8*I8 -> 10 | N8: 2 | O8: 100 | P8: =VLOOKUP(O8,المرجع!$B$3:$C$12,2) -> 5 | Q8: =VLOOKUP(P8,المرجع!$D$3:$E$12,2) -> أ+ | R8: =P8*N8 -> 10 | S8: 3 | T8: 100 | U8: =VLOOKUP(T8,المرجع!$B$3:$C$12,2) -> 5 | V8: =VLOOKUP(U8,المرجع!$D$3:$E$12,2) -> أ+ | W8: =U8*S8 -> 15 | X8: 2 | Y8: 100 | Z8: =VLOOKUP(Y8,المرجع!$B$3:$C$12,2) -> 5 | AA8: =VLOOKUP(Z8,المرجع!$D$3:$E$12,2) -> أ+ | AB8: =Z8*X8 -> 10 | AC8: 3 | AD8: 81 | AE8: =VLOOKUP(AD8,المرجع!$B$3:$C$12,2) -> 4 | AF8: =VLOOKUP(AE8,المرجع!$D$3:$E$12,2) -> ب | AG8: =AE8*AC8 -> 12 | AH8: 2 | AI8: 78 | AJ8: =VLOOKUP(AI8,المرجع!$B$3:$C$12,2) -> 3.5 | AK8: =VLOOKUP(AJ8,المرجع!$D$3:$E$12,2) -> ج+ | AL8: =AJ8*AH8 -> 7 | AM8: 3 | AN8: 92 | AO8: =VLOOKUP(AN8,المرجع!$B$3:$C$12,2) -> 4.75 | AP8: =VLOOKUP(AO8,المرجع!$D$3:$E$12,2) -> أ | AQ8: =AO8*AM8 -> 14.25 | AR8: 2 | AS8: 90 | AT8: =VLOOKUP(AS8,المرجع!$B$3:$C$12,2) -> 4.75 | AU8: =VLOOKUP(AT8,المرجع!$D$3:$E$12,2) -> أ | AV8: =AT8*AR8 -> 9.5 | AW8: 2 | AX8: 98 | AY8: =VLOOKUP(AX8,المرجع!$B$3:$C$12,2) -> 5 | AZ8: =VLOOKUP(AY8,المرجع!$D$3:$E$12,2) -> أ+ | BA8: =AY8*AW8 -> 10 | BB8: =BA8+AV8+AQ8+AL8+AG8+AB8+W8+R8+M8+H8 -> 102.75 | BC8: =AW8+AR8+AM8+AH8+AC8+X8+S8+N8+I8+D8 -> 22 | BD8: =BB8/BC8 -> 4.6704545 | BE8: =('المستوى الأول 2022'!BL8+'المستوى الثاني 2023'!BB8)/('المستوى الثاني 2023'!BC8+'المستوى الأول 2022'!BM8) -> 4.1055556 | BF8: =VLOOKUP(BE8,المرجع!$D$3:$F$12,3) -> جيد جد مرتفع | BG8: =RANK(BD8,$BD$3:$BD$87) -> 5
B9: 2023023 | C9: أمي بابا جاورا | D9: 1 | E9: 100 | F9: =VLOOKUP(E9,المرجع!$B$3:$C$12,2) -> 5 | G9: =VLOOKUP(F9,المرجع!$D$3:$E$12,2) -> أ+ | H9: =F9*D9 -> 5 | I9: 2 | J9: 100 | K9: =VLOOKUP(J9,المرجع!$B$3:$C$12,2) -> 5 | L9: =VLOOKUP(K9,المرجع!$D$3:$E$12,2) -> أ+ | M9: =K9*I9 -> 10 | N9: 2 | O9: 100 | P9: =VLOOKUP(O9,المرجع!$B$3:$C$12,2) -> 5 | Q9: =VLOOKUP(P9,المرجع!$D$3:$E$12,2) -> أ+ | R9: =P9*N9 -> 10 | S9: 3 | T9: 100 | U9: =VLOOKUP(T9,المرجع!$B$3:$C$12,2) -> 5 | V9: =VLOOKUP(U9,المرجع!$D$3:$E$12,2) -> أ+ | W9: =U9*S9 -> 15 | X9: 2 | Y9: 100 | Z9: =VLOOKUP(Y9,المرجع!$B$3:$C$12,2) -> 5 | AA9: =VLOOKUP(Z9,المرجع!$D$3:$E$12,2) -> أ+ | AB9: =Z9*X9 -> 10 | AC9: 3 | AD9: 81 | AE9: =VLOOKUP(AD9,المرجع!$B$3:$C$12,2) -> 4 | AF9: =VLOOKUP(AE9,المرجع!$D$3:$E$12,2) -> ب | AG9: =AE9*AC9 -> 12 | AH9: 2 | AI9: 95 | AJ9: =VLOOKUP(AI9,المرجع!$B$3:$C$12,2) -> 5 | AK9: =VLOOKUP(AJ9,المرجع!$D$3:$E$12,2) -> أ+ | AL9: =AJ9*AH9 -> 10 | AM9: 3 | AN9: 90 | AO9: =VLOOKUP(AN9,المرجع!$B$3:$C$12,2) -> 4.75 | AP9: =VLOOKUP(AO9,المرجع!$D$3:$E$12,2) -> أ | AQ9: =AO9*AM9 -> 14.25 | AR9: 2 | AS9: 70 | AT9: =VLOOKUP(AS9,المرجع!$B$3:$C$12,2) -> 3 | AU9: =VLOOKUP(AT9,المرجع!$D$3:$E$12,2) -> ج | AV9: =AT9*AR9 -> 6 | AW9: 2 | AX9: 100 | AY9: =VLOOKUP(AX9,المرجع!$B$3:$C$12,2) -> 5 | AZ9: =VLOOKUP(AY9,المرجع!$D$3:$E$12,2) -> أ+ | BA9: =AY9*AW9 -> 10 | BB9: =BA9+AV9+AQ9+AL9+AG9+AB9+W9+R9+M9+H9 -> 102.25 | BC9: =AW9+AR9+AM9+AH9+AC9+X9+S9+N9+I9+D9 -> 22 | BD9: =BB9/BC9 -> 4.6477273 | BE9: =('المستوى الأول 2022'!BL9+'المستوى الثاني 2023'!BB9)/('المستوى الثاني 2023'!BC9+'المستوى الأول 2022'!BM9) -> 4.0611111 | BF9: =VLOOKUP(BE9,المرجع!$D$3:$F$12,3) -> جيد جدا | BG9: =RANK(BD9,$BD$3:$BD$87) -> 6
B10: 2023084 | C10: فاطمة شيخ تونكارا | D10: 1 | E10: 100 | F10: =VLOOKUP(E10,المرجع!$B$3:$C$12,2) -> 5 | G10: =VLOOKUP(F10,المرجع!$D$3:$E$12,2) -> أ+ | H10: =F10*D10 -> 5 | I10: 2 | J10: 100 | K10: =VLOOKUP(J10,المرجع!$B$3:$C$12,2) -> 5 | L10: =VLOOKUP(K10,المرجع!$D$3:$E$12,2) -> أ+ | M10: =K10*I10 -> 10 | N10: 2 | O10: 100 | P10: =VLOOKUP(O10,المرجع!$B$3:$C$12,2) -> 5 | Q10: =VLOOKUP(P10,المرجع!$D$3:$E$12,2) -> أ+ | R10: =P10*N10 -> 10 | S10: 3 | T10: 100 | U10: =VLOOKUP(T10,المرجع!$B$3:$C$12,2) -> 5 | V10: =VLOOKUP(U10,المرجع!$D$3:$E$12,2) -> أ+ | W10: =U10*S10 -> 15 | X10: 2 | Y10: 91 | Z10: =VLOOKUP(Y10,المرجع!$B$3:$C$12,2) -> 4.75 | AA10: =VLOOKUP(Z10,المرجع!$D$3:$E$12,2) -> أ | AB10: =Z10*X10 -> 9.5 | AC10: 3 | AD10: 82 | AE10: =VLOOKUP(AD10,المرجع!$B$3:$C$12,2) -> 4 | AF10: =VLOOKUP(AE10,المرجع!$D$3:$E$12,2) -> ب | AG10: =AE10*AC10 -> 12 | AH10: 2 | AI10: 90 | AJ10: =VLOOKUP(AI10,المرجع!$B$3:$C$12,2) -> 4.75 | AK10: =VLOOKUP(AJ10,المرجع!$D$3:$E$12,2) -> أ | AL10: =AJ10*AH10 -> 9.5 | AM10: 3 | AN10: 99 | AO10: =VLOOKUP(AN10,المرجع!$B$3:$C$12,2) -> 5 | AP10: =VLOOKUP(AO10,المرجع!$D$3:$E$12,2) -> أ+ | AQ10: =AO10*AM10 -> 15 | AR10: 2 | AS10: 70 | AT10: =VLOOKUP(AS10,المرجع!$B$3:$C$12,2) -> 3 | AU10: =VLOOKUP(AT10,المرجع!$D$3:$E$12,2) -> ج | AV10: =AT10*AR10 -> 6 | AW10: 2 | AX10: 100 | AY10: =VLOOKUP(AX10,المرجع!$B$3:$C$12,2) -> 5 | AZ10: =VLOOKUP(AY10,المرجع!$D$3:$E$12,2) -> أ+ | BA10: =AY10*AW10 -> 10 | BB10: =BA10+AV10+AQ10+AL10+AG10+AB10+W10+R10+M10+H10 -> 102 | BC10: =AW10+AR10+AM10+AH10+AC10+X10+S10+N10+I10+D10 -> 22 | BD10: =BB10/BC10 -> 4.6363636 | BE10: =('المستوى الأول 2022'!BL10+'المستوى الثاني 2023'!BB10)/('المستوى الثاني 2023'!BC10+'المستوى الأول 2022'!BM10) -> 4.0777778 | BF10: =VLOOKUP(BE10,المرجع!$D$3:$F$12,3) -> جيد جدا | BG10: =RANK(BD10,$BD$3:$BD$87) -> 7
B11: 2023090 | C11: كيندو محمد | D11: 1 | E11: 98 | F11: =VLOOKUP(E11,المرجع!$B$3:$C$12,2) -> 5 | G11: =VLOOKUP(F11,المرجع!$D$3:$E$12,2) -> أ+ | H11: =F11*D11 -> 5 | I11: 2 | J11: 90 | K11: =VLOOKUP(J11,المرجع!$B$3:$C$12,2) -> 4.75 | L11: =VLOOKUP(K11,المرجع!$D$3:$E$12,2) -> أ | M11: =K11*I11 -> 9.5 | N11: 2 | O11: 89 | P11: =VLOOKUP(O11,المرجع!$B$3:$C$12,2) -> 4.5 | Q11: =VLOOKUP(P11,المرجع!$D$3:$E$12,2) -> ب+ | R11: =P11*N11 -> 9 | S11: 3 | T11: 99 | U11: =VLOOKUP(T11,المرجع!$B$3:$C$12,2) -> 5 | V11: =VLOOKUP(U11,المرجع!$D$3:$E$12,2) -> أ+ | W11: =U11*S11 -> 15 | X11: 2 | Y11: 94 | Z11: =VLOOKUP(Y11,المرجع!$B$3:$C$12,2) -> 4.75 | AA11: =VLOOKUP(Z11,المرجع!$D$3:$E$12,2) -> أ | AB11: =Z11*X11 -> 9.5 | AC11: 3 | AD11: 74 | AE11: =VLOOKUP(AD11,المرجع!$B$3:$C$12,2) -> 3 | AF11: =VLOOKUP(AE11,المرجع!$D$3:$E$12,2) -> ج | AG11: =AE11*AC11 -> 9 | AH11: 2 | AI11: 85 | AJ11: =VLOOKUP(AI11,المرجع!$B$3:$C$12,2) -> 4.5 | AK11: =VLOOKUP(AJ11,المرجع!$D$3:$E$12,2) -> ب+ | AL11: =AJ11*AH11 -> 9 | AM11: 3 | AN11: 90 | AO11: =VLOOKUP(AN11,المرجع!$B$3:$C$12,2) -> 4.75 | AP11: =VLOOKUP(AO11,المرجع!$D$3:$E$12,2) -> أ | AQ11: =AO11*AM11 -> 14.25 | AR11: 2 | AS11: 90 | AT11: =VLOOKUP(AS11,المرجع!$B$3:$C$12,2) -> 4.75 | AU11: =VLOOKUP(AT11,المرجع!$D$3:$E$12,2) -> أ | AV11: =AT11*AR11 -> 9.5 | AW11: 2 | AX11: 86 | AY11: =VLOOKUP(AX11,المرجع!$B$3:$C$12,2) -> 4.5 | AZ11: =VLOOKUP(AY11,المرجع!$D$3:$E$12,2) -> ب+ | BA11: =AY11*AW11 -> 9 | BB11: =BA11+AV11+AQ11+AL11+AG11+AB11+W11+R11+M11+H11 -> 98.75 | BC11: =AW11+AR11+AM11+AH11+AC11+X11+S11+N11+I11+D11 -> 22 | BD11: =BB11/BC11 -> 4.4886364 | BE11: =('المستوى الأول 2022'!BL11+'المستوى الثاني 2023'!BB11)/('المستوى الثاني 2023'!BC11+'المستوى الأول 2022'!BM11) -> 3.9388889 | BF11: =VLOOKUP(BE11,المرجع!$D$3:$F$12,3) -> جيد جدا | BG11: =RANK(BD11,$BD$3:$BD$87) -> 10
B12: 2023001 | C12: جميل براون | D12: 1 | E12: 96 | F12: =VLOOKUP(E12,المرجع!$B$3:$C$12,2) -> 5 | G12: =VLOOKUP(F12,المرجع!$D$3:$E$12,2) -> أ+ | H12: =F12*D12 -> 5 | I12: 2 | J12: 85 | K12: =VLOOKUP(J12,المرجع!$B$3:$C$12,2) -> 4.5 | L12: =VLOOKUP(K12,المرجع!$D$3:$E$12,2) -> ب+ | M12: =K12*I12 -> 9 | N12: 2 | O12: 84 | P12: =VLOOKUP(O12,المرجع!$B$3:$C$12,2) -> 4 | Q12: =VLOOKUP(P12,المرجع!$D$3:$E$12,2) -> ب | R12: =P12*N12 -> 8 | S12: 3 | T12: 100 | U12: =VLOOKUP(T12,المرجع!$B$3:$C$12,2) -> 5 | V12: =VLOOKUP(U12,المرجع!$D$3:$E$12,2) -> أ+ | W12: =U12*S12 -> 15 | X12: 2 | Y12: 100 | Z12: =VLOOKUP(Y12,المرجع!$B$3:$C$12,2) -> 5 | AA12: =VLOOKUP(Z12,المرجع!$D$3:$E$12,2) -> أ+ | AB12: =Z12*X12 -> 10 | AC12: 3 | AD12: 87 | AE12: =VLOOKUP(AD12,المرجع!$B$3:$C$12,2) -> 4.5 | AF12: =VLOOKUP(AE12,المرجع!$D$3:$E$12,2) -> ب+ | AG12: =AE12*AC12 -> 13.5 | AH12: 2 | AI12: 85 | AJ12: =VLOOKUP(AI12,المرجع!$B$3:$C$12,2) -> 4.5 | AK12: =VLOOKUP(AJ12,المرجع!$D$3:$E$12,2) -> ب+ | AL12: =AJ12*AH12 -> 9 | AM12: 3 | AN12: 90 | AO12: =VLOOKUP(AN12,المرجع!$B$3:$C$12,2) -> 4.75 | AP12: =VLOOKUP(AO12,المرجع!$D$3:$E$12,2) -> أ | AQ12: =AO12*AM12 -> 14.25 | AR12: 2 | AS12: 70 | AT12: =VLOOKUP(AS12,المرجع!$B$3:$C$12,2) -> 3 | AU12: =VLOOKUP(AT12,المرجع!$D$3:$E$12,2) -> ج | AV12: =AT12*AR12 -> 6 | AW12: 2 | AX12: 100 | AY12: =VLOOKUP(AX12,المرجع!$B$3:$C$12,2) -> 5 | AZ12: =VLOOKUP(AY12,المرجع!$D$3:$E$12,2) -> أ+ | BA12: =AY12*AW12 -> 10 | BB12: =BA12+AV12+AQ12+AL12+AG12+AB12+W12+R12+M12+H12 -> 99.75 | BC12: =AW12+AR12+AM12+AH12+AC12+X12+S12+N12+I12+D12 -> 22 | BD12: =BB12/BC12 -> 4.5340909 | BE12: =('المستوى الأول 2022'!BL12+'المستوى الثاني 2023'!BB12)/('المستوى الثاني 2023'!BC12+'المستوى الأول 2022'!BM12) -> 4.0555556 | BF12: =VLOOKUP(BE12,المرجع!$D$3:$F$12,3) -> جيد جدا | BG12: =RANK(BD12,$BD$3:$BD$87) -> 9
B13: 2023027 | C13: آدم عبد الحميد سنكارا | D13: 1 | E13: 100 | F13: =VLOOKUP(E13,المرجع!$B$3:$C$12,2) -> 5 | G13: =VLOOKUP(F13,المرجع!$D$3:$E$12,2) -> أ+ | H13: =F13*D13 -> 5 | I13: 2 | J13: 95 | K13: =VLOOKUP(J13,المرجع!$B$3:$C$12,2) -> 5 | L13: =VLOOKUP(K13,المرجع!$D$3:$E$12,2) -> أ+ | M13: =K13*I13 -> 10 | N13: 2 | O13: 94 | P13: =VLOOKUP(O13,المرجع!$B$3:$C$12,2) -> 4.75 | Q13: =VLOOKUP(P13,المرجع!$D$3:$E$12,2) -> أ | R13: =P13*N13 -> 9.5 | S13: 3 | T13: 100 | U13: =VLOOKUP(T13,المرجع!$B$3:$C$12,2) -> 5 | V13: =VLOOKUP(U13,المرجع!$D$3:$E$12,2) -> أ+ | W13: =U13*S13 -> 15 | X13: 2 | Y13: 100 | Z13: =VLOOKUP(Y13,المرجع!$B$3:$C$12,2) -> 5 | AA13: =VLOOKUP(Z13,المرجع!$D$3:$E$12,2) -> أ+ | AB13: =Z13*X13 -> 10 | AC13: 3 | AD13: 92 | AE13: =VLOOKUP(AD13,المرجع!$B$3:$C$12,2) -> 4.75 | AF13: =VLOOKUP(AE13,المرجع!$D$3:$E$12,2) -> أ | AG13: =AE13*AC13 -> 14.25 | AH13: 2 | AI13: 77 | AJ13: =VLOOKUP(AI13,المرجع!$B$3:$C$12,2) -> 3.5 | AK13: =VLOOKUP(AJ13,المرجع!$D$3:$E$12,2) -> ج+ | AL13: =AJ13*AH13 -> 7 | AM13: 3 | AN13: 97 | AO13: =VLOOKUP(AN13,المرجع!$B$3:$C$12,2) -> 5 | AP13: =VLOOKUP(AO13,المرجع!$D$3:$E$12,2) -> أ+ | AQ13: =AO13*AM13 -> 15 | AR13: 2 | AS13: 50 | AT13: =VLOOKUP(AS13,المرجع!$B$3:$C$12,2) -> 2 | AU13: =VLOOKUP(AT13,المرجع!$D$3:$E$12,2) -> د | AV13: =AT13*AR13 -> 4 | AW13: 2 | AX13: 83 | AY13: =VLOOKUP(AX13,المرجع!$B$3:$C$12,2) -> 4 | AZ13: =VLOOKUP(AY13,المرجع!$D$3:$E$12,2) -> ب | BA13: =AY13*AW13 -> 8 | BB13: =BA13+AV13+AQ13+AL13+AG13+AB13+W13+R13+M13+H13 -> 97.75 | BC13: =AW13+AR13+AM13+AH13+AC13+X13+S13+N13+I13+D13 -> 22 | BD13: =BB13/BC13 -> 4.4431818 | BE13: =('المستوى الأول 2022'!BL13+'المستوى الثاني 2023'!BB13)/('المستوى الثاني 2023'!BC13+'المستوى الأول 2022'!BM13) -> 3.9833333 | BF13: =VLOOKUP(BE13,المرجع!$D$3:$F$12,3) -> جيد جدا | BG13: =RANK(BD13,$BD$3:$BD$87) -> 11
B14: 2023087 | C14: فودي بندا سيلا | D14: 1 | E14: 92 | F14: =VLOOKUP(E14,المرجع!$B$3:$C$12,2) -> 4.75 | G14: =VLOOKUP(F14,المرجع!$D$3:$E$12,2) -> أ | H14: =F14*D14 -> 4.75 | I14: 2 | J14: 95 | K14: =VLOOKUP(J14,المرجع!$B$3:$C$12,2) -> 5 | L14: =VLOOKUP(K14,المرجع!$D$3:$E$12,2) -> أ+ | M14: =K14*I14 -> 10 | N14: 2 | O14: 87 | P14: =VLOOKUP(O14,المرجع!$B$3:$C$12,2) -> 4.5 | Q14: =VLOOKUP(P14,المرجع!$D$3:$E$12,2) -> ب+ | R14: =P14*N14 -> 9 | S14: 3 | T14: 100 | U14: =VLOOKUP(T14,المرجع!$B$3:$C$12,2) -> 5 | V14: =VLOOKUP(U14,المرجع!$D$3:$E$12,2) -> أ+ | W14: =U14*S14 -> 15 | X14: 2 | Y14: 91 | Z14: =VLOOKUP(Y14,المرجع!$B$3:$C$12,2) -> 4.75 | AA14: =VLOOKUP(Z14,المرجع!$D$3:$E$12,2) -> أ | AB14: =Z14*X14 -> 9.5 | AC14: 3 | AD14: 81 | AE14: =VLOOKUP(AD14,المرجع!$B$3:$C$12,2) -> 4 | AF14: =VLOOKUP(AE14,المرجع!$D$3:$E$12,2) -> ب | AG14: =AE14*AC14 -> 12 | AH14: 2 | AI14: 89 | AJ14: =VLOOKUP(AI14,المرجع!$B$3:$C$12,2) -> 4.5 | AK14: =VLOOKUP(AJ14,المرجع!$D$3:$E$12,2) -> ب+ | AL14: =AJ14*AH14 -> 9 | AM14: 3 | AN14: 100 | AO14: =VLOOKUP(AN14,المرجع!$B$3:$C$12,2) -> 5 | AP14: =VLOOKUP(AO14,المرجع!$D$3:$E$12,2) -> أ+ | AQ14: =AO14*AM14 -> 15 | AR14: 2 | AS14: 60 | AT14: =VLOOKUP(AS14,المرجع!$B$3:$C$12,2) -> 2 | AU14: =VLOOKUP(AT14,المرجع!$D$3:$E$12,2) -> د | AV14: =AT14*AR14 -> 4 | AW14: 2 | AX14: 88 | AY14: =VLOOKUP(AX14,المرجع!$B$3:$C$12,2) -> 4.5 | AZ14: =VLOOKUP(AY14,المرجع!$D$3:$E$12,2) -> ب+ | BA14: =AY14*AW14 -> 9 | BB14: =BA14+AV14+AQ14+AL14+AG14+AB14+W14+R14+M14+H14 -> 97.25 | BC14: =AW14+AR14+AM14+AH14+AC14+X14+S14+N14+I14+D14 -> 22 | BD14: =BB14/BC14 -> 4.4204545 | BE14: =('المستوى الأول 2022'!BL14+'المستوى الثاني 2023'!BB14)/('المستوى الثاني 2023'!BC14+'المستوى الأول 2022'!BM14) -> 4.0166667 | BF14: =VLOOKUP(BE14,المرجع!$D$3:$F$12,3) -> جيد جدا | BG14: =RANK(BD14,$BD$3:$BD$87) -> 12
... B87: 2023048 | C87: شعيب عمر درامي | D87: 1 | E87: 71 | F87: =VLOOKUP(E87,المرجع!$B$3:$C$12,2) -> 3 | G87: =VLOOKUP(F87,المرجع!$D$3:$E$12,2) -> ج | H87: =F87*D87 -> 3 | I87: 2 | J87: 68 | K87: =VLOOKUP(J87,المرجع!$B$3:$C$12,2) -> 2.5 | L87: =VLOOKUP(K87,المرجع!$D$3:$E$12,2) -> د+ | M87: =K87*I87 -> 5 | N87: 2 | O87: 50 | P87: =VLOOKUP(O87,المرجع!$B$3:$C$12,2) -> 2 | Q87: =VLOOKUP(P87,المرجع!$D$3:$E$12,2) -> د | R87: =P87*N87 -> 4 | S87: 3 | T87: 60 | U87: =VLOOKUP(T87,المرجع!$B$3:$C$12,2) -> 2 | V87: =VLOOKUP(U87,المرجع!$D$3:$E$12,2) -> د | W87: =U87*S87 -> 6 | X87: 2 | Y87: 69 | Z87: =VLOOKUP(Y87,المرجع!$B$3:$C$12,2) -> 2.5 | AA87: =VLOOKUP(Z87,المرجع!$D$3:$E$12,2) -> د+ | AB87: =Z87*X87 -> 5 | AC87: 3 | AD87: 50 | AE87: =VLOOKUP(AD87,المرجع!$B$3:$C$12,2) -> 2 | AF87: =VLOOKUP(AE87,المرجع!$D$3:$E$12,2) -> د | AG87: =AE87*AC87 -> 6 | AH87: 2 | AI87: 50 | AJ87: =VLOOKUP(AI87,المرجع!$B$3:$C$12,2) -> 2 | AK87: =VLOOKUP(AJ87,المرجع!$D$3:$E$12,2) -> د | AL87: =AJ87*AH87 -> 4 | AM87: 3 | AN87: 54 | AO87: =VLOOKUP(AN87,المرجع!$B$3:$C$12,2) -> 2 | AP87: =VLOOKUP(AO87,المرجع!$D$3:$E$12,2) -> د | AQ87: =AO87*AM87 -> 6 | AR87: 2 | AS87: 50 | AT87: =VLOOKUP(AS87,المرجع!$B$3:$C$12,2) -> 2 | AU87: =VLOOKUP(AT87,المرجع!$D$3:$E$12,2) -> د | AV87: =AT87*AR87 -> 4 | AW87: 2 | AX87: 50 | AY87: =VLOOKUP(AX87,المرجع!$B$3:$C$12,2) -> 2 | AZ87: =VLOOKUP(AY87,المرجع!$D$3:$E$12,2) -> د | BA87: =AY87*AW87 -> 4 | BB87: =BA87+AV87+AQ87+AL87+AG87+AB87+W87+R87+M87+H87 -> 47 | BC87: =AW87+AR87+AM87+AH87+AC87+X87+S87+N87+I87+D87 -> 22 | BD87: =BB87/BC87 -> 2.1363636 | BE87: =('المستوى الأول 2022'!BL87+'المستوى الثاني 2023'!BB87)/('المستوى الثاني 2023'!BC87+'المستوى الأول 2022'!BM87) -> 1.9777778 | BF87: =VLOOKUP(BE87,المرجع!$D$3:$F$12,3) -> راسب | BG87: =RANK(BD87,$BD$3:$BD$87) -> 85

Sheet المستوى الثالث ح
B2: رقم الجامعي | C2: أسماء الطلبة | D2: الساعة | E2: القرآن الكريم | F2: الوزن | G2: الرمز | H2: النقاط | I2: الساعة | J2: كتب السنة | K2: الوزن | L2: الرمز | M2: النقاط | N2: الساعة | O2: أصول الفقه | P2: الوزن | Q2: الرمز | R2: النقاط | S2: الساعة | T2: الفقه (3) | U2: الوزن | V2: الرمز | W2: النقاط | X2: الساعة | Y2: الحديث التحليلي (2) | Z2: الوزن | AA2: الرمز | AB2: النقاط | AC2: الساعة | AD2: رواة الحديث (2) | AE2: الوزن | AF2: الرمز | AG2: النقاط | AH2: الساعة | AI2: مصطلح الحديث (2) | AJ2: الوزن | AK2: الرمز | AL2: النقاط | AM2: الساعة | AN2: النحو (3) | AO2: الوزن | AP2: الرمز | AQ2: النقاط | AR2: الساعة | AS2: دراسات غامبيا | AT2: الوزن | AU2: الرمز | AV2: النقاط | AW2: الساعة | AX2: English(3) | AY2: الوزن | AZ2: الرمز | BA2: النقاط | BB2: مجموع النقاط | BC2: مجموع الساعات | BD2: المعدل الفصلي | BE2: المعدل التراكمي | BF2: التقدير | BG2: الترتيب
B3: 2023035 | C3: بنت موسى سماري | D3: 1 | E3: 95 | F3: =VLOOKUP(E3,المرجع!$B$3:$C$12,2) -> 5 | G3: =VLOOKUP(F3,المرجع!$D$3:$E$12,2) -> أ+ | H3: =F3*D3 -> 5 | I3: 3 | J3: 90 | K3: =VLOOKUP(J3,المرجع!$B$3:$C$12,2) -> 4.75 | L3: =VLOOKUP(K3,المرجع!$D$3:$E$12,2) -> أ | M3: =K3*I3 -> 14.25 | N3: 2 | O3: 94 | P3: =VLOOKUP(O3,المرجع!$B$3:$C$12,2) -> 4.75 | Q3: =VLOOKUP(P3,المرجع!$D$3:$E$12,2) -> أ | R3: =P3*N3 -> 9.5 | S3: 2 | T3: 90 | U3: =VLOOKUP(T3,المرجع!$B$3:$C$12,2) -> 4.75 | V3: =VLOOKUP(U3,المرجع!$D$3:$E$12,2) -> أ | W3: =U3*S3 -> 9.5 | X3: 3 | Y3: 92 | Z3: =VLOOKUP(Y3,المرجع!$B$3:$C$12,2) -> 4.75 | AA3: =VLOOKUP(Z3,المرجع!$D$3:$E$12,2) -> أ | AB3: =Z3*X3 -> 14.25 | AC3: 3 | AD3: 94 | AE3: =VLOOKUP(AD3,المرجع!$B$3:$C$12,2) -> 4.75 | AF3: =VLOOKUP(AE3,المرجع!$D$3:$E$12,2) -> أ | AG3: =AE3*AC3 -> 14.25 | AH3: 3 | AI3: 97 | AJ3: =VLOOKUP(AI3,المرجع!$B$3:$C$12,2) -> 5 | AK3: =VLOOKUP(AJ3,المرجع!$D$3:$E$12,2) -> أ+ | AL3: =AJ3*AH3 -> 15 | AM3: 2 | AN3: 100 | AO3: =VLOOKUP(AN3,المرجع!$B$3:$C$12,2) -> 5 | AP3: =VLOOKUP(AO3,المرجع!$D$3:$E$12,2) -> أ+ | AQ3: =AO3*AM3 -> 10 | AR3: 2 | AS3: 94 | AT3: =VLOOKUP(AS3,المرجع!$B$3:$C$12,2) -> 4.75 | AU3: =VLOOKUP(AT3,المرجع!$D$3:$E$12,2) -> أ | AV3: =AT3*AR3 -> 9.5 | AW3: 2 | AX3: 90 | AY3: =VLOOKUP(AX3,المرجع!$B$3:$C$12,2) -> 4.75 | AZ3: =VLOOKUP(AY3,المرجع!$D$3:$E$12,2) -> أ | BA3: =AY3*AW3 -> 9.5 | BB3: =BA3+AV3+AQ3+AL3+AG3+AB3+W3+R3+M3+H3 -> 110.75 | BC3: =AW3+AR3+AM3+AH3+AC3+X3+S3+N3+I3+D3 -> 23 | BD3: =BB3/BC3 -> 4.8152174 | BE3: =(BB3+'المستوى الثاني 2023'!BB3+'المستوى الأول 2022'!BL3)/('المستوى الأول 2022'!BM3+'المستوى الثاني 2023'!BC3+'المستوى الثالث ح'!BC3) -> 4.5257353 | BF3: =VLOOKUP(BD3,المرجع!$D$3:$F$12,3) -> ممتاز مرتفع | BG3: =RANK(BD3,$BD$3:$BD$77) -> 1
B4: 2023085 | C4: فاطمة صغرى محمد جابي | D4: 1 | E4: 99 | F4: =VLOOKUP(E4,المرجع!$B$3:$C$12,2) -> 5 | G4: =VLOOKUP(F4,المرجع!$D$3:$E$12,2) -> أ+ | H4: =F4*D4 -> 5 | I4: 3 | J4: 90 | K4: =VLOOKUP(J4,المرجع!$B$3:$C$12,2) -> 4.75 | L4: =VLOOKUP(K4,المرجع!$D$3:$E$12,2) -> أ | M4: =K4*I4 -> 14.25 | N4: 2 | O4: 100 | P4: =VLOOKUP(O4,المرجع!$B$3:$C$12,2) -> 5 | Q4: =VLOOKUP(P4,المرجع!$D$3:$E$12,2) -> أ+ | R4: =P4*N4 -> 10 | S4: 2 | T4: 90 | U4: =VLOOKUP(T4,المرجع!$B$3:$C$12,2) -> 4.75 | V4: =VLOOKUP(U4,المرجع!$D$3:$E$12,2) -> أ | W4: =U4*S4 -> 9.5 | X4: 3 | Y4: 100 | Z4: =VLOOKUP(Y4,المرجع!$B$3:$C$12,2) -> 5 | AA4: =VLOOKUP(Z4,المرجع!$D$3:$E$12,2) -> أ+ | AB4: =Z4*X4 -> 15 | AC4: 3 | AD4: 85 | AE4: =VLOOKUP(AD4,المرجع!$B$3:$C$12,2) -> 4.5 | AF4: =VLOOKUP(AE4,المرجع!$D$3:$E$12,2) -> ب+ | AG4: =AE4*AC4 -> 13.5 | AH4: 3 | AI4: 92 | AJ4: =VLOOKUP(AI4,المرجع!$B$3:$C$12,2) -> 4.75 | AK4: =VLOOKUP(AJ4,المرجع!$D$3:$E$12,2) -> أ | AL4: =AJ4*AH4 -> 14.25 | AM4: 2 | AN4: 82 | AO4: =VLOOKUP(AN4,المرجع!$B$3:$C$12,2) -> 4 | AP4: =VLOOKUP(AO4,المرجع!$D$3:$E$12,2) -> ب | AQ4: =AO4*AM4 -> 8 | AR4: 2 | AS4: 89 | AT4: =VLOOKUP(AS4,المرجع!$B$3:$C$12,2) -> 4.5 | AU4: =VLOOKUP(AT4,المرجع!$D$3:$E$12,2) -> ب+ | AV4: =AT4*AR4 -> 9 | AW4: 2 | AX4: 90 | AY4: =VLOOKUP(AX4,المرجع!$B$3:$C$12,2) -> 4.75 | AZ4: =VLOOKUP(AY4,المرجع!$D$3:$E$12,2) -> أ | BA4: =AY4*AW4 -> 9.5 | BB4: =BA4+AV4+AQ4+AL4+AG4+AB4+W4+R4+M4+H4 -> 108 | BC4: =AW4+AR4+AM4+AH4+AC4+X4+S4+N4+I4+D4 -> 23 | BD4: =BB4/BC4 -> 4.6956522 | BE4: =(BB4+'المستوى الثاني 2023'!BB4+'المستوى الأول 2022'!BL4)/('المستوى الأول 2022'!BM4+'المستوى الثاني 2023'!BC4+'المستوى الثالث ح'!BC4) -> 4.4705882 | BF4: =VLOOKUP(BD4,المرجع!$D$3:$F$12,3) -> ممتاز | BG4: =RANK(BD4,$BD$3:$BD$77) -> 2
B5: 2023027 | C5: آدم عبد الحميد سنكارا | D5: 1 | E5: 98 | F5: =VLOOKUP(E5,المرجع!$B$3:$C$12,2) -> 5 | G5: =VLOOKUP(F5,المرجع!$D$3:$E$12,2) -> أ+ | H5: =F5*D5 -> 5 | I5: 3 | J5: 83 | K5: =VLOOKUP(J5,المرجع!$B$3:$C$12,2) -> 4 | L5: =VLOOKUP(K5,المرجع!$D$3:$E$12,2) -> ب | M5: =K5*I5 -> 12 | N5: 2 | O5: 93 | P5: =VLOOKUP(O5,المرجع!$B$3:$C$12,2) -> 4.75 | Q5: =VLOOKUP(P5,المرجع!$D$3:$E$12,2) -> أ | R5: =P5*N5 -> 9.5 | S5: 2 | T5: 98 | U5: =VLOOKUP(T5,المرجع!$B$3:$C$12,2) -> 5 | V5: =VLOOKUP(U5,المرجع!$D$3:$E$12,2) -> أ+ | W5: =U5*S5 -> 10 | X5: 3 | Y5: 89 | Z5: =VLOOKUP(Y5,المرجع!$B$3:$C$12,2) -> 4.5 | AA5: =VLOOKUP(Z5,المرجع!$D$3:$E$12,2) -> ب+ | AB5: =Z5*X5 -> 13.5 | AC5: 3 | AD5: 95 | AE5: =VLOOKUP(AD5,المرجع!$B$3:$C$12,2) -> 5 | AF5: =VLOOKUP(AE5,المرجع!$D$3:$E$12,2) -> أ+ | AG5: =AE5*AC5 -> 15 | AH5: 3 | AI5: 100 | AJ5: =VLOOKUP(AI5,المرجع!$B$3:$C$12,2) -> 5 | AK5: =VLOOKUP(AJ5,المرجع!$D$3:$E$12,2) -> أ+ | AL5: =AJ5*AH5 -> 15 | AM5: 2 | AN5: 85 | AO5: =VLOOKUP(AN5,المرجع!$B$3:$C$12,2) -> 4.5 | AP5: =VLOOKUP(AO5,المرجع!$D$3:$E$12,2) -> ب+ | AQ5: =AO5*AM5 -> 9 | AR5: 2 | AS5: 89 | AT5: =VLOOKUP(AS5,المرجع!$B$3:$C$12,2) -> 4.5 | AU5: =VLOOKUP(AT5,المرجع!$D$3:$E$12,2) -> ب+ | AV5: =AT5*AR5 -> 9 | AW5: 2 | AX5: 70 | AY5: =VLOOKUP(AX5,المرجع!$B$3:$C$12,2) -> 3 | AZ5: =VLOOKUP(AY5,المرجع!$D$3:$E$12,2) -> ج | BA5: =AY5*AW5 -> 6 | BB5: =BA5+AV5+AQ5+AL5+AG5+AB5+W5+R5+M5+H5 -> 104 | BC5: =AW5+AR5+AM5+AH5+AC5+X5+S5+N5+I5+D5 -> 23 | BD5: =BB5/BC5 -> 4.5217391 | BE5: =(BB5+'المستوى الثاني 2023'!BB5+'المستوى الأول 2022'!BL5)/('المستوى الأول 2022'!BM5+'المستوى الثاني 2023'!BC5+'المستوى الثالث ح'!BC5) -> 4.3897059 | BF5: =VLOOKUP(BD5,المرجع!$D$3:$F$12,3) -> جيد جد مرتفع | BG5: =RANK(BD5,$BD$3:$BD$77) -> 3
B6: 2023002 | C6: ديالو إبراهيم | D6: 1 | E6: 97 | F6: =VLOOKUP(E6,المرجع!$B$3:$C$12,2) -> 5 | G6: =VLOOKUP(F6,المرجع!$D$3:$E$12,2) -> أ+ | H6: =F6*D6 -> 5 | I6: 3 | J6: 90 | K6: =VLOOKUP(J6,المرجع!$B$3:$C$12,2) -> 4.75 | L6: =VLOOKUP(K6,المرجع!$D$3:$E$12,2) -> أ | M6: =K6*I6 -> 14.25 | N6: 2 | O6: 93 | P6: =VLOOKUP(O6,المرجع!$B$3:$C$12,2) -> 4.75 | Q6: =VLOOKUP(P6,المرجع!$D$3:$E$12,2) -> أ | R6: =P6*N6 -> 9.5 | S6: 2 | T6: 98 | U6: =VLOOKUP(T6,المرجع!$B$3:$C$12,2) -> 5 | V6: =VLOOKUP(U6,المرجع!$D$3:$E$12,2) -> أ+ | W6: =U6*S6 -> 10 | X6: 3 | Y6: 100 | Z6: =VLOOKUP(Y6,المرجع!$B$3:$C$12,2) -> 5 | AA6: =VLOOKUP(Z6,المرجع!$D$3:$E$12,2) -> أ+ | AB6: =Z6*X6 -> 15 | AC6: 3 | AD6: 77 | AE6: =VLOOKUP(AD6,المرجع!$B$3:$C$12,2) -> 3.5 | AF6: =VLOOKUP(AE6,المرجع!$D$3:$E$12,2) -> ج+ | AG6: =AE6*AC6 -> 10.5 | AH6: 3 | AI6: 96 | AJ6: =VLOOKUP(AI6,المرجع!$B$3:$C$12,2) -> 5 | AK6: =VLOOKUP(AJ6,المرجع!$D$3:$E$12,2) -> أ+ | AL6: =AJ6*AH6 -> 15 | AM6: 2 | AN6: 90 | AO6: =VLOOKUP(AN6,المرجع!$B$3:$C$12,2) -> 4.75 | AP6: =VLOOKUP(AO6,المرجع!$D$3:$E$12,2) -> أ | AQ6: =AO6*AM6 -> 9.5 | AR6: 2 | AS6: 85 | AT6: =VLOOKUP(AS6,المرجع!$B$3:$C$12,2) -> 4.5 | AU6: =VLOOKUP(AT6,المرجع!$D$3:$E$12,2) -> ب+ | AV6: =AT6*AR6 -> 9 | AW6: 2 | AX6: 71 | AY6: =VLOOKUP(AX6,المرجع!$B$3:$C$12,2) -> 3 | AZ6: =VLOOKUP(AY6,المرجع!$D$3:$E$12,2) -> ج | BA6: =AY6*AW6 -> 6 | BB6: =BA6+AV6+AQ6+AL6+AG6+AB6+W6+R6+M6+H6 -> 103.75 | BC6: =AW6+AR6+AM6+AH6+AC6+X6+S6+N6+I6+D6 -> 23 | BD6: =BB6/BC6 -> 4.5108696 | BE6: =(BB6+'المستوى الثاني 2023'!BB6+'المستوى الأول 2022'!BL6)/('المستوى الأول 2022'!BM6+'المستوى الثاني 2023'!BC6+'المستوى الثالث ح'!BC6) -> 4.4779412 | BF6: =VLOOKUP(BD6,المرجع!$D$3:$F$12,3) -> جيد جد مرتفع | BG6: =RANK(BD6,$BD$3:$BD$77) -> 4
B7: 2023097 | C7: محمد بن سمبر دكوري | D7: 1 | E7: 98 | F7: =VLOOKUP(E7,المرجع!$B$3:$C$12,2) -> 5 | G7: =VLOOKUP(F7,المرجع!$D$3:$E$12,2) -> أ+ | H7: =F7*D7 -> 5 | I7: 3 | J7: 90 | K7: =VLOOKUP(J7,المرجع!$B$3:$C$12,2) -> 4.75 | L7: =VLOOKUP(K7,المرجع!$D$3:$E$12,2) -> أ | M7: =K7*I7 -> 14.25 | N7: 2 | O7: 92 | P7: =VLOOKUP(O7,المرجع!$B$3:$C$12,2) -> 4.75 | Q7: =VLOOKUP(P7,المرجع!$D$3:$E$12,2) -> أ | R7: =P7*N7 -> 9.5 | S7: 2 | T7: 100 | U7: =VLOOKUP(T7,المرجع!$B$3:$C$12,2) -> 5 | V7: =VLOOKUP(U7,المرجع!$D$3:$E$12,2) -> أ+ | W7: =U7*S7 -> 10 | X7: 3 | Y7: 82 | Z7: =VLOOKUP(Y7,المرجع!$B$3:$C$12,2) -> 4 | AA7: =VLOOKUP(Z7,المرجع!$D$3:$E$12,2) -> ب | AB7: =Z7*X7 -> 12 | AC7: 3 | AD7: 95 | AE7: =VLOOKUP(AD7,المرجع!$B$3:$C$12,2) -> 5 | AF7: =VLOOKUP(AE7,المرجع!$D$3:$E$12,2) -> أ+ | AG7: =AE7*AC7 -> 15 | AH7: 3 | AI7: 93 | AJ7: =VLOOKUP(AI7,المرجع!$B$3:$C$12,2) -> 4.75 | AK7: =VLOOKUP(AJ7,المرجع!$D$3:$E$12,2) -> أ | AL7: =AJ7*AH7 -> 14.25 | AM7: 2 | AN7: 100 | AO7: =VLOOKUP(AN7,المرجع!$B$3:$C$12,2) -> 5 | AP7: =VLOOKUP(AO7,المرجع!$D$3:$E$12,2) -> أ+ | AQ7: =AO7*AM7 -> 10 | AR7: 2 | AS7: 79 | AT7: =VLOOKUP(AS7,المرجع!$B$3:$C$12,2) -> 3.5 | AU7: =VLOOKUP(AT7,المرجع!$D$3:$E$12,2) -> ج+ | AV7: =AT7*AR7 -> 7 | AW7: 2 | AX7: 53 | AY7: =VLOOKUP(AX7,المرجع!$B$3:$C$12,2) -> 2 | AZ7: =VLOOKUP(AY7,المرجع!$D$3:$E$12,2) -> د | BA7: =AY7*AW7 -> 4 | BB7: =BA7+AV7+AQ7+AL7+AG7+AB7+W7+R7+M7+H7 -> 101 | BC7: =AW7+AR7+AM7+AH7+AC7+X7+S7+N7+I7+D7 -> 23 | BD7: =BB7/BC7 -> 4.3913043 | BE7: =(BB7+'المستوى الثاني 2023'!BB7+'المستوى الأول 2022'!BL7)/('المستوى الأول 2022'!BM7+'المستوى الثاني 2023'!BC7+'المستوى الثالث ح'!BC7) -> 4.2904412 | BF7: =VLOOKUP(BD7,المرجع!$D$3:$F$12,3) -> جيد جد مرتفع | BG7: =RANK(BD7,$BD$3:$BD$77) -> 5
